2024-09-23 14:12:44,199 Using device: cuda
2024-09-23 14:12:44,199 Scheduling mode set as BestBatch
2024-09-23 14:12:44,199 Monitoring status set to True
2024-09-23 14:12:59,263 [31m[1mWARNING: This is a development server. Do not use it in a production deployment. Use a production WSGI server instead.[0m
 * Running on all addresses (0.0.0.0)
 * Running on http://127.0.0.1:5000
 * Running on http://192.168.122.143:5000
2024-09-23 14:12:59,263 [33mPress CTRL+C to quit[0m
2024-09-23 14:13:00,572 127.0.0.1 - - [23/Sep/2024 14:13:00] "GET /health HTTP/1.1" 200 -
2024-09-23 14:13:00,807 Request with ID 866ada35 for model gemma-7b received
2024-09-23 14:13:00,807 Exception on /inference [POST]
Traceback (most recent call last):
  File "/home/amartinezi/sincere/venv/lib64/python3.9/site-packages/flask/app.py", line 1473, in wsgi_app
    response = self.full_dispatch_request()
  File "/home/amartinezi/sincere/venv/lib64/python3.9/site-packages/flask/app.py", line 882, in full_dispatch_request
    rv = self.handle_user_exception(e)
  File "/home/amartinezi/sincere/venv/lib64/python3.9/site-packages/flask/app.py", line 880, in full_dispatch_request
    rv = self.dispatch_request()
  File "/home/amartinezi/sincere/venv/lib64/python3.9/site-packages/flask/app.py", line 865, in dispatch_request
    return self.ensure_sync(self.view_functions[rule.endpoint])(**view_args)  # type: ignore[no-any-return]
  File "/home/amartinezi/sincere/api_scheduler_experiments.py", line 473, in inference
    model_usage_count[model_alias] += 1
NameError: name 'model_usage_count' is not defined
2024-09-23 14:13:00,809 127.0.0.1 - - [23/Sep/2024 14:13:00] "[35m[1mPOST /inference HTTP/1.1[0m" 500 -
2024-09-23 14:13:00,998 Request with ID c14e992b for model llama3-8b received
2024-09-23 14:13:00,998 Exception on /inference [POST]
Traceback (most recent call last):
  File "/home/amartinezi/sincere/venv/lib64/python3.9/site-packages/flask/app.py", line 1473, in wsgi_app
    response = self.full_dispatch_request()
  File "/home/amartinezi/sincere/venv/lib64/python3.9/site-packages/flask/app.py", line 882, in full_dispatch_request
    rv = self.handle_user_exception(e)
  File "/home/amartinezi/sincere/venv/lib64/python3.9/site-packages/flask/app.py", line 880, in full_dispatch_request
    rv = self.dispatch_request()
  File "/home/amartinezi/sincere/venv/lib64/python3.9/site-packages/flask/app.py", line 865, in dispatch_request
    return self.ensure_sync(self.view_functions[rule.endpoint])(**view_args)  # type: ignore[no-any-return]
  File "/home/amartinezi/sincere/api_scheduler_experiments.py", line 473, in inference
    model_usage_count[model_alias] += 1
NameError: name 'model_usage_count' is not defined
2024-09-23 14:13:00,999 127.0.0.1 - - [23/Sep/2024 14:13:00] "[35m[1mPOST /inference HTTP/1.1[0m" 500 -
2024-09-23 14:13:01,011 Request with ID be9cc463 for model llama3-8b received
2024-09-23 14:13:01,011 Exception on /inference [POST]
Traceback (most recent call last):
  File "/home/amartinezi/sincere/venv/lib64/python3.9/site-packages/flask/app.py", line 1473, in wsgi_app
    response = self.full_dispatch_request()
  File "/home/amartinezi/sincere/venv/lib64/python3.9/site-packages/flask/app.py", line 882, in full_dispatch_request
    rv = self.handle_user_exception(e)
  File "/home/amartinezi/sincere/venv/lib64/python3.9/site-packages/flask/app.py", line 880, in full_dispatch_request
    rv = self.dispatch_request()
  File "/home/amartinezi/sincere/venv/lib64/python3.9/site-packages/flask/app.py", line 865, in dispatch_request
    return self.ensure_sync(self.view_functions[rule.endpoint])(**view_args)  # type: ignore[no-any-return]
  File "/home/amartinezi/sincere/api_scheduler_experiments.py", line 473, in inference
    model_usage_count[model_alias] += 1
NameError: name 'model_usage_count' is not defined
2024-09-23 14:13:01,012 127.0.0.1 - - [23/Sep/2024 14:13:01] "[35m[1mPOST /inference HTTP/1.1[0m" 500 -
2024-09-23 14:13:01,129 Request with ID c0c4bb9d for model granite-7b received
2024-09-23 14:13:01,130 Exception on /inference [POST]
Traceback (most recent call last):
  File "/home/amartinezi/sincere/venv/lib64/python3.9/site-packages/flask/app.py", line 1473, in wsgi_app
    response = self.full_dispatch_request()
  File "/home/amartinezi/sincere/venv/lib64/python3.9/site-packages/flask/app.py", line 882, in full_dispatch_request
    rv = self.handle_user_exception(e)
  File "/home/amartinezi/sincere/venv/lib64/python3.9/site-packages/flask/app.py", line 880, in full_dispatch_request
    rv = self.dispatch_request()
  File "/home/amartinezi/sincere/venv/lib64/python3.9/site-packages/flask/app.py", line 865, in dispatch_request
    return self.ensure_sync(self.view_functions[rule.endpoint])(**view_args)  # type: ignore[no-any-return]
  File "/home/amartinezi/sincere/api_scheduler_experiments.py", line 473, in inference
    model_usage_count[model_alias] += 1
NameError: name 'model_usage_count' is not defined
2024-09-23 14:13:01,130 127.0.0.1 - - [23/Sep/2024 14:13:01] "[35m[1mPOST /inference HTTP/1.1[0m" 500 -
2024-09-23 14:13:01,570 Request with ID 500a72d3 for model llama3-8b received
2024-09-23 14:13:01,571 Request with ID 140279bd for model gemma-7b received
2024-09-23 14:13:01,571 Exception on /inference [POST]
Traceback (most recent call last):
  File "/home/amartinezi/sincere/venv/lib64/python3.9/site-packages/flask/app.py", line 1473, in wsgi_app
    response = self.full_dispatch_request()
  File "/home/amartinezi/sincere/venv/lib64/python3.9/site-packages/flask/app.py", line 882, in full_dispatch_request
    rv = self.handle_user_exception(e)
  File "/home/amartinezi/sincere/venv/lib64/python3.9/site-packages/flask/app.py", line 880, in full_dispatch_request
    rv = self.dispatch_request()
  File "/home/amartinezi/sincere/venv/lib64/python3.9/site-packages/flask/app.py", line 865, in dispatch_request
    return self.ensure_sync(self.view_functions[rule.endpoint])(**view_args)  # type: ignore[no-any-return]
  File "/home/amartinezi/sincere/api_scheduler_experiments.py", line 473, in inference
    model_usage_count[model_alias] += 1
NameError: name 'model_usage_count' is not defined
2024-09-23 14:13:01,572 Exception on /inference [POST]
Traceback (most recent call last):
  File "/home/amartinezi/sincere/venv/lib64/python3.9/site-packages/flask/app.py", line 1473, in wsgi_app
    response = self.full_dispatch_request()
  File "/home/amartinezi/sincere/venv/lib64/python3.9/site-packages/flask/app.py", line 882, in full_dispatch_request
    rv = self.handle_user_exception(e)
  File "/home/amartinezi/sincere/venv/lib64/python3.9/site-packages/flask/app.py", line 880, in full_dispatch_request
    rv = self.dispatch_request()
  File "/home/amartinezi/sincere/venv/lib64/python3.9/site-packages/flask/app.py", line 865, in dispatch_request
    return self.ensure_sync(self.view_functions[rule.endpoint])(**view_args)  # type: ignore[no-any-return]
  File "/home/amartinezi/sincere/api_scheduler_experiments.py", line 473, in inference
    model_usage_count[model_alias] += 1
NameError: name 'model_usage_count' is not defined
2024-09-23 14:13:01,572 127.0.0.1 - - [23/Sep/2024 14:13:01] "[35m[1mPOST /inference HTTP/1.1[0m" 500 -
2024-09-23 14:13:01,573 127.0.0.1 - - [23/Sep/2024 14:13:01] "[35m[1mPOST /inference HTTP/1.1[0m" 500 -
2024-09-23 14:13:01,618 Request with ID 82beacae for model granite-7b received
2024-09-23 14:13:01,618 Exception on /inference [POST]
Traceback (most recent call last):
  File "/home/amartinezi/sincere/venv/lib64/python3.9/site-packages/flask/app.py", line 1473, in wsgi_app
    response = self.full_dispatch_request()
  File "/home/amartinezi/sincere/venv/lib64/python3.9/site-packages/flask/app.py", line 882, in full_dispatch_request
    rv = self.handle_user_exception(e)
  File "/home/amartinezi/sincere/venv/lib64/python3.9/site-packages/flask/app.py", line 880, in full_dispatch_request
    rv = self.dispatch_request()
  File "/home/amartinezi/sincere/venv/lib64/python3.9/site-packages/flask/app.py", line 865, in dispatch_request
    return self.ensure_sync(self.view_functions[rule.endpoint])(**view_args)  # type: ignore[no-any-return]
  File "/home/amartinezi/sincere/api_scheduler_experiments.py", line 473, in inference
    model_usage_count[model_alias] += 1
NameError: name 'model_usage_count' is not defined
2024-09-23 14:13:01,619 127.0.0.1 - - [23/Sep/2024 14:13:01] "[35m[1mPOST /inference HTTP/1.1[0m" 500 -
2024-09-23 14:13:01,621 Request with ID 291141a2 for model llama3-8b received
2024-09-23 14:13:01,622 Exception on /inference [POST]
Traceback (most recent call last):
  File "/home/amartinezi/sincere/venv/lib64/python3.9/site-packages/flask/app.py", line 1473, in wsgi_app
    response = self.full_dispatch_request()
  File "/home/amartinezi/sincere/venv/lib64/python3.9/site-packages/flask/app.py", line 882, in full_dispatch_request
    rv = self.handle_user_exception(e)
  File "/home/amartinezi/sincere/venv/lib64/python3.9/site-packages/flask/app.py", line 880, in full_dispatch_request
    rv = self.dispatch_request()
  File "/home/amartinezi/sincere/venv/lib64/python3.9/site-packages/flask/app.py", line 865, in dispatch_request
    return self.ensure_sync(self.view_functions[rule.endpoint])(**view_args)  # type: ignore[no-any-return]
  File "/home/amartinezi/sincere/api_scheduler_experiments.py", line 473, in inference
    model_usage_count[model_alias] += 1
NameError: name 'model_usage_count' is not defined
2024-09-23 14:13:01,622 127.0.0.1 - - [23/Sep/2024 14:13:01] "[35m[1mPOST /inference HTTP/1.1[0m" 500 -
2024-09-23 14:13:01,641 Request with ID 1d8d3781 for model gemma-7b received
2024-09-23 14:13:01,641 Exception on /inference [POST]
Traceback (most recent call last):
  File "/home/amartinezi/sincere/venv/lib64/python3.9/site-packages/flask/app.py", line 1473, in wsgi_app
    response = self.full_dispatch_request()
  File "/home/amartinezi/sincere/venv/lib64/python3.9/site-packages/flask/app.py", line 882, in full_dispatch_request
    rv = self.handle_user_exception(e)
  File "/home/amartinezi/sincere/venv/lib64/python3.9/site-packages/flask/app.py", line 880, in full_dispatch_request
    rv = self.dispatch_request()
  File "/home/amartinezi/sincere/venv/lib64/python3.9/site-packages/flask/app.py", line 865, in dispatch_request
    return self.ensure_sync(self.view_functions[rule.endpoint])(**view_args)  # type: ignore[no-any-return]
  File "/home/amartinezi/sincere/api_scheduler_experiments.py", line 473, in inference
    model_usage_count[model_alias] += 1
NameError: name 'model_usage_count' is not defined
2024-09-23 14:13:01,642 127.0.0.1 - - [23/Sep/2024 14:13:01] "[35m[1mPOST /inference HTTP/1.1[0m" 500 -
2024-09-23 14:13:01,654 Request with ID 0d7708c7 for model gemma-7b received
2024-09-23 14:13:01,655 Exception on /inference [POST]
Traceback (most recent call last):
  File "/home/amartinezi/sincere/venv/lib64/python3.9/site-packages/flask/app.py", line 1473, in wsgi_app
    response = self.full_dispatch_request()
  File "/home/amartinezi/sincere/venv/lib64/python3.9/site-packages/flask/app.py", line 882, in full_dispatch_request
    rv = self.handle_user_exception(e)
  File "/home/amartinezi/sincere/venv/lib64/python3.9/site-packages/flask/app.py", line 880, in full_dispatch_request
    rv = self.dispatch_request()
  File "/home/amartinezi/sincere/venv/lib64/python3.9/site-packages/flask/app.py", line 865, in dispatch_request
    return self.ensure_sync(self.view_functions[rule.endpoint])(**view_args)  # type: ignore[no-any-return]
  File "/home/amartinezi/sincere/api_scheduler_experiments.py", line 473, in inference
    model_usage_count[model_alias] += 1
NameError: name 'model_usage_count' is not defined
2024-09-23 14:13:01,655 127.0.0.1 - - [23/Sep/2024 14:13:01] "[35m[1mPOST /inference HTTP/1.1[0m" 500 -
2024-09-23 14:13:02,169 Request with ID 418e35be for model granite-7b received
2024-09-23 14:13:02,169 Exception on /inference [POST]
Traceback (most recent call last):
  File "/home/amartinezi/sincere/venv/lib64/python3.9/site-packages/flask/app.py", line 1473, in wsgi_app
    response = self.full_dispatch_request()
  File "/home/amartinezi/sincere/venv/lib64/python3.9/site-packages/flask/app.py", line 882, in full_dispatch_request
    rv = self.handle_user_exception(e)
  File "/home/amartinezi/sincere/venv/lib64/python3.9/site-packages/flask/app.py", line 880, in full_dispatch_request
    rv = self.dispatch_request()
  File "/home/amartinezi/sincere/venv/lib64/python3.9/site-packages/flask/app.py", line 865, in dispatch_request
    return self.ensure_sync(self.view_functions[rule.endpoint])(**view_args)  # type: ignore[no-any-return]
  File "/home/amartinezi/sincere/api_scheduler_experiments.py", line 473, in inference
    model_usage_count[model_alias] += 1
NameError: name 'model_usage_count' is not defined
2024-09-23 14:13:02,170 127.0.0.1 - - [23/Sep/2024 14:13:02] "[35m[1mPOST /inference HTTP/1.1[0m" 500 -
2024-09-23 14:13:02,287 Request with ID 8d12ee8e for model llama3-8b received
2024-09-23 14:13:02,287 Exception on /inference [POST]
Traceback (most recent call last):
  File "/home/amartinezi/sincere/venv/lib64/python3.9/site-packages/flask/app.py", line 1473, in wsgi_app
    response = self.full_dispatch_request()
  File "/home/amartinezi/sincere/venv/lib64/python3.9/site-packages/flask/app.py", line 882, in full_dispatch_request
    rv = self.handle_user_exception(e)
  File "/home/amartinezi/sincere/venv/lib64/python3.9/site-packages/flask/app.py", line 880, in full_dispatch_request
    rv = self.dispatch_request()
  File "/home/amartinezi/sincere/venv/lib64/python3.9/site-packages/flask/app.py", line 865, in dispatch_request
    return self.ensure_sync(self.view_functions[rule.endpoint])(**view_args)  # type: ignore[no-any-return]
  File "/home/amartinezi/sincere/api_scheduler_experiments.py", line 473, in inference
    model_usage_count[model_alias] += 1
NameError: name 'model_usage_count' is not defined
2024-09-23 14:13:02,288 127.0.0.1 - - [23/Sep/2024 14:13:02] "[35m[1mPOST /inference HTTP/1.1[0m" 500 -
2024-09-23 14:13:02,289 Request with ID 800a5de1 for model llama3-8b received
2024-09-23 14:13:02,289 Exception on /inference [POST]
Traceback (most recent call last):
  File "/home/amartinezi/sincere/venv/lib64/python3.9/site-packages/flask/app.py", line 1473, in wsgi_app
    response = self.full_dispatch_request()
  File "/home/amartinezi/sincere/venv/lib64/python3.9/site-packages/flask/app.py", line 882, in full_dispatch_request
    rv = self.handle_user_exception(e)
  File "/home/amartinezi/sincere/venv/lib64/python3.9/site-packages/flask/app.py", line 880, in full_dispatch_request
    rv = self.dispatch_request()
  File "/home/amartinezi/sincere/venv/lib64/python3.9/site-packages/flask/app.py", line 865, in dispatch_request
    return self.ensure_sync(self.view_functions[rule.endpoint])(**view_args)  # type: ignore[no-any-return]
  File "/home/amartinezi/sincere/api_scheduler_experiments.py", line 473, in inference
    model_usage_count[model_alias] += 1
NameError: name 'model_usage_count' is not defined
2024-09-23 14:13:02,289 127.0.0.1 - - [23/Sep/2024 14:13:02] "[35m[1mPOST /inference HTTP/1.1[0m" 500 -
2024-09-23 14:13:02,498 Request with ID ed08c402 for model gemma-7b received
2024-09-23 14:13:02,498 Exception on /inference [POST]
Traceback (most recent call last):
  File "/home/amartinezi/sincere/venv/lib64/python3.9/site-packages/flask/app.py", line 1473, in wsgi_app
    response = self.full_dispatch_request()
  File "/home/amartinezi/sincere/venv/lib64/python3.9/site-packages/flask/app.py", line 882, in full_dispatch_request
    rv = self.handle_user_exception(e)
  File "/home/amartinezi/sincere/venv/lib64/python3.9/site-packages/flask/app.py", line 880, in full_dispatch_request
    rv = self.dispatch_request()
  File "/home/amartinezi/sincere/venv/lib64/python3.9/site-packages/flask/app.py", line 865, in dispatch_request
    return self.ensure_sync(self.view_functions[rule.endpoint])(**view_args)  # type: ignore[no-any-return]
  File "/home/amartinezi/sincere/api_scheduler_experiments.py", line 473, in inference
    model_usage_count[model_alias] += 1
NameError: name 'model_usage_count' is not defined
2024-09-23 14:13:02,499 127.0.0.1 - - [23/Sep/2024 14:13:02] "[35m[1mPOST /inference HTTP/1.1[0m" 500 -
2024-09-23 14:13:02,643 Request with ID 8dee31d4 for model granite-7b received
2024-09-23 14:13:02,644 Exception on /inference [POST]
Traceback (most recent call last):
  File "/home/amartinezi/sincere/venv/lib64/python3.9/site-packages/flask/app.py", line 1473, in wsgi_app
    response = self.full_dispatch_request()
  File "/home/amartinezi/sincere/venv/lib64/python3.9/site-packages/flask/app.py", line 882, in full_dispatch_request
    rv = self.handle_user_exception(e)
  File "/home/amartinezi/sincere/venv/lib64/python3.9/site-packages/flask/app.py", line 880, in full_dispatch_request
    rv = self.dispatch_request()
  File "/home/amartinezi/sincere/venv/lib64/python3.9/site-packages/flask/app.py", line 865, in dispatch_request
    return self.ensure_sync(self.view_functions[rule.endpoint])(**view_args)  # type: ignore[no-any-return]
  File "/home/amartinezi/sincere/api_scheduler_experiments.py", line 473, in inference
    model_usage_count[model_alias] += 1
NameError: name 'model_usage_count' is not defined
2024-09-23 14:13:02,644 127.0.0.1 - - [23/Sep/2024 14:13:02] "[35m[1mPOST /inference HTTP/1.1[0m" 500 -
2024-09-23 14:13:02,945 Request with ID b5dfde73 for model gemma-7b received
2024-09-23 14:13:02,945 Exception on /inference [POST]
Traceback (most recent call last):
  File "/home/amartinezi/sincere/venv/lib64/python3.9/site-packages/flask/app.py", line 1473, in wsgi_app
    response = self.full_dispatch_request()
  File "/home/amartinezi/sincere/venv/lib64/python3.9/site-packages/flask/app.py", line 882, in full_dispatch_request
    rv = self.handle_user_exception(e)
  File "/home/amartinezi/sincere/venv/lib64/python3.9/site-packages/flask/app.py", line 880, in full_dispatch_request
    rv = self.dispatch_request()
  File "/home/amartinezi/sincere/venv/lib64/python3.9/site-packages/flask/app.py", line 865, in dispatch_request
    return self.ensure_sync(self.view_functions[rule.endpoint])(**view_args)  # type: ignore[no-any-return]
  File "/home/amartinezi/sincere/api_scheduler_experiments.py", line 473, in inference
    model_usage_count[model_alias] += 1
NameError: name 'model_usage_count' is not defined
2024-09-23 14:13:02,946 127.0.0.1 - - [23/Sep/2024 14:13:02] "[35m[1mPOST /inference HTTP/1.1[0m" 500 -
2024-09-23 14:13:03,123 Request with ID a3fac35b for model llama3-8b received
2024-09-23 14:13:03,123 Exception on /inference [POST]
Traceback (most recent call last):
  File "/home/amartinezi/sincere/venv/lib64/python3.9/site-packages/flask/app.py", line 1473, in wsgi_app
    response = self.full_dispatch_request()
  File "/home/amartinezi/sincere/venv/lib64/python3.9/site-packages/flask/app.py", line 882, in full_dispatch_request
    rv = self.handle_user_exception(e)
  File "/home/amartinezi/sincere/venv/lib64/python3.9/site-packages/flask/app.py", line 880, in full_dispatch_request
    rv = self.dispatch_request()
  File "/home/amartinezi/sincere/venv/lib64/python3.9/site-packages/flask/app.py", line 865, in dispatch_request
    return self.ensure_sync(self.view_functions[rule.endpoint])(**view_args)  # type: ignore[no-any-return]
  File "/home/amartinezi/sincere/api_scheduler_experiments.py", line 473, in inference
    model_usage_count[model_alias] += 1
NameError: name 'model_usage_count' is not defined
2024-09-23 14:13:03,124 127.0.0.1 - - [23/Sep/2024 14:13:03] "[35m[1mPOST /inference HTTP/1.1[0m" 500 -
2024-09-23 14:13:03,223 Request with ID c72d799e for model llama3-8b received
2024-09-23 14:13:03,223 Exception on /inference [POST]
Traceback (most recent call last):
  File "/home/amartinezi/sincere/venv/lib64/python3.9/site-packages/flask/app.py", line 1473, in wsgi_app
    response = self.full_dispatch_request()
  File "/home/amartinezi/sincere/venv/lib64/python3.9/site-packages/flask/app.py", line 882, in full_dispatch_request
    rv = self.handle_user_exception(e)
  File "/home/amartinezi/sincere/venv/lib64/python3.9/site-packages/flask/app.py", line 880, in full_dispatch_request
    rv = self.dispatch_request()
  File "/home/amartinezi/sincere/venv/lib64/python3.9/site-packages/flask/app.py", line 865, in dispatch_request
    return self.ensure_sync(self.view_functions[rule.endpoint])(**view_args)  # type: ignore[no-any-return]
  File "/home/amartinezi/sincere/api_scheduler_experiments.py", line 473, in inference
    model_usage_count[model_alias] += 1
NameError: name 'model_usage_count' is not defined
2024-09-23 14:13:03,224 127.0.0.1 - - [23/Sep/2024 14:13:03] "[35m[1mPOST /inference HTTP/1.1[0m" 500 -
2024-09-23 14:13:03,411 Request with ID a23e30e2 for model gemma-7b received
2024-09-23 14:13:03,412 Exception on /inference [POST]
Traceback (most recent call last):
  File "/home/amartinezi/sincere/venv/lib64/python3.9/site-packages/flask/app.py", line 1473, in wsgi_app
    response = self.full_dispatch_request()
  File "/home/amartinezi/sincere/venv/lib64/python3.9/site-packages/flask/app.py", line 882, in full_dispatch_request
    rv = self.handle_user_exception(e)
  File "/home/amartinezi/sincere/venv/lib64/python3.9/site-packages/flask/app.py", line 880, in full_dispatch_request
    rv = self.dispatch_request()
  File "/home/amartinezi/sincere/venv/lib64/python3.9/site-packages/flask/app.py", line 865, in dispatch_request
    return self.ensure_sync(self.view_functions[rule.endpoint])(**view_args)  # type: ignore[no-any-return]
  File "/home/amartinezi/sincere/api_scheduler_experiments.py", line 473, in inference
    model_usage_count[model_alias] += 1
NameError: name 'model_usage_count' is not defined
2024-09-23 14:13:03,412 127.0.0.1 - - [23/Sep/2024 14:13:03] "[35m[1mPOST /inference HTTP/1.1[0m" 500 -
2024-09-23 14:13:03,739 Request with ID 1d1b50c5 for model gemma-7b received
2024-09-23 14:13:03,740 Exception on /inference [POST]
Traceback (most recent call last):
  File "/home/amartinezi/sincere/venv/lib64/python3.9/site-packages/flask/app.py", line 1473, in wsgi_app
    response = self.full_dispatch_request()
  File "/home/amartinezi/sincere/venv/lib64/python3.9/site-packages/flask/app.py", line 882, in full_dispatch_request
    rv = self.handle_user_exception(e)
  File "/home/amartinezi/sincere/venv/lib64/python3.9/site-packages/flask/app.py", line 880, in full_dispatch_request
    rv = self.dispatch_request()
  File "/home/amartinezi/sincere/venv/lib64/python3.9/site-packages/flask/app.py", line 865, in dispatch_request
    return self.ensure_sync(self.view_functions[rule.endpoint])(**view_args)  # type: ignore[no-any-return]
  File "/home/amartinezi/sincere/api_scheduler_experiments.py", line 473, in inference
    model_usage_count[model_alias] += 1
NameError: name 'model_usage_count' is not defined
2024-09-23 14:13:03,740 127.0.0.1 - - [23/Sep/2024 14:13:03] "[35m[1mPOST /inference HTTP/1.1[0m" 500 -
2024-09-23 14:13:03,846 Request with ID b84dda15 for model granite-7b received
2024-09-23 14:13:03,847 Exception on /inference [POST]
Traceback (most recent call last):
  File "/home/amartinezi/sincere/venv/lib64/python3.9/site-packages/flask/app.py", line 1473, in wsgi_app
    response = self.full_dispatch_request()
  File "/home/amartinezi/sincere/venv/lib64/python3.9/site-packages/flask/app.py", line 882, in full_dispatch_request
    rv = self.handle_user_exception(e)
  File "/home/amartinezi/sincere/venv/lib64/python3.9/site-packages/flask/app.py", line 880, in full_dispatch_request
    rv = self.dispatch_request()
  File "/home/amartinezi/sincere/venv/lib64/python3.9/site-packages/flask/app.py", line 865, in dispatch_request
    return self.ensure_sync(self.view_functions[rule.endpoint])(**view_args)  # type: ignore[no-any-return]
  File "/home/amartinezi/sincere/api_scheduler_experiments.py", line 473, in inference
    model_usage_count[model_alias] += 1
NameError: name 'model_usage_count' is not defined
2024-09-23 14:13:03,847 127.0.0.1 - - [23/Sep/2024 14:13:03] "[35m[1mPOST /inference HTTP/1.1[0m" 500 -
2024-09-23 14:13:03,897 Request with ID 83268885 for model llama3-8b received
2024-09-23 14:13:03,897 Exception on /inference [POST]
Traceback (most recent call last):
  File "/home/amartinezi/sincere/venv/lib64/python3.9/site-packages/flask/app.py", line 1473, in wsgi_app
    response = self.full_dispatch_request()
  File "/home/amartinezi/sincere/venv/lib64/python3.9/site-packages/flask/app.py", line 882, in full_dispatch_request
    rv = self.handle_user_exception(e)
  File "/home/amartinezi/sincere/venv/lib64/python3.9/site-packages/flask/app.py", line 880, in full_dispatch_request
    rv = self.dispatch_request()
  File "/home/amartinezi/sincere/venv/lib64/python3.9/site-packages/flask/app.py", line 865, in dispatch_request
    return self.ensure_sync(self.view_functions[rule.endpoint])(**view_args)  # type: ignore[no-any-return]
  File "/home/amartinezi/sincere/api_scheduler_experiments.py", line 473, in inference
    model_usage_count[model_alias] += 1
NameError: name 'model_usage_count' is not defined
2024-09-23 14:13:03,898 127.0.0.1 - - [23/Sep/2024 14:13:03] "[35m[1mPOST /inference HTTP/1.1[0m" 500 -
2024-09-23 14:13:04,009 Request with ID 8872ccfe for model llama3-8b received
2024-09-23 14:13:04,010 Exception on /inference [POST]
Traceback (most recent call last):
  File "/home/amartinezi/sincere/venv/lib64/python3.9/site-packages/flask/app.py", line 1473, in wsgi_app
    response = self.full_dispatch_request()
  File "/home/amartinezi/sincere/venv/lib64/python3.9/site-packages/flask/app.py", line 882, in full_dispatch_request
    rv = self.handle_user_exception(e)
  File "/home/amartinezi/sincere/venv/lib64/python3.9/site-packages/flask/app.py", line 880, in full_dispatch_request
    rv = self.dispatch_request()
  File "/home/amartinezi/sincere/venv/lib64/python3.9/site-packages/flask/app.py", line 865, in dispatch_request
    return self.ensure_sync(self.view_functions[rule.endpoint])(**view_args)  # type: ignore[no-any-return]
  File "/home/amartinezi/sincere/api_scheduler_experiments.py", line 473, in inference
    model_usage_count[model_alias] += 1
NameError: name 'model_usage_count' is not defined
2024-09-23 14:13:04,011 127.0.0.1 - - [23/Sep/2024 14:13:04] "[35m[1mPOST /inference HTTP/1.1[0m" 500 -
2024-09-23 14:13:04,051 Request with ID 0da04152 for model llama3-8b received
2024-09-23 14:13:04,052 Exception on /inference [POST]
Traceback (most recent call last):
  File "/home/amartinezi/sincere/venv/lib64/python3.9/site-packages/flask/app.py", line 1473, in wsgi_app
    response = self.full_dispatch_request()
  File "/home/amartinezi/sincere/venv/lib64/python3.9/site-packages/flask/app.py", line 882, in full_dispatch_request
    rv = self.handle_user_exception(e)
  File "/home/amartinezi/sincere/venv/lib64/python3.9/site-packages/flask/app.py", line 880, in full_dispatch_request
    rv = self.dispatch_request()
  File "/home/amartinezi/sincere/venv/lib64/python3.9/site-packages/flask/app.py", line 865, in dispatch_request
    return self.ensure_sync(self.view_functions[rule.endpoint])(**view_args)  # type: ignore[no-any-return]
  File "/home/amartinezi/sincere/api_scheduler_experiments.py", line 473, in inference
    model_usage_count[model_alias] += 1
NameError: name 'model_usage_count' is not defined
2024-09-23 14:13:04,052 127.0.0.1 - - [23/Sep/2024 14:13:04] "[35m[1mPOST /inference HTTP/1.1[0m" 500 -
2024-09-23 14:13:04,062 Request with ID 5431e4c1 for model gemma-7b received
2024-09-23 14:13:04,062 Exception on /inference [POST]
Traceback (most recent call last):
  File "/home/amartinezi/sincere/venv/lib64/python3.9/site-packages/flask/app.py", line 1473, in wsgi_app
    response = self.full_dispatch_request()
  File "/home/amartinezi/sincere/venv/lib64/python3.9/site-packages/flask/app.py", line 882, in full_dispatch_request
    rv = self.handle_user_exception(e)
  File "/home/amartinezi/sincere/venv/lib64/python3.9/site-packages/flask/app.py", line 880, in full_dispatch_request
    rv = self.dispatch_request()
  File "/home/amartinezi/sincere/venv/lib64/python3.9/site-packages/flask/app.py", line 865, in dispatch_request
    return self.ensure_sync(self.view_functions[rule.endpoint])(**view_args)  # type: ignore[no-any-return]
  File "/home/amartinezi/sincere/api_scheduler_experiments.py", line 473, in inference
    model_usage_count[model_alias] += 1
NameError: name 'model_usage_count' is not defined
2024-09-23 14:13:04,062 127.0.0.1 - - [23/Sep/2024 14:13:04] "[35m[1mPOST /inference HTTP/1.1[0m" 500 -
2024-09-23 14:13:04,107 Request with ID 0dafb73b for model gemma-7b received
2024-09-23 14:13:04,107 Exception on /inference [POST]
Traceback (most recent call last):
  File "/home/amartinezi/sincere/venv/lib64/python3.9/site-packages/flask/app.py", line 1473, in wsgi_app
    response = self.full_dispatch_request()
  File "/home/amartinezi/sincere/venv/lib64/python3.9/site-packages/flask/app.py", line 882, in full_dispatch_request
    rv = self.handle_user_exception(e)
  File "/home/amartinezi/sincere/venv/lib64/python3.9/site-packages/flask/app.py", line 880, in full_dispatch_request
    rv = self.dispatch_request()
  File "/home/amartinezi/sincere/venv/lib64/python3.9/site-packages/flask/app.py", line 865, in dispatch_request
    return self.ensure_sync(self.view_functions[rule.endpoint])(**view_args)  # type: ignore[no-any-return]
  File "/home/amartinezi/sincere/api_scheduler_experiments.py", line 473, in inference
    model_usage_count[model_alias] += 1
NameError: name 'model_usage_count' is not defined
2024-09-23 14:13:04,108 127.0.0.1 - - [23/Sep/2024 14:13:04] "[35m[1mPOST /inference HTTP/1.1[0m" 500 -
2024-09-23 14:13:04,264 Request with ID c5f10101 for model llama3-8b received
2024-09-23 14:13:04,264 Exception on /inference [POST]
Traceback (most recent call last):
  File "/home/amartinezi/sincere/venv/lib64/python3.9/site-packages/flask/app.py", line 1473, in wsgi_app
    response = self.full_dispatch_request()
  File "/home/amartinezi/sincere/venv/lib64/python3.9/site-packages/flask/app.py", line 882, in full_dispatch_request
    rv = self.handle_user_exception(e)
  File "/home/amartinezi/sincere/venv/lib64/python3.9/site-packages/flask/app.py", line 880, in full_dispatch_request
    rv = self.dispatch_request()
  File "/home/amartinezi/sincere/venv/lib64/python3.9/site-packages/flask/app.py", line 865, in dispatch_request
    return self.ensure_sync(self.view_functions[rule.endpoint])(**view_args)  # type: ignore[no-any-return]
  File "/home/amartinezi/sincere/api_scheduler_experiments.py", line 473, in inference
    model_usage_count[model_alias] += 1
NameError: name 'model_usage_count' is not defined
2024-09-23 14:13:04,265 127.0.0.1 - - [23/Sep/2024 14:13:04] "[35m[1mPOST /inference HTTP/1.1[0m" 500 -
2024-09-23 14:13:04,274 Request with ID a2750578 for model llama3-8b received
2024-09-23 14:13:04,274 Exception on /inference [POST]
Traceback (most recent call last):
  File "/home/amartinezi/sincere/venv/lib64/python3.9/site-packages/flask/app.py", line 1473, in wsgi_app
    response = self.full_dispatch_request()
  File "/home/amartinezi/sincere/venv/lib64/python3.9/site-packages/flask/app.py", line 882, in full_dispatch_request
    rv = self.handle_user_exception(e)
  File "/home/amartinezi/sincere/venv/lib64/python3.9/site-packages/flask/app.py", line 880, in full_dispatch_request
    rv = self.dispatch_request()
  File "/home/amartinezi/sincere/venv/lib64/python3.9/site-packages/flask/app.py", line 865, in dispatch_request
    return self.ensure_sync(self.view_functions[rule.endpoint])(**view_args)  # type: ignore[no-any-return]
  File "/home/amartinezi/sincere/api_scheduler_experiments.py", line 473, in inference
    model_usage_count[model_alias] += 1
NameError: name 'model_usage_count' is not defined
2024-09-23 14:13:04,274 127.0.0.1 - - [23/Sep/2024 14:13:04] "[35m[1mPOST /inference HTTP/1.1[0m" 500 -
2024-09-23 14:13:04,514 Request with ID f6e12907 for model gemma-7b received
2024-09-23 14:13:04,514 Exception on /inference [POST]
Traceback (most recent call last):
  File "/home/amartinezi/sincere/venv/lib64/python3.9/site-packages/flask/app.py", line 1473, in wsgi_app
    response = self.full_dispatch_request()
  File "/home/amartinezi/sincere/venv/lib64/python3.9/site-packages/flask/app.py", line 882, in full_dispatch_request
    rv = self.handle_user_exception(e)
  File "/home/amartinezi/sincere/venv/lib64/python3.9/site-packages/flask/app.py", line 880, in full_dispatch_request
    rv = self.dispatch_request()
  File "/home/amartinezi/sincere/venv/lib64/python3.9/site-packages/flask/app.py", line 865, in dispatch_request
    return self.ensure_sync(self.view_functions[rule.endpoint])(**view_args)  # type: ignore[no-any-return]
  File "/home/amartinezi/sincere/api_scheduler_experiments.py", line 473, in inference
    model_usage_count[model_alias] += 1
NameError: name 'model_usage_count' is not defined
2024-09-23 14:13:04,515 127.0.0.1 - - [23/Sep/2024 14:13:04] "[35m[1mPOST /inference HTTP/1.1[0m" 500 -
2024-09-23 14:13:04,523 Request with ID 8a262a06 for model llama3-8b received
2024-09-23 14:13:04,523 Exception on /inference [POST]
Traceback (most recent call last):
  File "/home/amartinezi/sincere/venv/lib64/python3.9/site-packages/flask/app.py", line 1473, in wsgi_app
    response = self.full_dispatch_request()
  File "/home/amartinezi/sincere/venv/lib64/python3.9/site-packages/flask/app.py", line 882, in full_dispatch_request
    rv = self.handle_user_exception(e)
  File "/home/amartinezi/sincere/venv/lib64/python3.9/site-packages/flask/app.py", line 880, in full_dispatch_request
    rv = self.dispatch_request()
  File "/home/amartinezi/sincere/venv/lib64/python3.9/site-packages/flask/app.py", line 865, in dispatch_request
    return self.ensure_sync(self.view_functions[rule.endpoint])(**view_args)  # type: ignore[no-any-return]
  File "/home/amartinezi/sincere/api_scheduler_experiments.py", line 473, in inference
    model_usage_count[model_alias] += 1
NameError: name 'model_usage_count' is not defined
2024-09-23 14:13:04,523 127.0.0.1 - - [23/Sep/2024 14:13:04] "[35m[1mPOST /inference HTTP/1.1[0m" 500 -
2024-09-23 14:13:04,637 Request with ID c3839ad1 for model llama3-8b received
2024-09-23 14:13:04,638 Exception on /inference [POST]
Traceback (most recent call last):
  File "/home/amartinezi/sincere/venv/lib64/python3.9/site-packages/flask/app.py", line 1473, in wsgi_app
    response = self.full_dispatch_request()
  File "/home/amartinezi/sincere/venv/lib64/python3.9/site-packages/flask/app.py", line 882, in full_dispatch_request
    rv = self.handle_user_exception(e)
  File "/home/amartinezi/sincere/venv/lib64/python3.9/site-packages/flask/app.py", line 880, in full_dispatch_request
    rv = self.dispatch_request()
  File "/home/amartinezi/sincere/venv/lib64/python3.9/site-packages/flask/app.py", line 865, in dispatch_request
    return self.ensure_sync(self.view_functions[rule.endpoint])(**view_args)  # type: ignore[no-any-return]
  File "/home/amartinezi/sincere/api_scheduler_experiments.py", line 473, in inference
    model_usage_count[model_alias] += 1
NameError: name 'model_usage_count' is not defined
2024-09-23 14:13:04,638 127.0.0.1 - - [23/Sep/2024 14:13:04] "[35m[1mPOST /inference HTTP/1.1[0m" 500 -
2024-09-23 14:13:04,653 Request with ID a396e344 for model llama3-8b received
2024-09-23 14:13:04,653 Exception on /inference [POST]
Traceback (most recent call last):
  File "/home/amartinezi/sincere/venv/lib64/python3.9/site-packages/flask/app.py", line 1473, in wsgi_app
    response = self.full_dispatch_request()
  File "/home/amartinezi/sincere/venv/lib64/python3.9/site-packages/flask/app.py", line 882, in full_dispatch_request
    rv = self.handle_user_exception(e)
  File "/home/amartinezi/sincere/venv/lib64/python3.9/site-packages/flask/app.py", line 880, in full_dispatch_request
    rv = self.dispatch_request()
  File "/home/amartinezi/sincere/venv/lib64/python3.9/site-packages/flask/app.py", line 865, in dispatch_request
    return self.ensure_sync(self.view_functions[rule.endpoint])(**view_args)  # type: ignore[no-any-return]
  File "/home/amartinezi/sincere/api_scheduler_experiments.py", line 473, in inference
    model_usage_count[model_alias] += 1
NameError: name 'model_usage_count' is not defined
2024-09-23 14:13:04,654 127.0.0.1 - - [23/Sep/2024 14:13:04] "[35m[1mPOST /inference HTTP/1.1[0m" 500 -
2024-09-23 14:13:04,816 Request with ID 8bc8a335 for model llama3-8b received
2024-09-23 14:13:04,816 Exception on /inference [POST]
Traceback (most recent call last):
  File "/home/amartinezi/sincere/venv/lib64/python3.9/site-packages/flask/app.py", line 1473, in wsgi_app
    response = self.full_dispatch_request()
  File "/home/amartinezi/sincere/venv/lib64/python3.9/site-packages/flask/app.py", line 882, in full_dispatch_request
    rv = self.handle_user_exception(e)
  File "/home/amartinezi/sincere/venv/lib64/python3.9/site-packages/flask/app.py", line 880, in full_dispatch_request
    rv = self.dispatch_request()
  File "/home/amartinezi/sincere/venv/lib64/python3.9/site-packages/flask/app.py", line 865, in dispatch_request
    return self.ensure_sync(self.view_functions[rule.endpoint])(**view_args)  # type: ignore[no-any-return]
  File "/home/amartinezi/sincere/api_scheduler_experiments.py", line 473, in inference
    model_usage_count[model_alias] += 1
NameError: name 'model_usage_count' is not defined
2024-09-23 14:13:04,817 127.0.0.1 - - [23/Sep/2024 14:13:04] "[35m[1mPOST /inference HTTP/1.1[0m" 500 -
2024-09-23 14:13:04,903 Request with ID 47511b32 for model llama3-8b received
2024-09-23 14:13:04,903 Exception on /inference [POST]
Traceback (most recent call last):
  File "/home/amartinezi/sincere/venv/lib64/python3.9/site-packages/flask/app.py", line 1473, in wsgi_app
    response = self.full_dispatch_request()
  File "/home/amartinezi/sincere/venv/lib64/python3.9/site-packages/flask/app.py", line 882, in full_dispatch_request
    rv = self.handle_user_exception(e)
  File "/home/amartinezi/sincere/venv/lib64/python3.9/site-packages/flask/app.py", line 880, in full_dispatch_request
    rv = self.dispatch_request()
  File "/home/amartinezi/sincere/venv/lib64/python3.9/site-packages/flask/app.py", line 865, in dispatch_request
    return self.ensure_sync(self.view_functions[rule.endpoint])(**view_args)  # type: ignore[no-any-return]
  File "/home/amartinezi/sincere/api_scheduler_experiments.py", line 473, in inference
    model_usage_count[model_alias] += 1
NameError: name 'model_usage_count' is not defined
2024-09-23 14:13:04,904 127.0.0.1 - - [23/Sep/2024 14:13:04] "[35m[1mPOST /inference HTTP/1.1[0m" 500 -
2024-09-23 14:13:04,918 Request with ID 62b69654 for model gemma-7b received
2024-09-23 14:13:04,918 Exception on /inference [POST]
Traceback (most recent call last):
  File "/home/amartinezi/sincere/venv/lib64/python3.9/site-packages/flask/app.py", line 1473, in wsgi_app
    response = self.full_dispatch_request()
  File "/home/amartinezi/sincere/venv/lib64/python3.9/site-packages/flask/app.py", line 882, in full_dispatch_request
    rv = self.handle_user_exception(e)
  File "/home/amartinezi/sincere/venv/lib64/python3.9/site-packages/flask/app.py", line 880, in full_dispatch_request
    rv = self.dispatch_request()
  File "/home/amartinezi/sincere/venv/lib64/python3.9/site-packages/flask/app.py", line 865, in dispatch_request
    return self.ensure_sync(self.view_functions[rule.endpoint])(**view_args)  # type: ignore[no-any-return]
  File "/home/amartinezi/sincere/api_scheduler_experiments.py", line 473, in inference
    model_usage_count[model_alias] += 1
NameError: name 'model_usage_count' is not defined
2024-09-23 14:13:04,918 127.0.0.1 - - [23/Sep/2024 14:13:04] "[35m[1mPOST /inference HTTP/1.1[0m" 500 -
2024-09-23 14:13:05,204 Request with ID bd507efc for model llama3-8b received
2024-09-23 14:13:05,204 Exception on /inference [POST]
Traceback (most recent call last):
  File "/home/amartinezi/sincere/venv/lib64/python3.9/site-packages/flask/app.py", line 1473, in wsgi_app
    response = self.full_dispatch_request()
  File "/home/amartinezi/sincere/venv/lib64/python3.9/site-packages/flask/app.py", line 882, in full_dispatch_request
    rv = self.handle_user_exception(e)
  File "/home/amartinezi/sincere/venv/lib64/python3.9/site-packages/flask/app.py", line 880, in full_dispatch_request
    rv = self.dispatch_request()
  File "/home/amartinezi/sincere/venv/lib64/python3.9/site-packages/flask/app.py", line 865, in dispatch_request
    return self.ensure_sync(self.view_functions[rule.endpoint])(**view_args)  # type: ignore[no-any-return]
  File "/home/amartinezi/sincere/api_scheduler_experiments.py", line 473, in inference
    model_usage_count[model_alias] += 1
NameError: name 'model_usage_count' is not defined
2024-09-23 14:13:05,205 127.0.0.1 - - [23/Sep/2024 14:13:05] "[35m[1mPOST /inference HTTP/1.1[0m" 500 -
2024-09-23 14:13:05,355 Request with ID 55d9c56e for model llama3-8b received
2024-09-23 14:13:05,355 Exception on /inference [POST]
Traceback (most recent call last):
  File "/home/amartinezi/sincere/venv/lib64/python3.9/site-packages/flask/app.py", line 1473, in wsgi_app
    response = self.full_dispatch_request()
  File "/home/amartinezi/sincere/venv/lib64/python3.9/site-packages/flask/app.py", line 882, in full_dispatch_request
    rv = self.handle_user_exception(e)
  File "/home/amartinezi/sincere/venv/lib64/python3.9/site-packages/flask/app.py", line 880, in full_dispatch_request
    rv = self.dispatch_request()
  File "/home/amartinezi/sincere/venv/lib64/python3.9/site-packages/flask/app.py", line 865, in dispatch_request
    return self.ensure_sync(self.view_functions[rule.endpoint])(**view_args)  # type: ignore[no-any-return]
  File "/home/amartinezi/sincere/api_scheduler_experiments.py", line 473, in inference
    model_usage_count[model_alias] += 1
NameError: name 'model_usage_count' is not defined
2024-09-23 14:13:05,355 127.0.0.1 - - [23/Sep/2024 14:13:05] "[35m[1mPOST /inference HTTP/1.1[0m" 500 -
2024-09-23 14:13:05,387 Request with ID 0778c7d2 for model llama3-8b received
2024-09-23 14:13:05,387 Exception on /inference [POST]
Traceback (most recent call last):
  File "/home/amartinezi/sincere/venv/lib64/python3.9/site-packages/flask/app.py", line 1473, in wsgi_app
    response = self.full_dispatch_request()
  File "/home/amartinezi/sincere/venv/lib64/python3.9/site-packages/flask/app.py", line 882, in full_dispatch_request
    rv = self.handle_user_exception(e)
  File "/home/amartinezi/sincere/venv/lib64/python3.9/site-packages/flask/app.py", line 880, in full_dispatch_request
    rv = self.dispatch_request()
  File "/home/amartinezi/sincere/venv/lib64/python3.9/site-packages/flask/app.py", line 865, in dispatch_request
    return self.ensure_sync(self.view_functions[rule.endpoint])(**view_args)  # type: ignore[no-any-return]
  File "/home/amartinezi/sincere/api_scheduler_experiments.py", line 473, in inference
    model_usage_count[model_alias] += 1
NameError: name 'model_usage_count' is not defined
2024-09-23 14:13:05,387 127.0.0.1 - - [23/Sep/2024 14:13:05] "[35m[1mPOST /inference HTTP/1.1[0m" 500 -
2024-09-23 14:13:05,538 Request with ID f739d169 for model llama3-8b received
2024-09-23 14:13:05,538 Exception on /inference [POST]
Traceback (most recent call last):
  File "/home/amartinezi/sincere/venv/lib64/python3.9/site-packages/flask/app.py", line 1473, in wsgi_app
    response = self.full_dispatch_request()
  File "/home/amartinezi/sincere/venv/lib64/python3.9/site-packages/flask/app.py", line 882, in full_dispatch_request
    rv = self.handle_user_exception(e)
  File "/home/amartinezi/sincere/venv/lib64/python3.9/site-packages/flask/app.py", line 880, in full_dispatch_request
    rv = self.dispatch_request()
  File "/home/amartinezi/sincere/venv/lib64/python3.9/site-packages/flask/app.py", line 865, in dispatch_request
    return self.ensure_sync(self.view_functions[rule.endpoint])(**view_args)  # type: ignore[no-any-return]
  File "/home/amartinezi/sincere/api_scheduler_experiments.py", line 473, in inference
    model_usage_count[model_alias] += 1
NameError: name 'model_usage_count' is not defined
2024-09-23 14:13:05,539 127.0.0.1 - - [23/Sep/2024 14:13:05] "[35m[1mPOST /inference HTTP/1.1[0m" 500 -
2024-09-23 14:13:05,746 Request with ID b7691b4d for model llama3-8b received
2024-09-23 14:13:05,746 Exception on /inference [POST]
Traceback (most recent call last):
  File "/home/amartinezi/sincere/venv/lib64/python3.9/site-packages/flask/app.py", line 1473, in wsgi_app
    response = self.full_dispatch_request()
  File "/home/amartinezi/sincere/venv/lib64/python3.9/site-packages/flask/app.py", line 882, in full_dispatch_request
    rv = self.handle_user_exception(e)
  File "/home/amartinezi/sincere/venv/lib64/python3.9/site-packages/flask/app.py", line 880, in full_dispatch_request
    rv = self.dispatch_request()
  File "/home/amartinezi/sincere/venv/lib64/python3.9/site-packages/flask/app.py", line 865, in dispatch_request
    return self.ensure_sync(self.view_functions[rule.endpoint])(**view_args)  # type: ignore[no-any-return]
  File "/home/amartinezi/sincere/api_scheduler_experiments.py", line 473, in inference
    model_usage_count[model_alias] += 1
NameError: name 'model_usage_count' is not defined
2024-09-23 14:13:05,747 127.0.0.1 - - [23/Sep/2024 14:13:05] "[35m[1mPOST /inference HTTP/1.1[0m" 500 -
2024-09-23 14:13:05,773 Request with ID 1d693145 for model llama3-8b received
2024-09-23 14:13:05,773 Exception on /inference [POST]
Traceback (most recent call last):
  File "/home/amartinezi/sincere/venv/lib64/python3.9/site-packages/flask/app.py", line 1473, in wsgi_app
    response = self.full_dispatch_request()
  File "/home/amartinezi/sincere/venv/lib64/python3.9/site-packages/flask/app.py", line 882, in full_dispatch_request
    rv = self.handle_user_exception(e)
  File "/home/amartinezi/sincere/venv/lib64/python3.9/site-packages/flask/app.py", line 880, in full_dispatch_request
    rv = self.dispatch_request()
  File "/home/amartinezi/sincere/venv/lib64/python3.9/site-packages/flask/app.py", line 865, in dispatch_request
    return self.ensure_sync(self.view_functions[rule.endpoint])(**view_args)  # type: ignore[no-any-return]
  File "/home/amartinezi/sincere/api_scheduler_experiments.py", line 473, in inference
    model_usage_count[model_alias] += 1
NameError: name 'model_usage_count' is not defined
2024-09-23 14:13:05,773 127.0.0.1 - - [23/Sep/2024 14:13:05] "[35m[1mPOST /inference HTTP/1.1[0m" 500 -
2024-09-23 14:13:05,981 Request with ID 07574878 for model gemma-7b received
2024-09-23 14:13:05,981 Exception on /inference [POST]
Traceback (most recent call last):
  File "/home/amartinezi/sincere/venv/lib64/python3.9/site-packages/flask/app.py", line 1473, in wsgi_app
    response = self.full_dispatch_request()
  File "/home/amartinezi/sincere/venv/lib64/python3.9/site-packages/flask/app.py", line 882, in full_dispatch_request
    rv = self.handle_user_exception(e)
  File "/home/amartinezi/sincere/venv/lib64/python3.9/site-packages/flask/app.py", line 880, in full_dispatch_request
    rv = self.dispatch_request()
  File "/home/amartinezi/sincere/venv/lib64/python3.9/site-packages/flask/app.py", line 865, in dispatch_request
    return self.ensure_sync(self.view_functions[rule.endpoint])(**view_args)  # type: ignore[no-any-return]
  File "/home/amartinezi/sincere/api_scheduler_experiments.py", line 473, in inference
    model_usage_count[model_alias] += 1
NameError: name 'model_usage_count' is not defined
2024-09-23 14:13:05,982 127.0.0.1 - - [23/Sep/2024 14:13:05] "[35m[1mPOST /inference HTTP/1.1[0m" 500 -
2024-09-23 14:13:05,997 Request with ID 68a95ac8 for model llama3-8b received
2024-09-23 14:13:05,998 Request with ID 3eb8cda8 for model llama3-8b received
2024-09-23 14:13:05,999 Exception on /inference [POST]
Traceback (most recent call last):
  File "/home/amartinezi/sincere/venv/lib64/python3.9/site-packages/flask/app.py", line 1473, in wsgi_app
    response = self.full_dispatch_request()
  File "/home/amartinezi/sincere/venv/lib64/python3.9/site-packages/flask/app.py", line 882, in full_dispatch_request
    rv = self.handle_user_exception(e)
  File "/home/amartinezi/sincere/venv/lib64/python3.9/site-packages/flask/app.py", line 880, in full_dispatch_request
    rv = self.dispatch_request()
  File "/home/amartinezi/sincere/venv/lib64/python3.9/site-packages/flask/app.py", line 865, in dispatch_request
    return self.ensure_sync(self.view_functions[rule.endpoint])(**view_args)  # type: ignore[no-any-return]
  File "/home/amartinezi/sincere/api_scheduler_experiments.py", line 473, in inference
    model_usage_count[model_alias] += 1
NameError: name 'model_usage_count' is not defined
2024-09-23 14:13:06,000 Request with ID a5383a2e for model llama3-8b received
2024-09-23 14:13:06,000 Exception on /inference [POST]
Traceback (most recent call last):
  File "/home/amartinezi/sincere/venv/lib64/python3.9/site-packages/flask/app.py", line 1473, in wsgi_app
    response = self.full_dispatch_request()
  File "/home/amartinezi/sincere/venv/lib64/python3.9/site-packages/flask/app.py", line 882, in full_dispatch_request
    rv = self.handle_user_exception(e)
  File "/home/amartinezi/sincere/venv/lib64/python3.9/site-packages/flask/app.py", line 880, in full_dispatch_request
    rv = self.dispatch_request()
  File "/home/amartinezi/sincere/venv/lib64/python3.9/site-packages/flask/app.py", line 865, in dispatch_request
    return self.ensure_sync(self.view_functions[rule.endpoint])(**view_args)  # type: ignore[no-any-return]
  File "/home/amartinezi/sincere/api_scheduler_experiments.py", line 473, in inference
    model_usage_count[model_alias] += 1
NameError: name 'model_usage_count' is not defined
2024-09-23 14:13:06,001 127.0.0.1 - - [23/Sep/2024 14:13:06] "[35m[1mPOST /inference HTTP/1.1[0m" 500 -
2024-09-23 14:13:06,001 Exception on /inference [POST]
Traceback (most recent call last):
  File "/home/amartinezi/sincere/venv/lib64/python3.9/site-packages/flask/app.py", line 1473, in wsgi_app
    response = self.full_dispatch_request()
  File "/home/amartinezi/sincere/venv/lib64/python3.9/site-packages/flask/app.py", line 882, in full_dispatch_request
    rv = self.handle_user_exception(e)
  File "/home/amartinezi/sincere/venv/lib64/python3.9/site-packages/flask/app.py", line 880, in full_dispatch_request
    rv = self.dispatch_request()
  File "/home/amartinezi/sincere/venv/lib64/python3.9/site-packages/flask/app.py", line 865, in dispatch_request
    return self.ensure_sync(self.view_functions[rule.endpoint])(**view_args)  # type: ignore[no-any-return]
  File "/home/amartinezi/sincere/api_scheduler_experiments.py", line 473, in inference
    model_usage_count[model_alias] += 1
NameError: name 'model_usage_count' is not defined
2024-09-23 14:13:06,002 127.0.0.1 - - [23/Sep/2024 14:13:06] "[35m[1mPOST /inference HTTP/1.1[0m" 500 -
2024-09-23 14:13:06,003 127.0.0.1 - - [23/Sep/2024 14:13:06] "[35m[1mPOST /inference HTTP/1.1[0m" 500 -
2024-09-23 14:13:06,084 Request with ID 408b9f9b for model gemma-7b received
2024-09-23 14:13:06,084 Exception on /inference [POST]
Traceback (most recent call last):
  File "/home/amartinezi/sincere/venv/lib64/python3.9/site-packages/flask/app.py", line 1473, in wsgi_app
    response = self.full_dispatch_request()
  File "/home/amartinezi/sincere/venv/lib64/python3.9/site-packages/flask/app.py", line 882, in full_dispatch_request
    rv = self.handle_user_exception(e)
  File "/home/amartinezi/sincere/venv/lib64/python3.9/site-packages/flask/app.py", line 880, in full_dispatch_request
    rv = self.dispatch_request()
  File "/home/amartinezi/sincere/venv/lib64/python3.9/site-packages/flask/app.py", line 865, in dispatch_request
    return self.ensure_sync(self.view_functions[rule.endpoint])(**view_args)  # type: ignore[no-any-return]
  File "/home/amartinezi/sincere/api_scheduler_experiments.py", line 473, in inference
    model_usage_count[model_alias] += 1
NameError: name 'model_usage_count' is not defined
2024-09-23 14:13:06,084 127.0.0.1 - - [23/Sep/2024 14:13:06] "[35m[1mPOST /inference HTTP/1.1[0m" 500 -
2024-09-23 14:13:06,443 Request with ID 47ef0502 for model llama3-8b received
2024-09-23 14:13:06,443 Exception on /inference [POST]
Traceback (most recent call last):
  File "/home/amartinezi/sincere/venv/lib64/python3.9/site-packages/flask/app.py", line 1473, in wsgi_app
    response = self.full_dispatch_request()
  File "/home/amartinezi/sincere/venv/lib64/python3.9/site-packages/flask/app.py", line 882, in full_dispatch_request
    rv = self.handle_user_exception(e)
  File "/home/amartinezi/sincere/venv/lib64/python3.9/site-packages/flask/app.py", line 880, in full_dispatch_request
    rv = self.dispatch_request()
  File "/home/amartinezi/sincere/venv/lib64/python3.9/site-packages/flask/app.py", line 865, in dispatch_request
    return self.ensure_sync(self.view_functions[rule.endpoint])(**view_args)  # type: ignore[no-any-return]
  File "/home/amartinezi/sincere/api_scheduler_experiments.py", line 473, in inference
    model_usage_count[model_alias] += 1
NameError: name 'model_usage_count' is not defined
2024-09-23 14:13:06,444 127.0.0.1 - - [23/Sep/2024 14:13:06] "[35m[1mPOST /inference HTTP/1.1[0m" 500 -
2024-09-23 14:13:06,509 Request with ID a2d78540 for model llama3-8b received
2024-09-23 14:13:06,509 Exception on /inference [POST]
Traceback (most recent call last):
  File "/home/amartinezi/sincere/venv/lib64/python3.9/site-packages/flask/app.py", line 1473, in wsgi_app
    response = self.full_dispatch_request()
  File "/home/amartinezi/sincere/venv/lib64/python3.9/site-packages/flask/app.py", line 882, in full_dispatch_request
    rv = self.handle_user_exception(e)
  File "/home/amartinezi/sincere/venv/lib64/python3.9/site-packages/flask/app.py", line 880, in full_dispatch_request
    rv = self.dispatch_request()
  File "/home/amartinezi/sincere/venv/lib64/python3.9/site-packages/flask/app.py", line 865, in dispatch_request
    return self.ensure_sync(self.view_functions[rule.endpoint])(**view_args)  # type: ignore[no-any-return]
  File "/home/amartinezi/sincere/api_scheduler_experiments.py", line 473, in inference
    model_usage_count[model_alias] += 1
NameError: name 'model_usage_count' is not defined
2024-09-23 14:13:06,510 127.0.0.1 - - [23/Sep/2024 14:13:06] "[35m[1mPOST /inference HTTP/1.1[0m" 500 -
2024-09-23 14:13:06,922 Request with ID 2df28320 for model gemma-7b received
2024-09-23 14:13:06,922 Exception on /inference [POST]
Traceback (most recent call last):
  File "/home/amartinezi/sincere/venv/lib64/python3.9/site-packages/flask/app.py", line 1473, in wsgi_app
    response = self.full_dispatch_request()
  File "/home/amartinezi/sincere/venv/lib64/python3.9/site-packages/flask/app.py", line 882, in full_dispatch_request
    rv = self.handle_user_exception(e)
  File "/home/amartinezi/sincere/venv/lib64/python3.9/site-packages/flask/app.py", line 880, in full_dispatch_request
    rv = self.dispatch_request()
  File "/home/amartinezi/sincere/venv/lib64/python3.9/site-packages/flask/app.py", line 865, in dispatch_request
    return self.ensure_sync(self.view_functions[rule.endpoint])(**view_args)  # type: ignore[no-any-return]
  File "/home/amartinezi/sincere/api_scheduler_experiments.py", line 473, in inference
    model_usage_count[model_alias] += 1
NameError: name 'model_usage_count' is not defined
2024-09-23 14:13:06,922 127.0.0.1 - - [23/Sep/2024 14:13:06] "[35m[1mPOST /inference HTTP/1.1[0m" 500 -
2024-09-23 14:13:06,926 Request with ID 762be4ae for model llama3-8b received
2024-09-23 14:13:06,926 Exception on /inference [POST]
Traceback (most recent call last):
  File "/home/amartinezi/sincere/venv/lib64/python3.9/site-packages/flask/app.py", line 1473, in wsgi_app
    response = self.full_dispatch_request()
  File "/home/amartinezi/sincere/venv/lib64/python3.9/site-packages/flask/app.py", line 882, in full_dispatch_request
    rv = self.handle_user_exception(e)
  File "/home/amartinezi/sincere/venv/lib64/python3.9/site-packages/flask/app.py", line 880, in full_dispatch_request
    rv = self.dispatch_request()
  File "/home/amartinezi/sincere/venv/lib64/python3.9/site-packages/flask/app.py", line 865, in dispatch_request
    return self.ensure_sync(self.view_functions[rule.endpoint])(**view_args)  # type: ignore[no-any-return]
  File "/home/amartinezi/sincere/api_scheduler_experiments.py", line 473, in inference
    model_usage_count[model_alias] += 1
NameError: name 'model_usage_count' is not defined
2024-09-23 14:13:06,927 127.0.0.1 - - [23/Sep/2024 14:13:06] "[35m[1mPOST /inference HTTP/1.1[0m" 500 -
2024-09-23 14:13:06,995 Request with ID 5293df98 for model gemma-7b received
2024-09-23 14:13:06,995 Exception on /inference [POST]
Traceback (most recent call last):
  File "/home/amartinezi/sincere/venv/lib64/python3.9/site-packages/flask/app.py", line 1473, in wsgi_app
    response = self.full_dispatch_request()
  File "/home/amartinezi/sincere/venv/lib64/python3.9/site-packages/flask/app.py", line 882, in full_dispatch_request
    rv = self.handle_user_exception(e)
  File "/home/amartinezi/sincere/venv/lib64/python3.9/site-packages/flask/app.py", line 880, in full_dispatch_request
    rv = self.dispatch_request()
  File "/home/amartinezi/sincere/venv/lib64/python3.9/site-packages/flask/app.py", line 865, in dispatch_request
    return self.ensure_sync(self.view_functions[rule.endpoint])(**view_args)  # type: ignore[no-any-return]
  File "/home/amartinezi/sincere/api_scheduler_experiments.py", line 473, in inference
    model_usage_count[model_alias] += 1
NameError: name 'model_usage_count' is not defined
2024-09-23 14:13:06,996 127.0.0.1 - - [23/Sep/2024 14:13:06] "[35m[1mPOST /inference HTTP/1.1[0m" 500 -
2024-09-23 14:13:07,295 Request with ID 5402fd86 for model gemma-7b received
2024-09-23 14:13:07,296 Exception on /inference [POST]
Traceback (most recent call last):
  File "/home/amartinezi/sincere/venv/lib64/python3.9/site-packages/flask/app.py", line 1473, in wsgi_app
    response = self.full_dispatch_request()
  File "/home/amartinezi/sincere/venv/lib64/python3.9/site-packages/flask/app.py", line 882, in full_dispatch_request
    rv = self.handle_user_exception(e)
  File "/home/amartinezi/sincere/venv/lib64/python3.9/site-packages/flask/app.py", line 880, in full_dispatch_request
    rv = self.dispatch_request()
  File "/home/amartinezi/sincere/venv/lib64/python3.9/site-packages/flask/app.py", line 865, in dispatch_request
    return self.ensure_sync(self.view_functions[rule.endpoint])(**view_args)  # type: ignore[no-any-return]
  File "/home/amartinezi/sincere/api_scheduler_experiments.py", line 473, in inference
    model_usage_count[model_alias] += 1
NameError: name 'model_usage_count' is not defined
2024-09-23 14:13:07,296 127.0.0.1 - - [23/Sep/2024 14:13:07] "[35m[1mPOST /inference HTTP/1.1[0m" 500 -
2024-09-23 14:13:07,381 Request with ID a321f364 for model llama3-8b received
2024-09-23 14:13:07,382 Exception on /inference [POST]
Traceback (most recent call last):
  File "/home/amartinezi/sincere/venv/lib64/python3.9/site-packages/flask/app.py", line 1473, in wsgi_app
    response = self.full_dispatch_request()
  File "/home/amartinezi/sincere/venv/lib64/python3.9/site-packages/flask/app.py", line 882, in full_dispatch_request
    rv = self.handle_user_exception(e)
  File "/home/amartinezi/sincere/venv/lib64/python3.9/site-packages/flask/app.py", line 880, in full_dispatch_request
    rv = self.dispatch_request()
  File "/home/amartinezi/sincere/venv/lib64/python3.9/site-packages/flask/app.py", line 865, in dispatch_request
    return self.ensure_sync(self.view_functions[rule.endpoint])(**view_args)  # type: ignore[no-any-return]
  File "/home/amartinezi/sincere/api_scheduler_experiments.py", line 473, in inference
    model_usage_count[model_alias] += 1
NameError: name 'model_usage_count' is not defined
2024-09-23 14:13:07,382 127.0.0.1 - - [23/Sep/2024 14:13:07] "[35m[1mPOST /inference HTTP/1.1[0m" 500 -
2024-09-23 14:13:07,495 Request with ID e8b49a37 for model gemma-7b received
2024-09-23 14:13:07,496 Exception on /inference [POST]
Traceback (most recent call last):
  File "/home/amartinezi/sincere/venv/lib64/python3.9/site-packages/flask/app.py", line 1473, in wsgi_app
    response = self.full_dispatch_request()
  File "/home/amartinezi/sincere/venv/lib64/python3.9/site-packages/flask/app.py", line 882, in full_dispatch_request
    rv = self.handle_user_exception(e)
  File "/home/amartinezi/sincere/venv/lib64/python3.9/site-packages/flask/app.py", line 880, in full_dispatch_request
    rv = self.dispatch_request()
  File "/home/amartinezi/sincere/venv/lib64/python3.9/site-packages/flask/app.py", line 865, in dispatch_request
    return self.ensure_sync(self.view_functions[rule.endpoint])(**view_args)  # type: ignore[no-any-return]
  File "/home/amartinezi/sincere/api_scheduler_experiments.py", line 473, in inference
    model_usage_count[model_alias] += 1
NameError: name 'model_usage_count' is not defined
2024-09-23 14:13:07,496 127.0.0.1 - - [23/Sep/2024 14:13:07] "[35m[1mPOST /inference HTTP/1.1[0m" 500 -
2024-09-23 14:13:07,531 Request with ID 8cf4135c for model gemma-7b received
2024-09-23 14:13:07,531 Exception on /inference [POST]
Traceback (most recent call last):
  File "/home/amartinezi/sincere/venv/lib64/python3.9/site-packages/flask/app.py", line 1473, in wsgi_app
    response = self.full_dispatch_request()
  File "/home/amartinezi/sincere/venv/lib64/python3.9/site-packages/flask/app.py", line 882, in full_dispatch_request
    rv = self.handle_user_exception(e)
  File "/home/amartinezi/sincere/venv/lib64/python3.9/site-packages/flask/app.py", line 880, in full_dispatch_request
    rv = self.dispatch_request()
  File "/home/amartinezi/sincere/venv/lib64/python3.9/site-packages/flask/app.py", line 865, in dispatch_request
    return self.ensure_sync(self.view_functions[rule.endpoint])(**view_args)  # type: ignore[no-any-return]
  File "/home/amartinezi/sincere/api_scheduler_experiments.py", line 473, in inference
    model_usage_count[model_alias] += 1
NameError: name 'model_usage_count' is not defined
2024-09-23 14:13:07,531 127.0.0.1 - - [23/Sep/2024 14:13:07] "[35m[1mPOST /inference HTTP/1.1[0m" 500 -
2024-09-23 14:13:07,658 Request with ID 35e31bd2 for model gemma-7b received
2024-09-23 14:13:07,659 Exception on /inference [POST]
Traceback (most recent call last):
  File "/home/amartinezi/sincere/venv/lib64/python3.9/site-packages/flask/app.py", line 1473, in wsgi_app
    response = self.full_dispatch_request()
  File "/home/amartinezi/sincere/venv/lib64/python3.9/site-packages/flask/app.py", line 882, in full_dispatch_request
    rv = self.handle_user_exception(e)
  File "/home/amartinezi/sincere/venv/lib64/python3.9/site-packages/flask/app.py", line 880, in full_dispatch_request
    rv = self.dispatch_request()
  File "/home/amartinezi/sincere/venv/lib64/python3.9/site-packages/flask/app.py", line 865, in dispatch_request
    return self.ensure_sync(self.view_functions[rule.endpoint])(**view_args)  # type: ignore[no-any-return]
  File "/home/amartinezi/sincere/api_scheduler_experiments.py", line 473, in inference
    model_usage_count[model_alias] += 1
NameError: name 'model_usage_count' is not defined
2024-09-23 14:13:07,659 127.0.0.1 - - [23/Sep/2024 14:13:07] "[35m[1mPOST /inference HTTP/1.1[0m" 500 -
2024-09-23 14:13:07,873 Request with ID fef20ea2 for model gemma-7b received
2024-09-23 14:13:07,873 Exception on /inference [POST]
Traceback (most recent call last):
  File "/home/amartinezi/sincere/venv/lib64/python3.9/site-packages/flask/app.py", line 1473, in wsgi_app
    response = self.full_dispatch_request()
  File "/home/amartinezi/sincere/venv/lib64/python3.9/site-packages/flask/app.py", line 882, in full_dispatch_request
    rv = self.handle_user_exception(e)
  File "/home/amartinezi/sincere/venv/lib64/python3.9/site-packages/flask/app.py", line 880, in full_dispatch_request
    rv = self.dispatch_request()
  File "/home/amartinezi/sincere/venv/lib64/python3.9/site-packages/flask/app.py", line 865, in dispatch_request
    return self.ensure_sync(self.view_functions[rule.endpoint])(**view_args)  # type: ignore[no-any-return]
  File "/home/amartinezi/sincere/api_scheduler_experiments.py", line 473, in inference
    model_usage_count[model_alias] += 1
NameError: name 'model_usage_count' is not defined
2024-09-23 14:13:07,874 127.0.0.1 - - [23/Sep/2024 14:13:07] "[35m[1mPOST /inference HTTP/1.1[0m" 500 -
2024-09-23 14:13:07,963 Request with ID aedef640 for model llama3-8b received
2024-09-23 14:13:07,963 Exception on /inference [POST]
Traceback (most recent call last):
  File "/home/amartinezi/sincere/venv/lib64/python3.9/site-packages/flask/app.py", line 1473, in wsgi_app
    response = self.full_dispatch_request()
  File "/home/amartinezi/sincere/venv/lib64/python3.9/site-packages/flask/app.py", line 882, in full_dispatch_request
    rv = self.handle_user_exception(e)
  File "/home/amartinezi/sincere/venv/lib64/python3.9/site-packages/flask/app.py", line 880, in full_dispatch_request
    rv = self.dispatch_request()
  File "/home/amartinezi/sincere/venv/lib64/python3.9/site-packages/flask/app.py", line 865, in dispatch_request
    return self.ensure_sync(self.view_functions[rule.endpoint])(**view_args)  # type: ignore[no-any-return]
  File "/home/amartinezi/sincere/api_scheduler_experiments.py", line 473, in inference
    model_usage_count[model_alias] += 1
NameError: name 'model_usage_count' is not defined
2024-09-23 14:13:07,964 127.0.0.1 - - [23/Sep/2024 14:13:07] "[35m[1mPOST /inference HTTP/1.1[0m" 500 -
2024-09-23 14:13:08,106 Request with ID cf14c56e for model llama3-8b received
2024-09-23 14:13:08,107 Exception on /inference [POST]
Traceback (most recent call last):
  File "/home/amartinezi/sincere/venv/lib64/python3.9/site-packages/flask/app.py", line 1473, in wsgi_app
    response = self.full_dispatch_request()
  File "/home/amartinezi/sincere/venv/lib64/python3.9/site-packages/flask/app.py", line 882, in full_dispatch_request
    rv = self.handle_user_exception(e)
  File "/home/amartinezi/sincere/venv/lib64/python3.9/site-packages/flask/app.py", line 880, in full_dispatch_request
    rv = self.dispatch_request()
  File "/home/amartinezi/sincere/venv/lib64/python3.9/site-packages/flask/app.py", line 865, in dispatch_request
    return self.ensure_sync(self.view_functions[rule.endpoint])(**view_args)  # type: ignore[no-any-return]
  File "/home/amartinezi/sincere/api_scheduler_experiments.py", line 473, in inference
    model_usage_count[model_alias] += 1
NameError: name 'model_usage_count' is not defined
2024-09-23 14:13:08,107 127.0.0.1 - - [23/Sep/2024 14:13:08] "[35m[1mPOST /inference HTTP/1.1[0m" 500 -
2024-09-23 14:13:08,139 Request with ID c9a978a2 for model gemma-7b received
2024-09-23 14:13:08,140 Exception on /inference [POST]
Traceback (most recent call last):
  File "/home/amartinezi/sincere/venv/lib64/python3.9/site-packages/flask/app.py", line 1473, in wsgi_app
    response = self.full_dispatch_request()
  File "/home/amartinezi/sincere/venv/lib64/python3.9/site-packages/flask/app.py", line 882, in full_dispatch_request
    rv = self.handle_user_exception(e)
  File "/home/amartinezi/sincere/venv/lib64/python3.9/site-packages/flask/app.py", line 880, in full_dispatch_request
    rv = self.dispatch_request()
  File "/home/amartinezi/sincere/venv/lib64/python3.9/site-packages/flask/app.py", line 865, in dispatch_request
    return self.ensure_sync(self.view_functions[rule.endpoint])(**view_args)  # type: ignore[no-any-return]
  File "/home/amartinezi/sincere/api_scheduler_experiments.py", line 473, in inference
    model_usage_count[model_alias] += 1
NameError: name 'model_usage_count' is not defined
2024-09-23 14:13:08,140 127.0.0.1 - - [23/Sep/2024 14:13:08] "[35m[1mPOST /inference HTTP/1.1[0m" 500 -
2024-09-23 14:13:08,289 Request with ID 93493572 for model llama3-8b received
2024-09-23 14:13:08,290 Exception on /inference [POST]
Traceback (most recent call last):
  File "/home/amartinezi/sincere/venv/lib64/python3.9/site-packages/flask/app.py", line 1473, in wsgi_app
    response = self.full_dispatch_request()
  File "/home/amartinezi/sincere/venv/lib64/python3.9/site-packages/flask/app.py", line 882, in full_dispatch_request
    rv = self.handle_user_exception(e)
  File "/home/amartinezi/sincere/venv/lib64/python3.9/site-packages/flask/app.py", line 880, in full_dispatch_request
    rv = self.dispatch_request()
  File "/home/amartinezi/sincere/venv/lib64/python3.9/site-packages/flask/app.py", line 865, in dispatch_request
    return self.ensure_sync(self.view_functions[rule.endpoint])(**view_args)  # type: ignore[no-any-return]
  File "/home/amartinezi/sincere/api_scheduler_experiments.py", line 473, in inference
    model_usage_count[model_alias] += 1
NameError: name 'model_usage_count' is not defined
2024-09-23 14:13:08,290 127.0.0.1 - - [23/Sep/2024 14:13:08] "[35m[1mPOST /inference HTTP/1.1[0m" 500 -
2024-09-23 14:13:08,519 Request with ID 580d7d91 for model gemma-7b received
2024-09-23 14:13:08,519 Exception on /inference [POST]
Traceback (most recent call last):
  File "/home/amartinezi/sincere/venv/lib64/python3.9/site-packages/flask/app.py", line 1473, in wsgi_app
    response = self.full_dispatch_request()
  File "/home/amartinezi/sincere/venv/lib64/python3.9/site-packages/flask/app.py", line 882, in full_dispatch_request
    rv = self.handle_user_exception(e)
  File "/home/amartinezi/sincere/venv/lib64/python3.9/site-packages/flask/app.py", line 880, in full_dispatch_request
    rv = self.dispatch_request()
  File "/home/amartinezi/sincere/venv/lib64/python3.9/site-packages/flask/app.py", line 865, in dispatch_request
    return self.ensure_sync(self.view_functions[rule.endpoint])(**view_args)  # type: ignore[no-any-return]
  File "/home/amartinezi/sincere/api_scheduler_experiments.py", line 473, in inference
    model_usage_count[model_alias] += 1
NameError: name 'model_usage_count' is not defined
2024-09-23 14:13:08,519 127.0.0.1 - - [23/Sep/2024 14:13:08] "[35m[1mPOST /inference HTTP/1.1[0m" 500 -
2024-09-23 14:13:08,534 Request with ID 94f5a678 for model llama3-8b received
2024-09-23 14:13:08,534 Exception on /inference [POST]
Traceback (most recent call last):
  File "/home/amartinezi/sincere/venv/lib64/python3.9/site-packages/flask/app.py", line 1473, in wsgi_app
    response = self.full_dispatch_request()
  File "/home/amartinezi/sincere/venv/lib64/python3.9/site-packages/flask/app.py", line 882, in full_dispatch_request
    rv = self.handle_user_exception(e)
  File "/home/amartinezi/sincere/venv/lib64/python3.9/site-packages/flask/app.py", line 880, in full_dispatch_request
    rv = self.dispatch_request()
  File "/home/amartinezi/sincere/venv/lib64/python3.9/site-packages/flask/app.py", line 865, in dispatch_request
    return self.ensure_sync(self.view_functions[rule.endpoint])(**view_args)  # type: ignore[no-any-return]
  File "/home/amartinezi/sincere/api_scheduler_experiments.py", line 473, in inference
    model_usage_count[model_alias] += 1
NameError: name 'model_usage_count' is not defined
2024-09-23 14:13:08,535 127.0.0.1 - - [23/Sep/2024 14:13:08] "[35m[1mPOST /inference HTTP/1.1[0m" 500 -
2024-09-23 14:13:08,573 Request with ID 69c3b1e3 for model gemma-7b received
2024-09-23 14:13:08,574 Exception on /inference [POST]
Traceback (most recent call last):
  File "/home/amartinezi/sincere/venv/lib64/python3.9/site-packages/flask/app.py", line 1473, in wsgi_app
    response = self.full_dispatch_request()
  File "/home/amartinezi/sincere/venv/lib64/python3.9/site-packages/flask/app.py", line 882, in full_dispatch_request
    rv = self.handle_user_exception(e)
  File "/home/amartinezi/sincere/venv/lib64/python3.9/site-packages/flask/app.py", line 880, in full_dispatch_request
    rv = self.dispatch_request()
  File "/home/amartinezi/sincere/venv/lib64/python3.9/site-packages/flask/app.py", line 865, in dispatch_request
    return self.ensure_sync(self.view_functions[rule.endpoint])(**view_args)  # type: ignore[no-any-return]
  File "/home/amartinezi/sincere/api_scheduler_experiments.py", line 473, in inference
    model_usage_count[model_alias] += 1
NameError: name 'model_usage_count' is not defined
2024-09-23 14:13:08,574 127.0.0.1 - - [23/Sep/2024 14:13:08] "[35m[1mPOST /inference HTTP/1.1[0m" 500 -
2024-09-23 14:13:09,079 Request with ID b5dfc3e1 for model gemma-7b received
2024-09-23 14:13:09,079 Exception on /inference [POST]
Traceback (most recent call last):
  File "/home/amartinezi/sincere/venv/lib64/python3.9/site-packages/flask/app.py", line 1473, in wsgi_app
    response = self.full_dispatch_request()
  File "/home/amartinezi/sincere/venv/lib64/python3.9/site-packages/flask/app.py", line 882, in full_dispatch_request
    rv = self.handle_user_exception(e)
  File "/home/amartinezi/sincere/venv/lib64/python3.9/site-packages/flask/app.py", line 880, in full_dispatch_request
    rv = self.dispatch_request()
  File "/home/amartinezi/sincere/venv/lib64/python3.9/site-packages/flask/app.py", line 865, in dispatch_request
    return self.ensure_sync(self.view_functions[rule.endpoint])(**view_args)  # type: ignore[no-any-return]
  File "/home/amartinezi/sincere/api_scheduler_experiments.py", line 473, in inference
    model_usage_count[model_alias] += 1
NameError: name 'model_usage_count' is not defined
2024-09-23 14:13:09,080 127.0.0.1 - - [23/Sep/2024 14:13:09] "[35m[1mPOST /inference HTTP/1.1[0m" 500 -
2024-09-23 14:13:09,091 Request with ID fe27307a for model llama3-8b received
2024-09-23 14:13:09,091 Exception on /inference [POST]
Traceback (most recent call last):
  File "/home/amartinezi/sincere/venv/lib64/python3.9/site-packages/flask/app.py", line 1473, in wsgi_app
    response = self.full_dispatch_request()
  File "/home/amartinezi/sincere/venv/lib64/python3.9/site-packages/flask/app.py", line 882, in full_dispatch_request
    rv = self.handle_user_exception(e)
  File "/home/amartinezi/sincere/venv/lib64/python3.9/site-packages/flask/app.py", line 880, in full_dispatch_request
    rv = self.dispatch_request()
  File "/home/amartinezi/sincere/venv/lib64/python3.9/site-packages/flask/app.py", line 865, in dispatch_request
    return self.ensure_sync(self.view_functions[rule.endpoint])(**view_args)  # type: ignore[no-any-return]
  File "/home/amartinezi/sincere/api_scheduler_experiments.py", line 473, in inference
    model_usage_count[model_alias] += 1
NameError: name 'model_usage_count' is not defined
2024-09-23 14:13:09,091 127.0.0.1 - - [23/Sep/2024 14:13:09] "[35m[1mPOST /inference HTTP/1.1[0m" 500 -
2024-09-23 14:13:09,219 Request with ID 2e36a960 for model gemma-7b received
2024-09-23 14:13:09,219 Exception on /inference [POST]
Traceback (most recent call last):
  File "/home/amartinezi/sincere/venv/lib64/python3.9/site-packages/flask/app.py", line 1473, in wsgi_app
    response = self.full_dispatch_request()
  File "/home/amartinezi/sincere/venv/lib64/python3.9/site-packages/flask/app.py", line 882, in full_dispatch_request
    rv = self.handle_user_exception(e)
  File "/home/amartinezi/sincere/venv/lib64/python3.9/site-packages/flask/app.py", line 880, in full_dispatch_request
    rv = self.dispatch_request()
  File "/home/amartinezi/sincere/venv/lib64/python3.9/site-packages/flask/app.py", line 865, in dispatch_request
    return self.ensure_sync(self.view_functions[rule.endpoint])(**view_args)  # type: ignore[no-any-return]
  File "/home/amartinezi/sincere/api_scheduler_experiments.py", line 473, in inference
    model_usage_count[model_alias] += 1
NameError: name 'model_usage_count' is not defined
2024-09-23 14:13:09,219 127.0.0.1 - - [23/Sep/2024 14:13:09] "[35m[1mPOST /inference HTTP/1.1[0m" 500 -
2024-09-23 14:13:09,371 Request with ID 0a6d2ac5 for model llama3-8b received
2024-09-23 14:13:09,371 Exception on /inference [POST]
Traceback (most recent call last):
  File "/home/amartinezi/sincere/venv/lib64/python3.9/site-packages/flask/app.py", line 1473, in wsgi_app
    response = self.full_dispatch_request()
  File "/home/amartinezi/sincere/venv/lib64/python3.9/site-packages/flask/app.py", line 882, in full_dispatch_request
    rv = self.handle_user_exception(e)
  File "/home/amartinezi/sincere/venv/lib64/python3.9/site-packages/flask/app.py", line 880, in full_dispatch_request
    rv = self.dispatch_request()
  File "/home/amartinezi/sincere/venv/lib64/python3.9/site-packages/flask/app.py", line 865, in dispatch_request
    return self.ensure_sync(self.view_functions[rule.endpoint])(**view_args)  # type: ignore[no-any-return]
  File "/home/amartinezi/sincere/api_scheduler_experiments.py", line 473, in inference
    model_usage_count[model_alias] += 1
NameError: name 'model_usage_count' is not defined
2024-09-23 14:13:09,371 127.0.0.1 - - [23/Sep/2024 14:13:09] "[35m[1mPOST /inference HTTP/1.1[0m" 500 -
2024-09-23 14:13:09,436 Request with ID 551fb3ec for model llama3-8b received
2024-09-23 14:13:09,436 Exception on /inference [POST]
Traceback (most recent call last):
  File "/home/amartinezi/sincere/venv/lib64/python3.9/site-packages/flask/app.py", line 1473, in wsgi_app
    response = self.full_dispatch_request()
  File "/home/amartinezi/sincere/venv/lib64/python3.9/site-packages/flask/app.py", line 882, in full_dispatch_request
    rv = self.handle_user_exception(e)
  File "/home/amartinezi/sincere/venv/lib64/python3.9/site-packages/flask/app.py", line 880, in full_dispatch_request
    rv = self.dispatch_request()
  File "/home/amartinezi/sincere/venv/lib64/python3.9/site-packages/flask/app.py", line 865, in dispatch_request
    return self.ensure_sync(self.view_functions[rule.endpoint])(**view_args)  # type: ignore[no-any-return]
  File "/home/amartinezi/sincere/api_scheduler_experiments.py", line 473, in inference
    model_usage_count[model_alias] += 1
NameError: name 'model_usage_count' is not defined
2024-09-23 14:13:09,437 127.0.0.1 - - [23/Sep/2024 14:13:09] "[35m[1mPOST /inference HTTP/1.1[0m" 500 -
2024-09-23 14:13:09,448 Request with ID 14a6855d for model llama3-8b received
2024-09-23 14:13:09,448 Exception on /inference [POST]
Traceback (most recent call last):
  File "/home/amartinezi/sincere/venv/lib64/python3.9/site-packages/flask/app.py", line 1473, in wsgi_app
    response = self.full_dispatch_request()
  File "/home/amartinezi/sincere/venv/lib64/python3.9/site-packages/flask/app.py", line 882, in full_dispatch_request
    rv = self.handle_user_exception(e)
  File "/home/amartinezi/sincere/venv/lib64/python3.9/site-packages/flask/app.py", line 880, in full_dispatch_request
    rv = self.dispatch_request()
  File "/home/amartinezi/sincere/venv/lib64/python3.9/site-packages/flask/app.py", line 865, in dispatch_request
    return self.ensure_sync(self.view_functions[rule.endpoint])(**view_args)  # type: ignore[no-any-return]
  File "/home/amartinezi/sincere/api_scheduler_experiments.py", line 473, in inference
    model_usage_count[model_alias] += 1
NameError: name 'model_usage_count' is not defined
2024-09-23 14:13:09,448 127.0.0.1 - - [23/Sep/2024 14:13:09] "[35m[1mPOST /inference HTTP/1.1[0m" 500 -
2024-09-23 14:13:09,567 Request with ID 99407b7e for model llama3-8b received
2024-09-23 14:13:09,569 Request with ID 5ce8273c for model gemma-7b received
2024-09-23 14:13:09,569 Exception on /inference [POST]
Traceback (most recent call last):
  File "/home/amartinezi/sincere/venv/lib64/python3.9/site-packages/flask/app.py", line 1473, in wsgi_app
    response = self.full_dispatch_request()
  File "/home/amartinezi/sincere/venv/lib64/python3.9/site-packages/flask/app.py", line 882, in full_dispatch_request
    rv = self.handle_user_exception(e)
  File "/home/amartinezi/sincere/venv/lib64/python3.9/site-packages/flask/app.py", line 880, in full_dispatch_request
    rv = self.dispatch_request()
  File "/home/amartinezi/sincere/venv/lib64/python3.9/site-packages/flask/app.py", line 865, in dispatch_request
    return self.ensure_sync(self.view_functions[rule.endpoint])(**view_args)  # type: ignore[no-any-return]
  File "/home/amartinezi/sincere/api_scheduler_experiments.py", line 473, in inference
    model_usage_count[model_alias] += 1
NameError: name 'model_usage_count' is not defined
2024-09-23 14:13:09,569 Exception on /inference [POST]
Traceback (most recent call last):
  File "/home/amartinezi/sincere/venv/lib64/python3.9/site-packages/flask/app.py", line 1473, in wsgi_app
    response = self.full_dispatch_request()
  File "/home/amartinezi/sincere/venv/lib64/python3.9/site-packages/flask/app.py", line 882, in full_dispatch_request
    rv = self.handle_user_exception(e)
  File "/home/amartinezi/sincere/venv/lib64/python3.9/site-packages/flask/app.py", line 880, in full_dispatch_request
    rv = self.dispatch_request()
  File "/home/amartinezi/sincere/venv/lib64/python3.9/site-packages/flask/app.py", line 865, in dispatch_request
    return self.ensure_sync(self.view_functions[rule.endpoint])(**view_args)  # type: ignore[no-any-return]
  File "/home/amartinezi/sincere/api_scheduler_experiments.py", line 473, in inference
    model_usage_count[model_alias] += 1
NameError: name 'model_usage_count' is not defined
2024-09-23 14:13:09,570 127.0.0.1 - - [23/Sep/2024 14:13:09] "[35m[1mPOST /inference HTTP/1.1[0m" 500 -
2024-09-23 14:13:09,571 127.0.0.1 - - [23/Sep/2024 14:13:09] "[35m[1mPOST /inference HTTP/1.1[0m" 500 -
2024-09-23 14:13:09,652 Request with ID 94c847a4 for model gemma-7b received
2024-09-23 14:13:09,653 Exception on /inference [POST]
Traceback (most recent call last):
  File "/home/amartinezi/sincere/venv/lib64/python3.9/site-packages/flask/app.py", line 1473, in wsgi_app
    response = self.full_dispatch_request()
  File "/home/amartinezi/sincere/venv/lib64/python3.9/site-packages/flask/app.py", line 882, in full_dispatch_request
    rv = self.handle_user_exception(e)
  File "/home/amartinezi/sincere/venv/lib64/python3.9/site-packages/flask/app.py", line 880, in full_dispatch_request
    rv = self.dispatch_request()
  File "/home/amartinezi/sincere/venv/lib64/python3.9/site-packages/flask/app.py", line 865, in dispatch_request
    return self.ensure_sync(self.view_functions[rule.endpoint])(**view_args)  # type: ignore[no-any-return]
  File "/home/amartinezi/sincere/api_scheduler_experiments.py", line 473, in inference
    model_usage_count[model_alias] += 1
NameError: name 'model_usage_count' is not defined
2024-09-23 14:13:09,653 127.0.0.1 - - [23/Sep/2024 14:13:09] "[35m[1mPOST /inference HTTP/1.1[0m" 500 -
2024-09-23 14:13:09,810 Request with ID bcf9822a for model gemma-7b received
2024-09-23 14:13:09,810 Exception on /inference [POST]
Traceback (most recent call last):
  File "/home/amartinezi/sincere/venv/lib64/python3.9/site-packages/flask/app.py", line 1473, in wsgi_app
    response = self.full_dispatch_request()
  File "/home/amartinezi/sincere/venv/lib64/python3.9/site-packages/flask/app.py", line 882, in full_dispatch_request
    rv = self.handle_user_exception(e)
  File "/home/amartinezi/sincere/venv/lib64/python3.9/site-packages/flask/app.py", line 880, in full_dispatch_request
    rv = self.dispatch_request()
  File "/home/amartinezi/sincere/venv/lib64/python3.9/site-packages/flask/app.py", line 865, in dispatch_request
    return self.ensure_sync(self.view_functions[rule.endpoint])(**view_args)  # type: ignore[no-any-return]
  File "/home/amartinezi/sincere/api_scheduler_experiments.py", line 473, in inference
    model_usage_count[model_alias] += 1
NameError: name 'model_usage_count' is not defined
2024-09-23 14:13:09,810 127.0.0.1 - - [23/Sep/2024 14:13:09] "[35m[1mPOST /inference HTTP/1.1[0m" 500 -
2024-09-23 14:13:09,983 Request with ID 060b0b35 for model llama3-8b received
2024-09-23 14:13:09,983 Exception on /inference [POST]
Traceback (most recent call last):
  File "/home/amartinezi/sincere/venv/lib64/python3.9/site-packages/flask/app.py", line 1473, in wsgi_app
    response = self.full_dispatch_request()
  File "/home/amartinezi/sincere/venv/lib64/python3.9/site-packages/flask/app.py", line 882, in full_dispatch_request
    rv = self.handle_user_exception(e)
  File "/home/amartinezi/sincere/venv/lib64/python3.9/site-packages/flask/app.py", line 880, in full_dispatch_request
    rv = self.dispatch_request()
  File "/home/amartinezi/sincere/venv/lib64/python3.9/site-packages/flask/app.py", line 865, in dispatch_request
    return self.ensure_sync(self.view_functions[rule.endpoint])(**view_args)  # type: ignore[no-any-return]
  File "/home/amartinezi/sincere/api_scheduler_experiments.py", line 473, in inference
    model_usage_count[model_alias] += 1
NameError: name 'model_usage_count' is not defined
2024-09-23 14:13:09,984 127.0.0.1 - - [23/Sep/2024 14:13:09] "[35m[1mPOST /inference HTTP/1.1[0m" 500 -
2024-09-23 14:13:10,144 Request with ID 152781ca for model llama3-8b received
2024-09-23 14:13:10,144 Exception on /inference [POST]
Traceback (most recent call last):
  File "/home/amartinezi/sincere/venv/lib64/python3.9/site-packages/flask/app.py", line 1473, in wsgi_app
    response = self.full_dispatch_request()
  File "/home/amartinezi/sincere/venv/lib64/python3.9/site-packages/flask/app.py", line 882, in full_dispatch_request
    rv = self.handle_user_exception(e)
  File "/home/amartinezi/sincere/venv/lib64/python3.9/site-packages/flask/app.py", line 880, in full_dispatch_request
    rv = self.dispatch_request()
  File "/home/amartinezi/sincere/venv/lib64/python3.9/site-packages/flask/app.py", line 865, in dispatch_request
    return self.ensure_sync(self.view_functions[rule.endpoint])(**view_args)  # type: ignore[no-any-return]
  File "/home/amartinezi/sincere/api_scheduler_experiments.py", line 473, in inference
    model_usage_count[model_alias] += 1
NameError: name 'model_usage_count' is not defined
2024-09-23 14:13:10,145 127.0.0.1 - - [23/Sep/2024 14:13:10] "[35m[1mPOST /inference HTTP/1.1[0m" 500 -
2024-09-23 14:13:10,157 Request with ID 94c2ccf7 for model gemma-7b received
2024-09-23 14:13:10,158 Exception on /inference [POST]
Traceback (most recent call last):
  File "/home/amartinezi/sincere/venv/lib64/python3.9/site-packages/flask/app.py", line 1473, in wsgi_app
    response = self.full_dispatch_request()
  File "/home/amartinezi/sincere/venv/lib64/python3.9/site-packages/flask/app.py", line 882, in full_dispatch_request
    rv = self.handle_user_exception(e)
  File "/home/amartinezi/sincere/venv/lib64/python3.9/site-packages/flask/app.py", line 880, in full_dispatch_request
    rv = self.dispatch_request()
  File "/home/amartinezi/sincere/venv/lib64/python3.9/site-packages/flask/app.py", line 865, in dispatch_request
    return self.ensure_sync(self.view_functions[rule.endpoint])(**view_args)  # type: ignore[no-any-return]
  File "/home/amartinezi/sincere/api_scheduler_experiments.py", line 473, in inference
    model_usage_count[model_alias] += 1
NameError: name 'model_usage_count' is not defined
2024-09-23 14:13:10,158 127.0.0.1 - - [23/Sep/2024 14:13:10] "[35m[1mPOST /inference HTTP/1.1[0m" 500 -
2024-09-23 14:13:10,194 Request with ID a3088aa6 for model llama3-8b received
2024-09-23 14:13:10,195 Exception on /inference [POST]
Traceback (most recent call last):
  File "/home/amartinezi/sincere/venv/lib64/python3.9/site-packages/flask/app.py", line 1473, in wsgi_app
    response = self.full_dispatch_request()
  File "/home/amartinezi/sincere/venv/lib64/python3.9/site-packages/flask/app.py", line 882, in full_dispatch_request
    rv = self.handle_user_exception(e)
  File "/home/amartinezi/sincere/venv/lib64/python3.9/site-packages/flask/app.py", line 880, in full_dispatch_request
    rv = self.dispatch_request()
  File "/home/amartinezi/sincere/venv/lib64/python3.9/site-packages/flask/app.py", line 865, in dispatch_request
    return self.ensure_sync(self.view_functions[rule.endpoint])(**view_args)  # type: ignore[no-any-return]
  File "/home/amartinezi/sincere/api_scheduler_experiments.py", line 473, in inference
    model_usage_count[model_alias] += 1
NameError: name 'model_usage_count' is not defined
2024-09-23 14:13:10,195 127.0.0.1 - - [23/Sep/2024 14:13:10] "[35m[1mPOST /inference HTTP/1.1[0m" 500 -
2024-09-23 14:13:10,281 Request with ID 0795b45f for model llama3-8b received
2024-09-23 14:13:10,281 Exception on /inference [POST]
Traceback (most recent call last):
  File "/home/amartinezi/sincere/venv/lib64/python3.9/site-packages/flask/app.py", line 1473, in wsgi_app
    response = self.full_dispatch_request()
  File "/home/amartinezi/sincere/venv/lib64/python3.9/site-packages/flask/app.py", line 882, in full_dispatch_request
    rv = self.handle_user_exception(e)
  File "/home/amartinezi/sincere/venv/lib64/python3.9/site-packages/flask/app.py", line 880, in full_dispatch_request
    rv = self.dispatch_request()
  File "/home/amartinezi/sincere/venv/lib64/python3.9/site-packages/flask/app.py", line 865, in dispatch_request
    return self.ensure_sync(self.view_functions[rule.endpoint])(**view_args)  # type: ignore[no-any-return]
  File "/home/amartinezi/sincere/api_scheduler_experiments.py", line 473, in inference
    model_usage_count[model_alias] += 1
NameError: name 'model_usage_count' is not defined
2024-09-23 14:13:10,282 127.0.0.1 - - [23/Sep/2024 14:13:10] "[35m[1mPOST /inference HTTP/1.1[0m" 500 -
2024-09-23 14:13:10,480 Request with ID c1113838 for model llama3-8b received
2024-09-23 14:13:10,480 Exception on /inference [POST]
Traceback (most recent call last):
  File "/home/amartinezi/sincere/venv/lib64/python3.9/site-packages/flask/app.py", line 1473, in wsgi_app
    response = self.full_dispatch_request()
  File "/home/amartinezi/sincere/venv/lib64/python3.9/site-packages/flask/app.py", line 882, in full_dispatch_request
    rv = self.handle_user_exception(e)
  File "/home/amartinezi/sincere/venv/lib64/python3.9/site-packages/flask/app.py", line 880, in full_dispatch_request
    rv = self.dispatch_request()
  File "/home/amartinezi/sincere/venv/lib64/python3.9/site-packages/flask/app.py", line 865, in dispatch_request
    return self.ensure_sync(self.view_functions[rule.endpoint])(**view_args)  # type: ignore[no-any-return]
  File "/home/amartinezi/sincere/api_scheduler_experiments.py", line 473, in inference
    model_usage_count[model_alias] += 1
NameError: name 'model_usage_count' is not defined
2024-09-23 14:13:10,481 127.0.0.1 - - [23/Sep/2024 14:13:10] "[35m[1mPOST /inference HTTP/1.1[0m" 500 -
2024-09-23 14:13:10,620 Request with ID 040a4684 for model gemma-7b received
2024-09-23 14:13:10,620 Exception on /inference [POST]
Traceback (most recent call last):
  File "/home/amartinezi/sincere/venv/lib64/python3.9/site-packages/flask/app.py", line 1473, in wsgi_app
    response = self.full_dispatch_request()
  File "/home/amartinezi/sincere/venv/lib64/python3.9/site-packages/flask/app.py", line 882, in full_dispatch_request
    rv = self.handle_user_exception(e)
  File "/home/amartinezi/sincere/venv/lib64/python3.9/site-packages/flask/app.py", line 880, in full_dispatch_request
    rv = self.dispatch_request()
  File "/home/amartinezi/sincere/venv/lib64/python3.9/site-packages/flask/app.py", line 865, in dispatch_request
    return self.ensure_sync(self.view_functions[rule.endpoint])(**view_args)  # type: ignore[no-any-return]
  File "/home/amartinezi/sincere/api_scheduler_experiments.py", line 473, in inference
    model_usage_count[model_alias] += 1
NameError: name 'model_usage_count' is not defined
2024-09-23 14:13:10,621 127.0.0.1 - - [23/Sep/2024 14:13:10] "[35m[1mPOST /inference HTTP/1.1[0m" 500 -
2024-09-23 14:13:10,782 Request with ID 73349763 for model llama3-8b received
2024-09-23 14:13:10,783 Exception on /inference [POST]
Traceback (most recent call last):
  File "/home/amartinezi/sincere/venv/lib64/python3.9/site-packages/flask/app.py", line 1473, in wsgi_app
    response = self.full_dispatch_request()
  File "/home/amartinezi/sincere/venv/lib64/python3.9/site-packages/flask/app.py", line 882, in full_dispatch_request
    rv = self.handle_user_exception(e)
  File "/home/amartinezi/sincere/venv/lib64/python3.9/site-packages/flask/app.py", line 880, in full_dispatch_request
    rv = self.dispatch_request()
  File "/home/amartinezi/sincere/venv/lib64/python3.9/site-packages/flask/app.py", line 865, in dispatch_request
    return self.ensure_sync(self.view_functions[rule.endpoint])(**view_args)  # type: ignore[no-any-return]
  File "/home/amartinezi/sincere/api_scheduler_experiments.py", line 473, in inference
    model_usage_count[model_alias] += 1
NameError: name 'model_usage_count' is not defined
2024-09-23 14:13:10,783 127.0.0.1 - - [23/Sep/2024 14:13:10] "[35m[1mPOST /inference HTTP/1.1[0m" 500 -
2024-09-23 14:13:10,967 Request with ID 30cf8d70 for model llama3-8b received
2024-09-23 14:13:10,967 Exception on /inference [POST]
Traceback (most recent call last):
  File "/home/amartinezi/sincere/venv/lib64/python3.9/site-packages/flask/app.py", line 1473, in wsgi_app
    response = self.full_dispatch_request()
  File "/home/amartinezi/sincere/venv/lib64/python3.9/site-packages/flask/app.py", line 882, in full_dispatch_request
    rv = self.handle_user_exception(e)
  File "/home/amartinezi/sincere/venv/lib64/python3.9/site-packages/flask/app.py", line 880, in full_dispatch_request
    rv = self.dispatch_request()
  File "/home/amartinezi/sincere/venv/lib64/python3.9/site-packages/flask/app.py", line 865, in dispatch_request
    return self.ensure_sync(self.view_functions[rule.endpoint])(**view_args)  # type: ignore[no-any-return]
  File "/home/amartinezi/sincere/api_scheduler_experiments.py", line 473, in inference
    model_usage_count[model_alias] += 1
NameError: name 'model_usage_count' is not defined
2024-09-23 14:13:10,967 127.0.0.1 - - [23/Sep/2024 14:13:10] "[35m[1mPOST /inference HTTP/1.1[0m" 500 -
2024-09-23 14:13:11,047 Request with ID 9498efa1 for model llama3-8b received
2024-09-23 14:13:11,048 Exception on /inference [POST]
Traceback (most recent call last):
  File "/home/amartinezi/sincere/venv/lib64/python3.9/site-packages/flask/app.py", line 1473, in wsgi_app
    response = self.full_dispatch_request()
  File "/home/amartinezi/sincere/venv/lib64/python3.9/site-packages/flask/app.py", line 882, in full_dispatch_request
    rv = self.handle_user_exception(e)
  File "/home/amartinezi/sincere/venv/lib64/python3.9/site-packages/flask/app.py", line 880, in full_dispatch_request
    rv = self.dispatch_request()
  File "/home/amartinezi/sincere/venv/lib64/python3.9/site-packages/flask/app.py", line 865, in dispatch_request
    return self.ensure_sync(self.view_functions[rule.endpoint])(**view_args)  # type: ignore[no-any-return]
  File "/home/amartinezi/sincere/api_scheduler_experiments.py", line 473, in inference
    model_usage_count[model_alias] += 1
NameError: name 'model_usage_count' is not defined
2024-09-23 14:13:11,048 127.0.0.1 - - [23/Sep/2024 14:13:11] "[35m[1mPOST /inference HTTP/1.1[0m" 500 -
2024-09-23 14:13:11,107 Request with ID bb05ce5d for model llama3-8b received
2024-09-23 14:13:11,107 Exception on /inference [POST]
Traceback (most recent call last):
  File "/home/amartinezi/sincere/venv/lib64/python3.9/site-packages/flask/app.py", line 1473, in wsgi_app
    response = self.full_dispatch_request()
  File "/home/amartinezi/sincere/venv/lib64/python3.9/site-packages/flask/app.py", line 882, in full_dispatch_request
    rv = self.handle_user_exception(e)
  File "/home/amartinezi/sincere/venv/lib64/python3.9/site-packages/flask/app.py", line 880, in full_dispatch_request
    rv = self.dispatch_request()
  File "/home/amartinezi/sincere/venv/lib64/python3.9/site-packages/flask/app.py", line 865, in dispatch_request
    return self.ensure_sync(self.view_functions[rule.endpoint])(**view_args)  # type: ignore[no-any-return]
  File "/home/amartinezi/sincere/api_scheduler_experiments.py", line 473, in inference
    model_usage_count[model_alias] += 1
NameError: name 'model_usage_count' is not defined
2024-09-23 14:13:11,108 127.0.0.1 - - [23/Sep/2024 14:13:11] "[35m[1mPOST /inference HTTP/1.1[0m" 500 -
2024-09-23 14:13:11,159 Request with ID c1557dba for model llama3-8b received
2024-09-23 14:13:11,159 Exception on /inference [POST]
Traceback (most recent call last):
  File "/home/amartinezi/sincere/venv/lib64/python3.9/site-packages/flask/app.py", line 1473, in wsgi_app
    response = self.full_dispatch_request()
  File "/home/amartinezi/sincere/venv/lib64/python3.9/site-packages/flask/app.py", line 882, in full_dispatch_request
    rv = self.handle_user_exception(e)
  File "/home/amartinezi/sincere/venv/lib64/python3.9/site-packages/flask/app.py", line 880, in full_dispatch_request
    rv = self.dispatch_request()
  File "/home/amartinezi/sincere/venv/lib64/python3.9/site-packages/flask/app.py", line 865, in dispatch_request
    return self.ensure_sync(self.view_functions[rule.endpoint])(**view_args)  # type: ignore[no-any-return]
  File "/home/amartinezi/sincere/api_scheduler_experiments.py", line 473, in inference
    model_usage_count[model_alias] += 1
NameError: name 'model_usage_count' is not defined
2024-09-23 14:13:11,160 127.0.0.1 - - [23/Sep/2024 14:13:11] "[35m[1mPOST /inference HTTP/1.1[0m" 500 -
2024-09-23 14:13:11,576 Request with ID 8732db4d for model granite-7b received
2024-09-23 14:13:11,576 Exception on /inference [POST]
Traceback (most recent call last):
  File "/home/amartinezi/sincere/venv/lib64/python3.9/site-packages/flask/app.py", line 1473, in wsgi_app
    response = self.full_dispatch_request()
  File "/home/amartinezi/sincere/venv/lib64/python3.9/site-packages/flask/app.py", line 882, in full_dispatch_request
    rv = self.handle_user_exception(e)
  File "/home/amartinezi/sincere/venv/lib64/python3.9/site-packages/flask/app.py", line 880, in full_dispatch_request
    rv = self.dispatch_request()
  File "/home/amartinezi/sincere/venv/lib64/python3.9/site-packages/flask/app.py", line 865, in dispatch_request
    return self.ensure_sync(self.view_functions[rule.endpoint])(**view_args)  # type: ignore[no-any-return]
  File "/home/amartinezi/sincere/api_scheduler_experiments.py", line 473, in inference
    model_usage_count[model_alias] += 1
NameError: name 'model_usage_count' is not defined
2024-09-23 14:13:11,577 127.0.0.1 - - [23/Sep/2024 14:13:11] "[35m[1mPOST /inference HTTP/1.1[0m" 500 -
2024-09-23 14:13:11,624 Request with ID 8b0e2ac1 for model gemma-7b received
2024-09-23 14:13:11,624 Exception on /inference [POST]
Traceback (most recent call last):
  File "/home/amartinezi/sincere/venv/lib64/python3.9/site-packages/flask/app.py", line 1473, in wsgi_app
    response = self.full_dispatch_request()
  File "/home/amartinezi/sincere/venv/lib64/python3.9/site-packages/flask/app.py", line 882, in full_dispatch_request
    rv = self.handle_user_exception(e)
  File "/home/amartinezi/sincere/venv/lib64/python3.9/site-packages/flask/app.py", line 880, in full_dispatch_request
    rv = self.dispatch_request()
  File "/home/amartinezi/sincere/venv/lib64/python3.9/site-packages/flask/app.py", line 865, in dispatch_request
    return self.ensure_sync(self.view_functions[rule.endpoint])(**view_args)  # type: ignore[no-any-return]
  File "/home/amartinezi/sincere/api_scheduler_experiments.py", line 473, in inference
    model_usage_count[model_alias] += 1
NameError: name 'model_usage_count' is not defined
2024-09-23 14:13:11,624 127.0.0.1 - - [23/Sep/2024 14:13:11] "[35m[1mPOST /inference HTTP/1.1[0m" 500 -
2024-09-23 14:13:11,707 Request with ID 6520d675 for model llama3-8b received
2024-09-23 14:13:11,708 Exception on /inference [POST]
Traceback (most recent call last):
  File "/home/amartinezi/sincere/venv/lib64/python3.9/site-packages/flask/app.py", line 1473, in wsgi_app
    response = self.full_dispatch_request()
  File "/home/amartinezi/sincere/venv/lib64/python3.9/site-packages/flask/app.py", line 882, in full_dispatch_request
    rv = self.handle_user_exception(e)
  File "/home/amartinezi/sincere/venv/lib64/python3.9/site-packages/flask/app.py", line 880, in full_dispatch_request
    rv = self.dispatch_request()
  File "/home/amartinezi/sincere/venv/lib64/python3.9/site-packages/flask/app.py", line 865, in dispatch_request
    return self.ensure_sync(self.view_functions[rule.endpoint])(**view_args)  # type: ignore[no-any-return]
  File "/home/amartinezi/sincere/api_scheduler_experiments.py", line 473, in inference
    model_usage_count[model_alias] += 1
NameError: name 'model_usage_count' is not defined
2024-09-23 14:13:11,708 127.0.0.1 - - [23/Sep/2024 14:13:11] "[35m[1mPOST /inference HTTP/1.1[0m" 500 -
2024-09-23 14:13:12,054 Request with ID 6e9624a2 for model llama3-8b received
2024-09-23 14:13:12,054 Exception on /inference [POST]
Traceback (most recent call last):
  File "/home/amartinezi/sincere/venv/lib64/python3.9/site-packages/flask/app.py", line 1473, in wsgi_app
    response = self.full_dispatch_request()
  File "/home/amartinezi/sincere/venv/lib64/python3.9/site-packages/flask/app.py", line 882, in full_dispatch_request
    rv = self.handle_user_exception(e)
  File "/home/amartinezi/sincere/venv/lib64/python3.9/site-packages/flask/app.py", line 880, in full_dispatch_request
    rv = self.dispatch_request()
  File "/home/amartinezi/sincere/venv/lib64/python3.9/site-packages/flask/app.py", line 865, in dispatch_request
    return self.ensure_sync(self.view_functions[rule.endpoint])(**view_args)  # type: ignore[no-any-return]
  File "/home/amartinezi/sincere/api_scheduler_experiments.py", line 473, in inference
    model_usage_count[model_alias] += 1
NameError: name 'model_usage_count' is not defined
2024-09-23 14:13:12,054 127.0.0.1 - - [23/Sep/2024 14:13:12] "[35m[1mPOST /inference HTTP/1.1[0m" 500 -
2024-09-23 14:13:12,063 Request with ID 6f5e945c for model llama3-8b received
2024-09-23 14:13:12,064 Exception on /inference [POST]
Traceback (most recent call last):
  File "/home/amartinezi/sincere/venv/lib64/python3.9/site-packages/flask/app.py", line 1473, in wsgi_app
    response = self.full_dispatch_request()
  File "/home/amartinezi/sincere/venv/lib64/python3.9/site-packages/flask/app.py", line 882, in full_dispatch_request
    rv = self.handle_user_exception(e)
  File "/home/amartinezi/sincere/venv/lib64/python3.9/site-packages/flask/app.py", line 880, in full_dispatch_request
    rv = self.dispatch_request()
  File "/home/amartinezi/sincere/venv/lib64/python3.9/site-packages/flask/app.py", line 865, in dispatch_request
    return self.ensure_sync(self.view_functions[rule.endpoint])(**view_args)  # type: ignore[no-any-return]
  File "/home/amartinezi/sincere/api_scheduler_experiments.py", line 473, in inference
    model_usage_count[model_alias] += 1
NameError: name 'model_usage_count' is not defined
2024-09-23 14:13:12,064 127.0.0.1 - - [23/Sep/2024 14:13:12] "[35m[1mPOST /inference HTTP/1.1[0m" 500 -
2024-09-23 14:13:12,644 Request with ID 4b8511ad for model gemma-7b received
2024-09-23 14:13:12,644 Exception on /inference [POST]
Traceback (most recent call last):
  File "/home/amartinezi/sincere/venv/lib64/python3.9/site-packages/flask/app.py", line 1473, in wsgi_app
    response = self.full_dispatch_request()
  File "/home/amartinezi/sincere/venv/lib64/python3.9/site-packages/flask/app.py", line 882, in full_dispatch_request
    rv = self.handle_user_exception(e)
  File "/home/amartinezi/sincere/venv/lib64/python3.9/site-packages/flask/app.py", line 880, in full_dispatch_request
    rv = self.dispatch_request()
  File "/home/amartinezi/sincere/venv/lib64/python3.9/site-packages/flask/app.py", line 865, in dispatch_request
    return self.ensure_sync(self.view_functions[rule.endpoint])(**view_args)  # type: ignore[no-any-return]
  File "/home/amartinezi/sincere/api_scheduler_experiments.py", line 473, in inference
    model_usage_count[model_alias] += 1
NameError: name 'model_usage_count' is not defined
2024-09-23 14:13:12,645 127.0.0.1 - - [23/Sep/2024 14:13:12] "[35m[1mPOST /inference HTTP/1.1[0m" 500 -
2024-09-23 14:13:12,694 Request with ID b625d983 for model gemma-7b received
2024-09-23 14:13:12,694 Exception on /inference [POST]
Traceback (most recent call last):
  File "/home/amartinezi/sincere/venv/lib64/python3.9/site-packages/flask/app.py", line 1473, in wsgi_app
    response = self.full_dispatch_request()
  File "/home/amartinezi/sincere/venv/lib64/python3.9/site-packages/flask/app.py", line 882, in full_dispatch_request
    rv = self.handle_user_exception(e)
  File "/home/amartinezi/sincere/venv/lib64/python3.9/site-packages/flask/app.py", line 880, in full_dispatch_request
    rv = self.dispatch_request()
  File "/home/amartinezi/sincere/venv/lib64/python3.9/site-packages/flask/app.py", line 865, in dispatch_request
    return self.ensure_sync(self.view_functions[rule.endpoint])(**view_args)  # type: ignore[no-any-return]
  File "/home/amartinezi/sincere/api_scheduler_experiments.py", line 473, in inference
    model_usage_count[model_alias] += 1
NameError: name 'model_usage_count' is not defined
2024-09-23 14:13:12,694 127.0.0.1 - - [23/Sep/2024 14:13:12] "[35m[1mPOST /inference HTTP/1.1[0m" 500 -
2024-09-23 14:13:12,738 Request with ID a8d27a71 for model llama3-8b received
2024-09-23 14:13:12,738 Exception on /inference [POST]
Traceback (most recent call last):
  File "/home/amartinezi/sincere/venv/lib64/python3.9/site-packages/flask/app.py", line 1473, in wsgi_app
    response = self.full_dispatch_request()
  File "/home/amartinezi/sincere/venv/lib64/python3.9/site-packages/flask/app.py", line 882, in full_dispatch_request
    rv = self.handle_user_exception(e)
  File "/home/amartinezi/sincere/venv/lib64/python3.9/site-packages/flask/app.py", line 880, in full_dispatch_request
    rv = self.dispatch_request()
  File "/home/amartinezi/sincere/venv/lib64/python3.9/site-packages/flask/app.py", line 865, in dispatch_request
    return self.ensure_sync(self.view_functions[rule.endpoint])(**view_args)  # type: ignore[no-any-return]
  File "/home/amartinezi/sincere/api_scheduler_experiments.py", line 473, in inference
    model_usage_count[model_alias] += 1
NameError: name 'model_usage_count' is not defined
2024-09-23 14:13:12,738 127.0.0.1 - - [23/Sep/2024 14:13:12] "[35m[1mPOST /inference HTTP/1.1[0m" 500 -
2024-09-23 14:13:12,994 Request with ID c2870db5 for model granite-7b received
2024-09-23 14:13:12,995 Request with ID 76eb9254 for model llama3-8b received
2024-09-23 14:13:12,995 Exception on /inference [POST]
Traceback (most recent call last):
  File "/home/amartinezi/sincere/venv/lib64/python3.9/site-packages/flask/app.py", line 1473, in wsgi_app
    response = self.full_dispatch_request()
  File "/home/amartinezi/sincere/venv/lib64/python3.9/site-packages/flask/app.py", line 882, in full_dispatch_request
    rv = self.handle_user_exception(e)
  File "/home/amartinezi/sincere/venv/lib64/python3.9/site-packages/flask/app.py", line 880, in full_dispatch_request
    rv = self.dispatch_request()
  File "/home/amartinezi/sincere/venv/lib64/python3.9/site-packages/flask/app.py", line 865, in dispatch_request
    return self.ensure_sync(self.view_functions[rule.endpoint])(**view_args)  # type: ignore[no-any-return]
  File "/home/amartinezi/sincere/api_scheduler_experiments.py", line 473, in inference
    model_usage_count[model_alias] += 1
NameError: name 'model_usage_count' is not defined
2024-09-23 14:13:12,995 Exception on /inference [POST]
Traceback (most recent call last):
  File "/home/amartinezi/sincere/venv/lib64/python3.9/site-packages/flask/app.py", line 1473, in wsgi_app
    response = self.full_dispatch_request()
  File "/home/amartinezi/sincere/venv/lib64/python3.9/site-packages/flask/app.py", line 882, in full_dispatch_request
    rv = self.handle_user_exception(e)
  File "/home/amartinezi/sincere/venv/lib64/python3.9/site-packages/flask/app.py", line 880, in full_dispatch_request
    rv = self.dispatch_request()
  File "/home/amartinezi/sincere/venv/lib64/python3.9/site-packages/flask/app.py", line 865, in dispatch_request
    return self.ensure_sync(self.view_functions[rule.endpoint])(**view_args)  # type: ignore[no-any-return]
  File "/home/amartinezi/sincere/api_scheduler_experiments.py", line 473, in inference
    model_usage_count[model_alias] += 1
NameError: name 'model_usage_count' is not defined
2024-09-23 14:13:12,996 127.0.0.1 - - [23/Sep/2024 14:13:12] "[35m[1mPOST /inference HTTP/1.1[0m" 500 -
2024-09-23 14:13:12,997 127.0.0.1 - - [23/Sep/2024 14:13:12] "[35m[1mPOST /inference HTTP/1.1[0m" 500 -
2024-09-23 14:13:13,127 Request with ID 75abbc34 for model granite-7b received
2024-09-23 14:13:13,127 Exception on /inference [POST]
Traceback (most recent call last):
  File "/home/amartinezi/sincere/venv/lib64/python3.9/site-packages/flask/app.py", line 1473, in wsgi_app
    response = self.full_dispatch_request()
  File "/home/amartinezi/sincere/venv/lib64/python3.9/site-packages/flask/app.py", line 882, in full_dispatch_request
    rv = self.handle_user_exception(e)
  File "/home/amartinezi/sincere/venv/lib64/python3.9/site-packages/flask/app.py", line 880, in full_dispatch_request
    rv = self.dispatch_request()
  File "/home/amartinezi/sincere/venv/lib64/python3.9/site-packages/flask/app.py", line 865, in dispatch_request
    return self.ensure_sync(self.view_functions[rule.endpoint])(**view_args)  # type: ignore[no-any-return]
  File "/home/amartinezi/sincere/api_scheduler_experiments.py", line 473, in inference
    model_usage_count[model_alias] += 1
NameError: name 'model_usage_count' is not defined
2024-09-23 14:13:13,128 127.0.0.1 - - [23/Sep/2024 14:13:13] "[35m[1mPOST /inference HTTP/1.1[0m" 500 -
2024-09-23 14:13:13,402 Request with ID 7c2773a8 for model gemma-7b received
2024-09-23 14:13:13,402 Exception on /inference [POST]
Traceback (most recent call last):
  File "/home/amartinezi/sincere/venv/lib64/python3.9/site-packages/flask/app.py", line 1473, in wsgi_app
    response = self.full_dispatch_request()
  File "/home/amartinezi/sincere/venv/lib64/python3.9/site-packages/flask/app.py", line 882, in full_dispatch_request
    rv = self.handle_user_exception(e)
  File "/home/amartinezi/sincere/venv/lib64/python3.9/site-packages/flask/app.py", line 880, in full_dispatch_request
    rv = self.dispatch_request()
  File "/home/amartinezi/sincere/venv/lib64/python3.9/site-packages/flask/app.py", line 865, in dispatch_request
    return self.ensure_sync(self.view_functions[rule.endpoint])(**view_args)  # type: ignore[no-any-return]
  File "/home/amartinezi/sincere/api_scheduler_experiments.py", line 473, in inference
    model_usage_count[model_alias] += 1
NameError: name 'model_usage_count' is not defined
2024-09-23 14:13:13,403 127.0.0.1 - - [23/Sep/2024 14:13:13] "[35m[1mPOST /inference HTTP/1.1[0m" 500 -
2024-09-23 14:13:13,413 Request with ID 45817c7c for model granite-7b received
2024-09-23 14:13:13,414 Exception on /inference [POST]
Traceback (most recent call last):
  File "/home/amartinezi/sincere/venv/lib64/python3.9/site-packages/flask/app.py", line 1473, in wsgi_app
    response = self.full_dispatch_request()
  File "/home/amartinezi/sincere/venv/lib64/python3.9/site-packages/flask/app.py", line 882, in full_dispatch_request
    rv = self.handle_user_exception(e)
  File "/home/amartinezi/sincere/venv/lib64/python3.9/site-packages/flask/app.py", line 880, in full_dispatch_request
    rv = self.dispatch_request()
  File "/home/amartinezi/sincere/venv/lib64/python3.9/site-packages/flask/app.py", line 865, in dispatch_request
    return self.ensure_sync(self.view_functions[rule.endpoint])(**view_args)  # type: ignore[no-any-return]
  File "/home/amartinezi/sincere/api_scheduler_experiments.py", line 473, in inference
    model_usage_count[model_alias] += 1
NameError: name 'model_usage_count' is not defined
2024-09-23 14:13:13,414 127.0.0.1 - - [23/Sep/2024 14:13:13] "[35m[1mPOST /inference HTTP/1.1[0m" 500 -
2024-09-23 14:13:13,494 Request with ID 0c86f268 for model llama3-8b received
2024-09-23 14:13:13,495 Exception on /inference [POST]
Traceback (most recent call last):
  File "/home/amartinezi/sincere/venv/lib64/python3.9/site-packages/flask/app.py", line 1473, in wsgi_app
    response = self.full_dispatch_request()
  File "/home/amartinezi/sincere/venv/lib64/python3.9/site-packages/flask/app.py", line 882, in full_dispatch_request
    rv = self.handle_user_exception(e)
  File "/home/amartinezi/sincere/venv/lib64/python3.9/site-packages/flask/app.py", line 880, in full_dispatch_request
    rv = self.dispatch_request()
  File "/home/amartinezi/sincere/venv/lib64/python3.9/site-packages/flask/app.py", line 865, in dispatch_request
    return self.ensure_sync(self.view_functions[rule.endpoint])(**view_args)  # type: ignore[no-any-return]
  File "/home/amartinezi/sincere/api_scheduler_experiments.py", line 473, in inference
    model_usage_count[model_alias] += 1
NameError: name 'model_usage_count' is not defined
2024-09-23 14:13:13,495 127.0.0.1 - - [23/Sep/2024 14:13:13] "[35m[1mPOST /inference HTTP/1.1[0m" 500 -
2024-09-23 14:13:13,725 Request with ID 13646113 for model granite-7b received
2024-09-23 14:13:13,725 Exception on /inference [POST]
Traceback (most recent call last):
  File "/home/amartinezi/sincere/venv/lib64/python3.9/site-packages/flask/app.py", line 1473, in wsgi_app
    response = self.full_dispatch_request()
  File "/home/amartinezi/sincere/venv/lib64/python3.9/site-packages/flask/app.py", line 882, in full_dispatch_request
    rv = self.handle_user_exception(e)
  File "/home/amartinezi/sincere/venv/lib64/python3.9/site-packages/flask/app.py", line 880, in full_dispatch_request
    rv = self.dispatch_request()
  File "/home/amartinezi/sincere/venv/lib64/python3.9/site-packages/flask/app.py", line 865, in dispatch_request
    return self.ensure_sync(self.view_functions[rule.endpoint])(**view_args)  # type: ignore[no-any-return]
  File "/home/amartinezi/sincere/api_scheduler_experiments.py", line 473, in inference
    model_usage_count[model_alias] += 1
NameError: name 'model_usage_count' is not defined
2024-09-23 14:13:13,725 127.0.0.1 - - [23/Sep/2024 14:13:13] "[35m[1mPOST /inference HTTP/1.1[0m" 500 -
2024-09-23 14:13:13,771 Request with ID 6ee61d7f for model gemma-7b received
2024-09-23 14:13:13,771 Exception on /inference [POST]
Traceback (most recent call last):
  File "/home/amartinezi/sincere/venv/lib64/python3.9/site-packages/flask/app.py", line 1473, in wsgi_app
    response = self.full_dispatch_request()
  File "/home/amartinezi/sincere/venv/lib64/python3.9/site-packages/flask/app.py", line 882, in full_dispatch_request
    rv = self.handle_user_exception(e)
  File "/home/amartinezi/sincere/venv/lib64/python3.9/site-packages/flask/app.py", line 880, in full_dispatch_request
    rv = self.dispatch_request()
  File "/home/amartinezi/sincere/venv/lib64/python3.9/site-packages/flask/app.py", line 865, in dispatch_request
    return self.ensure_sync(self.view_functions[rule.endpoint])(**view_args)  # type: ignore[no-any-return]
  File "/home/amartinezi/sincere/api_scheduler_experiments.py", line 473, in inference
    model_usage_count[model_alias] += 1
NameError: name 'model_usage_count' is not defined
2024-09-23 14:13:13,772 127.0.0.1 - - [23/Sep/2024 14:13:13] "[35m[1mPOST /inference HTTP/1.1[0m" 500 -
2024-09-23 14:13:13,896 Request with ID a309a60f for model llama3-8b received
2024-09-23 14:13:13,897 Exception on /inference [POST]
Traceback (most recent call last):
  File "/home/amartinezi/sincere/venv/lib64/python3.9/site-packages/flask/app.py", line 1473, in wsgi_app
    response = self.full_dispatch_request()
  File "/home/amartinezi/sincere/venv/lib64/python3.9/site-packages/flask/app.py", line 882, in full_dispatch_request
    rv = self.handle_user_exception(e)
  File "/home/amartinezi/sincere/venv/lib64/python3.9/site-packages/flask/app.py", line 880, in full_dispatch_request
    rv = self.dispatch_request()
  File "/home/amartinezi/sincere/venv/lib64/python3.9/site-packages/flask/app.py", line 865, in dispatch_request
    return self.ensure_sync(self.view_functions[rule.endpoint])(**view_args)  # type: ignore[no-any-return]
  File "/home/amartinezi/sincere/api_scheduler_experiments.py", line 473, in inference
    model_usage_count[model_alias] += 1
NameError: name 'model_usage_count' is not defined
2024-09-23 14:13:13,897 127.0.0.1 - - [23/Sep/2024 14:13:13] "[35m[1mPOST /inference HTTP/1.1[0m" 500 -
2024-09-23 14:13:13,924 Request with ID 6872593c for model llama3-8b received
2024-09-23 14:13:13,924 Exception on /inference [POST]
Traceback (most recent call last):
  File "/home/amartinezi/sincere/venv/lib64/python3.9/site-packages/flask/app.py", line 1473, in wsgi_app
    response = self.full_dispatch_request()
  File "/home/amartinezi/sincere/venv/lib64/python3.9/site-packages/flask/app.py", line 882, in full_dispatch_request
    rv = self.handle_user_exception(e)
  File "/home/amartinezi/sincere/venv/lib64/python3.9/site-packages/flask/app.py", line 880, in full_dispatch_request
    rv = self.dispatch_request()
  File "/home/amartinezi/sincere/venv/lib64/python3.9/site-packages/flask/app.py", line 865, in dispatch_request
    return self.ensure_sync(self.view_functions[rule.endpoint])(**view_args)  # type: ignore[no-any-return]
  File "/home/amartinezi/sincere/api_scheduler_experiments.py", line 473, in inference
    model_usage_count[model_alias] += 1
NameError: name 'model_usage_count' is not defined
2024-09-23 14:13:13,925 127.0.0.1 - - [23/Sep/2024 14:13:13] "[35m[1mPOST /inference HTTP/1.1[0m" 500 -
2024-09-23 14:13:13,943 Request with ID a7d86f1a for model llama3-8b received
2024-09-23 14:13:13,943 Exception on /inference [POST]
Traceback (most recent call last):
  File "/home/amartinezi/sincere/venv/lib64/python3.9/site-packages/flask/app.py", line 1473, in wsgi_app
    response = self.full_dispatch_request()
  File "/home/amartinezi/sincere/venv/lib64/python3.9/site-packages/flask/app.py", line 882, in full_dispatch_request
    rv = self.handle_user_exception(e)
  File "/home/amartinezi/sincere/venv/lib64/python3.9/site-packages/flask/app.py", line 880, in full_dispatch_request
    rv = self.dispatch_request()
  File "/home/amartinezi/sincere/venv/lib64/python3.9/site-packages/flask/app.py", line 865, in dispatch_request
    return self.ensure_sync(self.view_functions[rule.endpoint])(**view_args)  # type: ignore[no-any-return]
  File "/home/amartinezi/sincere/api_scheduler_experiments.py", line 473, in inference
    model_usage_count[model_alias] += 1
NameError: name 'model_usage_count' is not defined
2024-09-23 14:13:13,944 127.0.0.1 - - [23/Sep/2024 14:13:13] "[35m[1mPOST /inference HTTP/1.1[0m" 500 -
2024-09-23 14:13:14,102 Request with ID 7598dd0c for model llama3-8b received
2024-09-23 14:13:14,102 Exception on /inference [POST]
Traceback (most recent call last):
  File "/home/amartinezi/sincere/venv/lib64/python3.9/site-packages/flask/app.py", line 1473, in wsgi_app
    response = self.full_dispatch_request()
  File "/home/amartinezi/sincere/venv/lib64/python3.9/site-packages/flask/app.py", line 882, in full_dispatch_request
    rv = self.handle_user_exception(e)
  File "/home/amartinezi/sincere/venv/lib64/python3.9/site-packages/flask/app.py", line 880, in full_dispatch_request
    rv = self.dispatch_request()
  File "/home/amartinezi/sincere/venv/lib64/python3.9/site-packages/flask/app.py", line 865, in dispatch_request
    return self.ensure_sync(self.view_functions[rule.endpoint])(**view_args)  # type: ignore[no-any-return]
  File "/home/amartinezi/sincere/api_scheduler_experiments.py", line 473, in inference
    model_usage_count[model_alias] += 1
NameError: name 'model_usage_count' is not defined
2024-09-23 14:13:14,103 127.0.0.1 - - [23/Sep/2024 14:13:14] "[35m[1mPOST /inference HTTP/1.1[0m" 500 -
2024-09-23 14:13:14,144 Request with ID 12cc1ef1 for model granite-7b received
2024-09-23 14:13:14,144 Exception on /inference [POST]
Traceback (most recent call last):
  File "/home/amartinezi/sincere/venv/lib64/python3.9/site-packages/flask/app.py", line 1473, in wsgi_app
    response = self.full_dispatch_request()
  File "/home/amartinezi/sincere/venv/lib64/python3.9/site-packages/flask/app.py", line 882, in full_dispatch_request
    rv = self.handle_user_exception(e)
  File "/home/amartinezi/sincere/venv/lib64/python3.9/site-packages/flask/app.py", line 880, in full_dispatch_request
    rv = self.dispatch_request()
  File "/home/amartinezi/sincere/venv/lib64/python3.9/site-packages/flask/app.py", line 865, in dispatch_request
    return self.ensure_sync(self.view_functions[rule.endpoint])(**view_args)  # type: ignore[no-any-return]
  File "/home/amartinezi/sincere/api_scheduler_experiments.py", line 473, in inference
    model_usage_count[model_alias] += 1
NameError: name 'model_usage_count' is not defined
2024-09-23 14:13:14,145 127.0.0.1 - - [23/Sep/2024 14:13:14] "[35m[1mPOST /inference HTTP/1.1[0m" 500 -
2024-09-23 14:13:14,147 Request with ID 4f826b3f for model granite-7b received
2024-09-23 14:13:14,148 Exception on /inference [POST]
Traceback (most recent call last):
  File "/home/amartinezi/sincere/venv/lib64/python3.9/site-packages/flask/app.py", line 1473, in wsgi_app
    response = self.full_dispatch_request()
  File "/home/amartinezi/sincere/venv/lib64/python3.9/site-packages/flask/app.py", line 882, in full_dispatch_request
    rv = self.handle_user_exception(e)
  File "/home/amartinezi/sincere/venv/lib64/python3.9/site-packages/flask/app.py", line 880, in full_dispatch_request
    rv = self.dispatch_request()
  File "/home/amartinezi/sincere/venv/lib64/python3.9/site-packages/flask/app.py", line 865, in dispatch_request
    return self.ensure_sync(self.view_functions[rule.endpoint])(**view_args)  # type: ignore[no-any-return]
  File "/home/amartinezi/sincere/api_scheduler_experiments.py", line 473, in inference
    model_usage_count[model_alias] += 1
NameError: name 'model_usage_count' is not defined
2024-09-23 14:13:14,148 127.0.0.1 - - [23/Sep/2024 14:13:14] "[35m[1mPOST /inference HTTP/1.1[0m" 500 -
2024-09-23 14:13:14,220 Request with ID 28eee04e for model llama3-8b received
2024-09-23 14:13:14,220 Exception on /inference [POST]
Traceback (most recent call last):
  File "/home/amartinezi/sincere/venv/lib64/python3.9/site-packages/flask/app.py", line 1473, in wsgi_app
    response = self.full_dispatch_request()
  File "/home/amartinezi/sincere/venv/lib64/python3.9/site-packages/flask/app.py", line 882, in full_dispatch_request
    rv = self.handle_user_exception(e)
  File "/home/amartinezi/sincere/venv/lib64/python3.9/site-packages/flask/app.py", line 880, in full_dispatch_request
    rv = self.dispatch_request()
  File "/home/amartinezi/sincere/venv/lib64/python3.9/site-packages/flask/app.py", line 865, in dispatch_request
    return self.ensure_sync(self.view_functions[rule.endpoint])(**view_args)  # type: ignore[no-any-return]
  File "/home/amartinezi/sincere/api_scheduler_experiments.py", line 473, in inference
    model_usage_count[model_alias] += 1
NameError: name 'model_usage_count' is not defined
2024-09-23 14:13:14,221 127.0.0.1 - - [23/Sep/2024 14:13:14] "[35m[1mPOST /inference HTTP/1.1[0m" 500 -
2024-09-23 14:13:14,244 Request with ID 44c69703 for model llama3-8b received
2024-09-23 14:13:14,244 Exception on /inference [POST]
Traceback (most recent call last):
  File "/home/amartinezi/sincere/venv/lib64/python3.9/site-packages/flask/app.py", line 1473, in wsgi_app
    response = self.full_dispatch_request()
  File "/home/amartinezi/sincere/venv/lib64/python3.9/site-packages/flask/app.py", line 882, in full_dispatch_request
    rv = self.handle_user_exception(e)
  File "/home/amartinezi/sincere/venv/lib64/python3.9/site-packages/flask/app.py", line 880, in full_dispatch_request
    rv = self.dispatch_request()
  File "/home/amartinezi/sincere/venv/lib64/python3.9/site-packages/flask/app.py", line 865, in dispatch_request
    return self.ensure_sync(self.view_functions[rule.endpoint])(**view_args)  # type: ignore[no-any-return]
  File "/home/amartinezi/sincere/api_scheduler_experiments.py", line 473, in inference
    model_usage_count[model_alias] += 1
NameError: name 'model_usage_count' is not defined
2024-09-23 14:13:14,245 127.0.0.1 - - [23/Sep/2024 14:13:14] "[35m[1mPOST /inference HTTP/1.1[0m" 500 -
2024-09-23 14:13:14,280 Request with ID 6a192bb7 for model llama3-8b received
2024-09-23 14:13:14,280 Exception on /inference [POST]
Traceback (most recent call last):
  File "/home/amartinezi/sincere/venv/lib64/python3.9/site-packages/flask/app.py", line 1473, in wsgi_app
    response = self.full_dispatch_request()
  File "/home/amartinezi/sincere/venv/lib64/python3.9/site-packages/flask/app.py", line 882, in full_dispatch_request
    rv = self.handle_user_exception(e)
  File "/home/amartinezi/sincere/venv/lib64/python3.9/site-packages/flask/app.py", line 880, in full_dispatch_request
    rv = self.dispatch_request()
  File "/home/amartinezi/sincere/venv/lib64/python3.9/site-packages/flask/app.py", line 865, in dispatch_request
    return self.ensure_sync(self.view_functions[rule.endpoint])(**view_args)  # type: ignore[no-any-return]
  File "/home/amartinezi/sincere/api_scheduler_experiments.py", line 473, in inference
    model_usage_count[model_alias] += 1
NameError: name 'model_usage_count' is not defined
2024-09-23 14:13:14,281 127.0.0.1 - - [23/Sep/2024 14:13:14] "[35m[1mPOST /inference HTTP/1.1[0m" 500 -
2024-09-23 14:13:14,417 Request with ID 8d1357fe for model llama3-8b received
2024-09-23 14:13:14,417 Exception on /inference [POST]
Traceback (most recent call last):
  File "/home/amartinezi/sincere/venv/lib64/python3.9/site-packages/flask/app.py", line 1473, in wsgi_app
    response = self.full_dispatch_request()
  File "/home/amartinezi/sincere/venv/lib64/python3.9/site-packages/flask/app.py", line 882, in full_dispatch_request
    rv = self.handle_user_exception(e)
  File "/home/amartinezi/sincere/venv/lib64/python3.9/site-packages/flask/app.py", line 880, in full_dispatch_request
    rv = self.dispatch_request()
  File "/home/amartinezi/sincere/venv/lib64/python3.9/site-packages/flask/app.py", line 865, in dispatch_request
    return self.ensure_sync(self.view_functions[rule.endpoint])(**view_args)  # type: ignore[no-any-return]
  File "/home/amartinezi/sincere/api_scheduler_experiments.py", line 473, in inference
    model_usage_count[model_alias] += 1
NameError: name 'model_usage_count' is not defined
2024-09-23 14:13:14,418 127.0.0.1 - - [23/Sep/2024 14:13:14] "[35m[1mPOST /inference HTTP/1.1[0m" 500 -
2024-09-23 14:13:14,586 Request with ID a5a2c6ec for model llama3-8b received
2024-09-23 14:13:14,587 Exception on /inference [POST]
Traceback (most recent call last):
  File "/home/amartinezi/sincere/venv/lib64/python3.9/site-packages/flask/app.py", line 1473, in wsgi_app
    response = self.full_dispatch_request()
  File "/home/amartinezi/sincere/venv/lib64/python3.9/site-packages/flask/app.py", line 882, in full_dispatch_request
    rv = self.handle_user_exception(e)
  File "/home/amartinezi/sincere/venv/lib64/python3.9/site-packages/flask/app.py", line 880, in full_dispatch_request
    rv = self.dispatch_request()
  File "/home/amartinezi/sincere/venv/lib64/python3.9/site-packages/flask/app.py", line 865, in dispatch_request
    return self.ensure_sync(self.view_functions[rule.endpoint])(**view_args)  # type: ignore[no-any-return]
  File "/home/amartinezi/sincere/api_scheduler_experiments.py", line 473, in inference
    model_usage_count[model_alias] += 1
NameError: name 'model_usage_count' is not defined
2024-09-23 14:13:14,587 127.0.0.1 - - [23/Sep/2024 14:13:14] "[35m[1mPOST /inference HTTP/1.1[0m" 500 -
2024-09-23 14:13:14,752 Request with ID c5f66b16 for model gemma-7b received
2024-09-23 14:13:14,752 Exception on /inference [POST]
Traceback (most recent call last):
  File "/home/amartinezi/sincere/venv/lib64/python3.9/site-packages/flask/app.py", line 1473, in wsgi_app
    response = self.full_dispatch_request()
  File "/home/amartinezi/sincere/venv/lib64/python3.9/site-packages/flask/app.py", line 882, in full_dispatch_request
    rv = self.handle_user_exception(e)
  File "/home/amartinezi/sincere/venv/lib64/python3.9/site-packages/flask/app.py", line 880, in full_dispatch_request
    rv = self.dispatch_request()
  File "/home/amartinezi/sincere/venv/lib64/python3.9/site-packages/flask/app.py", line 865, in dispatch_request
    return self.ensure_sync(self.view_functions[rule.endpoint])(**view_args)  # type: ignore[no-any-return]
  File "/home/amartinezi/sincere/api_scheduler_experiments.py", line 473, in inference
    model_usage_count[model_alias] += 1
NameError: name 'model_usage_count' is not defined
2024-09-23 14:13:14,753 127.0.0.1 - - [23/Sep/2024 14:13:14] "[35m[1mPOST /inference HTTP/1.1[0m" 500 -
2024-09-23 14:13:14,930 Request with ID b88e0591 for model granite-7b received
2024-09-23 14:13:14,931 Exception on /inference [POST]
Traceback (most recent call last):
  File "/home/amartinezi/sincere/venv/lib64/python3.9/site-packages/flask/app.py", line 1473, in wsgi_app
    response = self.full_dispatch_request()
  File "/home/amartinezi/sincere/venv/lib64/python3.9/site-packages/flask/app.py", line 882, in full_dispatch_request
    rv = self.handle_user_exception(e)
  File "/home/amartinezi/sincere/venv/lib64/python3.9/site-packages/flask/app.py", line 880, in full_dispatch_request
    rv = self.dispatch_request()
  File "/home/amartinezi/sincere/venv/lib64/python3.9/site-packages/flask/app.py", line 865, in dispatch_request
    return self.ensure_sync(self.view_functions[rule.endpoint])(**view_args)  # type: ignore[no-any-return]
  File "/home/amartinezi/sincere/api_scheduler_experiments.py", line 473, in inference
    model_usage_count[model_alias] += 1
NameError: name 'model_usage_count' is not defined
2024-09-23 14:13:14,931 127.0.0.1 - - [23/Sep/2024 14:13:14] "[35m[1mPOST /inference HTTP/1.1[0m" 500 -
2024-09-23 14:13:14,936 Request with ID 724e4a81 for model llama3-8b received
2024-09-23 14:13:14,936 Exception on /inference [POST]
Traceback (most recent call last):
  File "/home/amartinezi/sincere/venv/lib64/python3.9/site-packages/flask/app.py", line 1473, in wsgi_app
    response = self.full_dispatch_request()
  File "/home/amartinezi/sincere/venv/lib64/python3.9/site-packages/flask/app.py", line 882, in full_dispatch_request
    rv = self.handle_user_exception(e)
  File "/home/amartinezi/sincere/venv/lib64/python3.9/site-packages/flask/app.py", line 880, in full_dispatch_request
    rv = self.dispatch_request()
  File "/home/amartinezi/sincere/venv/lib64/python3.9/site-packages/flask/app.py", line 865, in dispatch_request
    return self.ensure_sync(self.view_functions[rule.endpoint])(**view_args)  # type: ignore[no-any-return]
  File "/home/amartinezi/sincere/api_scheduler_experiments.py", line 473, in inference
    model_usage_count[model_alias] += 1
NameError: name 'model_usage_count' is not defined
2024-09-23 14:13:14,936 127.0.0.1 - - [23/Sep/2024 14:13:14] "[35m[1mPOST /inference HTTP/1.1[0m" 500 -
2024-09-23 14:13:14,962 Request with ID 6cc08c90 for model gemma-7b received
2024-09-23 14:13:14,962 Exception on /inference [POST]
Traceback (most recent call last):
  File "/home/amartinezi/sincere/venv/lib64/python3.9/site-packages/flask/app.py", line 1473, in wsgi_app
    response = self.full_dispatch_request()
  File "/home/amartinezi/sincere/venv/lib64/python3.9/site-packages/flask/app.py", line 882, in full_dispatch_request
    rv = self.handle_user_exception(e)
  File "/home/amartinezi/sincere/venv/lib64/python3.9/site-packages/flask/app.py", line 880, in full_dispatch_request
    rv = self.dispatch_request()
  File "/home/amartinezi/sincere/venv/lib64/python3.9/site-packages/flask/app.py", line 865, in dispatch_request
    return self.ensure_sync(self.view_functions[rule.endpoint])(**view_args)  # type: ignore[no-any-return]
  File "/home/amartinezi/sincere/api_scheduler_experiments.py", line 473, in inference
    model_usage_count[model_alias] += 1
NameError: name 'model_usage_count' is not defined
2024-09-23 14:13:14,963 127.0.0.1 - - [23/Sep/2024 14:13:14] "[35m[1mPOST /inference HTTP/1.1[0m" 500 -
2024-09-23 14:13:15,042 Request with ID d46083c3 for model gemma-7b received
2024-09-23 14:13:15,042 Exception on /inference [POST]
Traceback (most recent call last):
  File "/home/amartinezi/sincere/venv/lib64/python3.9/site-packages/flask/app.py", line 1473, in wsgi_app
    response = self.full_dispatch_request()
  File "/home/amartinezi/sincere/venv/lib64/python3.9/site-packages/flask/app.py", line 882, in full_dispatch_request
    rv = self.handle_user_exception(e)
  File "/home/amartinezi/sincere/venv/lib64/python3.9/site-packages/flask/app.py", line 880, in full_dispatch_request
    rv = self.dispatch_request()
  File "/home/amartinezi/sincere/venv/lib64/python3.9/site-packages/flask/app.py", line 865, in dispatch_request
    return self.ensure_sync(self.view_functions[rule.endpoint])(**view_args)  # type: ignore[no-any-return]
  File "/home/amartinezi/sincere/api_scheduler_experiments.py", line 473, in inference
    model_usage_count[model_alias] += 1
NameError: name 'model_usage_count' is not defined
2024-09-23 14:13:15,043 127.0.0.1 - - [23/Sep/2024 14:13:15] "[35m[1mPOST /inference HTTP/1.1[0m" 500 -
2024-09-23 14:13:15,163 Request with ID bef47c28 for model llama3-8b received
2024-09-23 14:13:15,163 Exception on /inference [POST]
Traceback (most recent call last):
  File "/home/amartinezi/sincere/venv/lib64/python3.9/site-packages/flask/app.py", line 1473, in wsgi_app
    response = self.full_dispatch_request()
  File "/home/amartinezi/sincere/venv/lib64/python3.9/site-packages/flask/app.py", line 882, in full_dispatch_request
    rv = self.handle_user_exception(e)
  File "/home/amartinezi/sincere/venv/lib64/python3.9/site-packages/flask/app.py", line 880, in full_dispatch_request
    rv = self.dispatch_request()
  File "/home/amartinezi/sincere/venv/lib64/python3.9/site-packages/flask/app.py", line 865, in dispatch_request
    return self.ensure_sync(self.view_functions[rule.endpoint])(**view_args)  # type: ignore[no-any-return]
  File "/home/amartinezi/sincere/api_scheduler_experiments.py", line 473, in inference
    model_usage_count[model_alias] += 1
NameError: name 'model_usage_count' is not defined
2024-09-23 14:13:15,164 127.0.0.1 - - [23/Sep/2024 14:13:15] "[35m[1mPOST /inference HTTP/1.1[0m" 500 -
2024-09-23 14:13:15,299 Request with ID f9472514 for model llama3-8b received
2024-09-23 14:13:15,299 Exception on /inference [POST]
Traceback (most recent call last):
  File "/home/amartinezi/sincere/venv/lib64/python3.9/site-packages/flask/app.py", line 1473, in wsgi_app
    response = self.full_dispatch_request()
  File "/home/amartinezi/sincere/venv/lib64/python3.9/site-packages/flask/app.py", line 882, in full_dispatch_request
    rv = self.handle_user_exception(e)
  File "/home/amartinezi/sincere/venv/lib64/python3.9/site-packages/flask/app.py", line 880, in full_dispatch_request
    rv = self.dispatch_request()
  File "/home/amartinezi/sincere/venv/lib64/python3.9/site-packages/flask/app.py", line 865, in dispatch_request
    return self.ensure_sync(self.view_functions[rule.endpoint])(**view_args)  # type: ignore[no-any-return]
  File "/home/amartinezi/sincere/api_scheduler_experiments.py", line 473, in inference
    model_usage_count[model_alias] += 1
NameError: name 'model_usage_count' is not defined
2024-09-23 14:13:15,300 127.0.0.1 - - [23/Sep/2024 14:13:15] "[35m[1mPOST /inference HTTP/1.1[0m" 500 -
2024-09-23 14:13:15,660 Request with ID 00889f82 for model llama3-8b received
2024-09-23 14:13:15,661 Exception on /inference [POST]
Traceback (most recent call last):
  File "/home/amartinezi/sincere/venv/lib64/python3.9/site-packages/flask/app.py", line 1473, in wsgi_app
    response = self.full_dispatch_request()
  File "/home/amartinezi/sincere/venv/lib64/python3.9/site-packages/flask/app.py", line 882, in full_dispatch_request
    rv = self.handle_user_exception(e)
  File "/home/amartinezi/sincere/venv/lib64/python3.9/site-packages/flask/app.py", line 880, in full_dispatch_request
    rv = self.dispatch_request()
  File "/home/amartinezi/sincere/venv/lib64/python3.9/site-packages/flask/app.py", line 865, in dispatch_request
    return self.ensure_sync(self.view_functions[rule.endpoint])(**view_args)  # type: ignore[no-any-return]
  File "/home/amartinezi/sincere/api_scheduler_experiments.py", line 473, in inference
    model_usage_count[model_alias] += 1
NameError: name 'model_usage_count' is not defined
2024-09-23 14:13:15,662 127.0.0.1 - - [23/Sep/2024 14:13:15] "[35m[1mPOST /inference HTTP/1.1[0m" 500 -
2024-09-23 14:13:15,788 Request with ID 87350bf9 for model llama3-8b received
2024-09-23 14:13:15,788 Exception on /inference [POST]
Traceback (most recent call last):
  File "/home/amartinezi/sincere/venv/lib64/python3.9/site-packages/flask/app.py", line 1473, in wsgi_app
    response = self.full_dispatch_request()
  File "/home/amartinezi/sincere/venv/lib64/python3.9/site-packages/flask/app.py", line 882, in full_dispatch_request
    rv = self.handle_user_exception(e)
  File "/home/amartinezi/sincere/venv/lib64/python3.9/site-packages/flask/app.py", line 880, in full_dispatch_request
    rv = self.dispatch_request()
  File "/home/amartinezi/sincere/venv/lib64/python3.9/site-packages/flask/app.py", line 865, in dispatch_request
    return self.ensure_sync(self.view_functions[rule.endpoint])(**view_args)  # type: ignore[no-any-return]
  File "/home/amartinezi/sincere/api_scheduler_experiments.py", line 473, in inference
    model_usage_count[model_alias] += 1
NameError: name 'model_usage_count' is not defined
2024-09-23 14:13:15,789 127.0.0.1 - - [23/Sep/2024 14:13:15] "[35m[1mPOST /inference HTTP/1.1[0m" 500 -
2024-09-23 14:13:15,851 Request with ID 72e83ce2 for model llama3-8b received
2024-09-23 14:13:15,851 Exception on /inference [POST]
Traceback (most recent call last):
  File "/home/amartinezi/sincere/venv/lib64/python3.9/site-packages/flask/app.py", line 1473, in wsgi_app
    response = self.full_dispatch_request()
  File "/home/amartinezi/sincere/venv/lib64/python3.9/site-packages/flask/app.py", line 882, in full_dispatch_request
    rv = self.handle_user_exception(e)
  File "/home/amartinezi/sincere/venv/lib64/python3.9/site-packages/flask/app.py", line 880, in full_dispatch_request
    rv = self.dispatch_request()
  File "/home/amartinezi/sincere/venv/lib64/python3.9/site-packages/flask/app.py", line 865, in dispatch_request
    return self.ensure_sync(self.view_functions[rule.endpoint])(**view_args)  # type: ignore[no-any-return]
  File "/home/amartinezi/sincere/api_scheduler_experiments.py", line 473, in inference
    model_usage_count[model_alias] += 1
NameError: name 'model_usage_count' is not defined
2024-09-23 14:13:15,852 127.0.0.1 - - [23/Sep/2024 14:13:15] "[35m[1mPOST /inference HTTP/1.1[0m" 500 -
2024-09-23 14:13:15,951 Request with ID cee79b90 for model llama3-8b received
2024-09-23 14:13:15,951 Exception on /inference [POST]
Traceback (most recent call last):
  File "/home/amartinezi/sincere/venv/lib64/python3.9/site-packages/flask/app.py", line 1473, in wsgi_app
    response = self.full_dispatch_request()
  File "/home/amartinezi/sincere/venv/lib64/python3.9/site-packages/flask/app.py", line 882, in full_dispatch_request
    rv = self.handle_user_exception(e)
  File "/home/amartinezi/sincere/venv/lib64/python3.9/site-packages/flask/app.py", line 880, in full_dispatch_request
    rv = self.dispatch_request()
  File "/home/amartinezi/sincere/venv/lib64/python3.9/site-packages/flask/app.py", line 865, in dispatch_request
    return self.ensure_sync(self.view_functions[rule.endpoint])(**view_args)  # type: ignore[no-any-return]
  File "/home/amartinezi/sincere/api_scheduler_experiments.py", line 473, in inference
    model_usage_count[model_alias] += 1
NameError: name 'model_usage_count' is not defined
2024-09-23 14:13:15,952 127.0.0.1 - - [23/Sep/2024 14:13:15] "[35m[1mPOST /inference HTTP/1.1[0m" 500 -
2024-09-23 14:13:16,167 Request with ID 643d673b for model llama3-8b received
2024-09-23 14:13:16,168 Exception on /inference [POST]
Traceback (most recent call last):
  File "/home/amartinezi/sincere/venv/lib64/python3.9/site-packages/flask/app.py", line 1473, in wsgi_app
    response = self.full_dispatch_request()
  File "/home/amartinezi/sincere/venv/lib64/python3.9/site-packages/flask/app.py", line 882, in full_dispatch_request
    rv = self.handle_user_exception(e)
  File "/home/amartinezi/sincere/venv/lib64/python3.9/site-packages/flask/app.py", line 880, in full_dispatch_request
    rv = self.dispatch_request()
  File "/home/amartinezi/sincere/venv/lib64/python3.9/site-packages/flask/app.py", line 865, in dispatch_request
    return self.ensure_sync(self.view_functions[rule.endpoint])(**view_args)  # type: ignore[no-any-return]
  File "/home/amartinezi/sincere/api_scheduler_experiments.py", line 473, in inference
    model_usage_count[model_alias] += 1
NameError: name 'model_usage_count' is not defined
2024-09-23 14:13:16,168 127.0.0.1 - - [23/Sep/2024 14:13:16] "[35m[1mPOST /inference HTTP/1.1[0m" 500 -
2024-09-23 14:13:16,195 Request with ID 58fa1cfc for model gemma-7b received
2024-09-23 14:13:16,195 Exception on /inference [POST]
Traceback (most recent call last):
  File "/home/amartinezi/sincere/venv/lib64/python3.9/site-packages/flask/app.py", line 1473, in wsgi_app
    response = self.full_dispatch_request()
  File "/home/amartinezi/sincere/venv/lib64/python3.9/site-packages/flask/app.py", line 882, in full_dispatch_request
    rv = self.handle_user_exception(e)
  File "/home/amartinezi/sincere/venv/lib64/python3.9/site-packages/flask/app.py", line 880, in full_dispatch_request
    rv = self.dispatch_request()
  File "/home/amartinezi/sincere/venv/lib64/python3.9/site-packages/flask/app.py", line 865, in dispatch_request
    return self.ensure_sync(self.view_functions[rule.endpoint])(**view_args)  # type: ignore[no-any-return]
  File "/home/amartinezi/sincere/api_scheduler_experiments.py", line 473, in inference
    model_usage_count[model_alias] += 1
NameError: name 'model_usage_count' is not defined
2024-09-23 14:13:16,196 127.0.0.1 - - [23/Sep/2024 14:13:16] "[35m[1mPOST /inference HTTP/1.1[0m" 500 -
2024-09-23 14:13:16,198 Request with ID fc323e21 for model llama3-8b received
2024-09-23 14:13:16,198 Exception on /inference [POST]
Traceback (most recent call last):
  File "/home/amartinezi/sincere/venv/lib64/python3.9/site-packages/flask/app.py", line 1473, in wsgi_app
    response = self.full_dispatch_request()
  File "/home/amartinezi/sincere/venv/lib64/python3.9/site-packages/flask/app.py", line 882, in full_dispatch_request
    rv = self.handle_user_exception(e)
  File "/home/amartinezi/sincere/venv/lib64/python3.9/site-packages/flask/app.py", line 880, in full_dispatch_request
    rv = self.dispatch_request()
  File "/home/amartinezi/sincere/venv/lib64/python3.9/site-packages/flask/app.py", line 865, in dispatch_request
    return self.ensure_sync(self.view_functions[rule.endpoint])(**view_args)  # type: ignore[no-any-return]
  File "/home/amartinezi/sincere/api_scheduler_experiments.py", line 473, in inference
    model_usage_count[model_alias] += 1
NameError: name 'model_usage_count' is not defined
2024-09-23 14:13:16,199 127.0.0.1 - - [23/Sep/2024 14:13:16] "[35m[1mPOST /inference HTTP/1.1[0m" 500 -
2024-09-23 14:13:16,208 Request with ID 17771015 for model gemma-7b received
2024-09-23 14:13:16,208 Exception on /inference [POST]
Traceback (most recent call last):
  File "/home/amartinezi/sincere/venv/lib64/python3.9/site-packages/flask/app.py", line 1473, in wsgi_app
    response = self.full_dispatch_request()
  File "/home/amartinezi/sincere/venv/lib64/python3.9/site-packages/flask/app.py", line 882, in full_dispatch_request
    rv = self.handle_user_exception(e)
  File "/home/amartinezi/sincere/venv/lib64/python3.9/site-packages/flask/app.py", line 880, in full_dispatch_request
    rv = self.dispatch_request()
  File "/home/amartinezi/sincere/venv/lib64/python3.9/site-packages/flask/app.py", line 865, in dispatch_request
    return self.ensure_sync(self.view_functions[rule.endpoint])(**view_args)  # type: ignore[no-any-return]
  File "/home/amartinezi/sincere/api_scheduler_experiments.py", line 473, in inference
    model_usage_count[model_alias] += 1
NameError: name 'model_usage_count' is not defined
2024-09-23 14:13:16,209 127.0.0.1 - - [23/Sep/2024 14:13:16] "[35m[1mPOST /inference HTTP/1.1[0m" 500 -
2024-09-23 14:13:16,354 Request with ID d4abaefa for model gemma-7b received
2024-09-23 14:13:16,354 Exception on /inference [POST]
Traceback (most recent call last):
  File "/home/amartinezi/sincere/venv/lib64/python3.9/site-packages/flask/app.py", line 1473, in wsgi_app
    response = self.full_dispatch_request()
  File "/home/amartinezi/sincere/venv/lib64/python3.9/site-packages/flask/app.py", line 882, in full_dispatch_request
    rv = self.handle_user_exception(e)
  File "/home/amartinezi/sincere/venv/lib64/python3.9/site-packages/flask/app.py", line 880, in full_dispatch_request
    rv = self.dispatch_request()
  File "/home/amartinezi/sincere/venv/lib64/python3.9/site-packages/flask/app.py", line 865, in dispatch_request
    return self.ensure_sync(self.view_functions[rule.endpoint])(**view_args)  # type: ignore[no-any-return]
  File "/home/amartinezi/sincere/api_scheduler_experiments.py", line 473, in inference
    model_usage_count[model_alias] += 1
NameError: name 'model_usage_count' is not defined
2024-09-23 14:13:16,355 127.0.0.1 - - [23/Sep/2024 14:13:16] "[35m[1mPOST /inference HTTP/1.1[0m" 500 -
2024-09-23 14:13:16,442 Request with ID 9c76fa1f for model llama3-8b received
2024-09-23 14:13:16,443 Exception on /inference [POST]
Traceback (most recent call last):
  File "/home/amartinezi/sincere/venv/lib64/python3.9/site-packages/flask/app.py", line 1473, in wsgi_app
    response = self.full_dispatch_request()
  File "/home/amartinezi/sincere/venv/lib64/python3.9/site-packages/flask/app.py", line 882, in full_dispatch_request
    rv = self.handle_user_exception(e)
  File "/home/amartinezi/sincere/venv/lib64/python3.9/site-packages/flask/app.py", line 880, in full_dispatch_request
    rv = self.dispatch_request()
  File "/home/amartinezi/sincere/venv/lib64/python3.9/site-packages/flask/app.py", line 865, in dispatch_request
    return self.ensure_sync(self.view_functions[rule.endpoint])(**view_args)  # type: ignore[no-any-return]
  File "/home/amartinezi/sincere/api_scheduler_experiments.py", line 473, in inference
    model_usage_count[model_alias] += 1
NameError: name 'model_usage_count' is not defined
2024-09-23 14:13:16,443 127.0.0.1 - - [23/Sep/2024 14:13:16] "[35m[1mPOST /inference HTTP/1.1[0m" 500 -
2024-09-23 14:13:16,568 Request with ID c158f915 for model granite-7b received
2024-09-23 14:13:16,568 Exception on /inference [POST]
Traceback (most recent call last):
  File "/home/amartinezi/sincere/venv/lib64/python3.9/site-packages/flask/app.py", line 1473, in wsgi_app
    response = self.full_dispatch_request()
  File "/home/amartinezi/sincere/venv/lib64/python3.9/site-packages/flask/app.py", line 882, in full_dispatch_request
    rv = self.handle_user_exception(e)
  File "/home/amartinezi/sincere/venv/lib64/python3.9/site-packages/flask/app.py", line 880, in full_dispatch_request
    rv = self.dispatch_request()
  File "/home/amartinezi/sincere/venv/lib64/python3.9/site-packages/flask/app.py", line 865, in dispatch_request
    return self.ensure_sync(self.view_functions[rule.endpoint])(**view_args)  # type: ignore[no-any-return]
  File "/home/amartinezi/sincere/api_scheduler_experiments.py", line 473, in inference
    model_usage_count[model_alias] += 1
NameError: name 'model_usage_count' is not defined
2024-09-23 14:13:16,569 127.0.0.1 - - [23/Sep/2024 14:13:16] "[35m[1mPOST /inference HTTP/1.1[0m" 500 -
2024-09-23 14:13:16,637 Request with ID 4f28f54a for model gemma-7b received
2024-09-23 14:13:16,637 Exception on /inference [POST]
Traceback (most recent call last):
  File "/home/amartinezi/sincere/venv/lib64/python3.9/site-packages/flask/app.py", line 1473, in wsgi_app
    response = self.full_dispatch_request()
  File "/home/amartinezi/sincere/venv/lib64/python3.9/site-packages/flask/app.py", line 882, in full_dispatch_request
    rv = self.handle_user_exception(e)
  File "/home/amartinezi/sincere/venv/lib64/python3.9/site-packages/flask/app.py", line 880, in full_dispatch_request
    rv = self.dispatch_request()
  File "/home/amartinezi/sincere/venv/lib64/python3.9/site-packages/flask/app.py", line 865, in dispatch_request
    return self.ensure_sync(self.view_functions[rule.endpoint])(**view_args)  # type: ignore[no-any-return]
  File "/home/amartinezi/sincere/api_scheduler_experiments.py", line 473, in inference
    model_usage_count[model_alias] += 1
NameError: name 'model_usage_count' is not defined
2024-09-23 14:13:16,638 127.0.0.1 - - [23/Sep/2024 14:13:16] "[35m[1mPOST /inference HTTP/1.1[0m" 500 -
2024-09-23 14:13:16,812 Request with ID da43ae02 for model llama3-8b received
2024-09-23 14:13:16,812 Exception on /inference [POST]
Traceback (most recent call last):
  File "/home/amartinezi/sincere/venv/lib64/python3.9/site-packages/flask/app.py", line 1473, in wsgi_app
    response = self.full_dispatch_request()
  File "/home/amartinezi/sincere/venv/lib64/python3.9/site-packages/flask/app.py", line 882, in full_dispatch_request
    rv = self.handle_user_exception(e)
  File "/home/amartinezi/sincere/venv/lib64/python3.9/site-packages/flask/app.py", line 880, in full_dispatch_request
    rv = self.dispatch_request()
  File "/home/amartinezi/sincere/venv/lib64/python3.9/site-packages/flask/app.py", line 865, in dispatch_request
    return self.ensure_sync(self.view_functions[rule.endpoint])(**view_args)  # type: ignore[no-any-return]
  File "/home/amartinezi/sincere/api_scheduler_experiments.py", line 473, in inference
    model_usage_count[model_alias] += 1
NameError: name 'model_usage_count' is not defined
2024-09-23 14:13:16,813 127.0.0.1 - - [23/Sep/2024 14:13:16] "[35m[1mPOST /inference HTTP/1.1[0m" 500 -
2024-09-23 14:13:16,872 Request with ID bc82898c for model gemma-7b received
2024-09-23 14:13:16,872 Exception on /inference [POST]
Traceback (most recent call last):
  File "/home/amartinezi/sincere/venv/lib64/python3.9/site-packages/flask/app.py", line 1473, in wsgi_app
    response = self.full_dispatch_request()
  File "/home/amartinezi/sincere/venv/lib64/python3.9/site-packages/flask/app.py", line 882, in full_dispatch_request
    rv = self.handle_user_exception(e)
  File "/home/amartinezi/sincere/venv/lib64/python3.9/site-packages/flask/app.py", line 880, in full_dispatch_request
    rv = self.dispatch_request()
  File "/home/amartinezi/sincere/venv/lib64/python3.9/site-packages/flask/app.py", line 865, in dispatch_request
    return self.ensure_sync(self.view_functions[rule.endpoint])(**view_args)  # type: ignore[no-any-return]
  File "/home/amartinezi/sincere/api_scheduler_experiments.py", line 473, in inference
    model_usage_count[model_alias] += 1
NameError: name 'model_usage_count' is not defined
2024-09-23 14:13:16,873 127.0.0.1 - - [23/Sep/2024 14:13:16] "[35m[1mPOST /inference HTTP/1.1[0m" 500 -
2024-09-23 14:13:17,209 Request with ID e9442b72 for model gemma-7b received
2024-09-23 14:13:17,209 Exception on /inference [POST]
Traceback (most recent call last):
  File "/home/amartinezi/sincere/venv/lib64/python3.9/site-packages/flask/app.py", line 1473, in wsgi_app
    response = self.full_dispatch_request()
  File "/home/amartinezi/sincere/venv/lib64/python3.9/site-packages/flask/app.py", line 882, in full_dispatch_request
    rv = self.handle_user_exception(e)
  File "/home/amartinezi/sincere/venv/lib64/python3.9/site-packages/flask/app.py", line 880, in full_dispatch_request
    rv = self.dispatch_request()
  File "/home/amartinezi/sincere/venv/lib64/python3.9/site-packages/flask/app.py", line 865, in dispatch_request
    return self.ensure_sync(self.view_functions[rule.endpoint])(**view_args)  # type: ignore[no-any-return]
  File "/home/amartinezi/sincere/api_scheduler_experiments.py", line 473, in inference
    model_usage_count[model_alias] += 1
NameError: name 'model_usage_count' is not defined
2024-09-23 14:13:17,209 127.0.0.1 - - [23/Sep/2024 14:13:17] "[35m[1mPOST /inference HTTP/1.1[0m" 500 -
2024-09-23 14:13:17,352 Request with ID 42990871 for model gemma-7b received
2024-09-23 14:13:17,352 Exception on /inference [POST]
Traceback (most recent call last):
  File "/home/amartinezi/sincere/venv/lib64/python3.9/site-packages/flask/app.py", line 1473, in wsgi_app
    response = self.full_dispatch_request()
  File "/home/amartinezi/sincere/venv/lib64/python3.9/site-packages/flask/app.py", line 882, in full_dispatch_request
    rv = self.handle_user_exception(e)
  File "/home/amartinezi/sincere/venv/lib64/python3.9/site-packages/flask/app.py", line 880, in full_dispatch_request
    rv = self.dispatch_request()
  File "/home/amartinezi/sincere/venv/lib64/python3.9/site-packages/flask/app.py", line 865, in dispatch_request
    return self.ensure_sync(self.view_functions[rule.endpoint])(**view_args)  # type: ignore[no-any-return]
  File "/home/amartinezi/sincere/api_scheduler_experiments.py", line 473, in inference
    model_usage_count[model_alias] += 1
NameError: name 'model_usage_count' is not defined
2024-09-23 14:13:17,353 127.0.0.1 - - [23/Sep/2024 14:13:17] "[35m[1mPOST /inference HTTP/1.1[0m" 500 -
2024-09-23 14:13:17,449 Request with ID ee5151c9 for model llama3-8b received
2024-09-23 14:13:17,449 Exception on /inference [POST]
Traceback (most recent call last):
  File "/home/amartinezi/sincere/venv/lib64/python3.9/site-packages/flask/app.py", line 1473, in wsgi_app
    response = self.full_dispatch_request()
  File "/home/amartinezi/sincere/venv/lib64/python3.9/site-packages/flask/app.py", line 882, in full_dispatch_request
    rv = self.handle_user_exception(e)
  File "/home/amartinezi/sincere/venv/lib64/python3.9/site-packages/flask/app.py", line 880, in full_dispatch_request
    rv = self.dispatch_request()
  File "/home/amartinezi/sincere/venv/lib64/python3.9/site-packages/flask/app.py", line 865, in dispatch_request
    return self.ensure_sync(self.view_functions[rule.endpoint])(**view_args)  # type: ignore[no-any-return]
  File "/home/amartinezi/sincere/api_scheduler_experiments.py", line 473, in inference
    model_usage_count[model_alias] += 1
NameError: name 'model_usage_count' is not defined
2024-09-23 14:13:17,450 127.0.0.1 - - [23/Sep/2024 14:13:17] "[35m[1mPOST /inference HTTP/1.1[0m" 500 -
2024-09-23 14:13:17,498 Request with ID 68e22640 for model granite-7b received
2024-09-23 14:13:17,499 Exception on /inference [POST]
Traceback (most recent call last):
  File "/home/amartinezi/sincere/venv/lib64/python3.9/site-packages/flask/app.py", line 1473, in wsgi_app
    response = self.full_dispatch_request()
  File "/home/amartinezi/sincere/venv/lib64/python3.9/site-packages/flask/app.py", line 882, in full_dispatch_request
    rv = self.handle_user_exception(e)
  File "/home/amartinezi/sincere/venv/lib64/python3.9/site-packages/flask/app.py", line 880, in full_dispatch_request
    rv = self.dispatch_request()
  File "/home/amartinezi/sincere/venv/lib64/python3.9/site-packages/flask/app.py", line 865, in dispatch_request
    return self.ensure_sync(self.view_functions[rule.endpoint])(**view_args)  # type: ignore[no-any-return]
  File "/home/amartinezi/sincere/api_scheduler_experiments.py", line 473, in inference
    model_usage_count[model_alias] += 1
NameError: name 'model_usage_count' is not defined
2024-09-23 14:13:17,499 127.0.0.1 - - [23/Sep/2024 14:13:17] "[35m[1mPOST /inference HTTP/1.1[0m" 500 -
2024-09-23 14:13:17,506 Request with ID 6b02e337 for model gemma-7b received
2024-09-23 14:13:17,506 Exception on /inference [POST]
Traceback (most recent call last):
  File "/home/amartinezi/sincere/venv/lib64/python3.9/site-packages/flask/app.py", line 1473, in wsgi_app
    response = self.full_dispatch_request()
  File "/home/amartinezi/sincere/venv/lib64/python3.9/site-packages/flask/app.py", line 882, in full_dispatch_request
    rv = self.handle_user_exception(e)
  File "/home/amartinezi/sincere/venv/lib64/python3.9/site-packages/flask/app.py", line 880, in full_dispatch_request
    rv = self.dispatch_request()
  File "/home/amartinezi/sincere/venv/lib64/python3.9/site-packages/flask/app.py", line 865, in dispatch_request
    return self.ensure_sync(self.view_functions[rule.endpoint])(**view_args)  # type: ignore[no-any-return]
  File "/home/amartinezi/sincere/api_scheduler_experiments.py", line 473, in inference
    model_usage_count[model_alias] += 1
NameError: name 'model_usage_count' is not defined
2024-09-23 14:13:17,506 127.0.0.1 - - [23/Sep/2024 14:13:17] "[35m[1mPOST /inference HTTP/1.1[0m" 500 -
2024-09-23 14:13:17,902 Request with ID 89f08836 for model llama3-8b received
2024-09-23 14:13:17,902 Exception on /inference [POST]
Traceback (most recent call last):
  File "/home/amartinezi/sincere/venv/lib64/python3.9/site-packages/flask/app.py", line 1473, in wsgi_app
    response = self.full_dispatch_request()
  File "/home/amartinezi/sincere/venv/lib64/python3.9/site-packages/flask/app.py", line 882, in full_dispatch_request
    rv = self.handle_user_exception(e)
  File "/home/amartinezi/sincere/venv/lib64/python3.9/site-packages/flask/app.py", line 880, in full_dispatch_request
    rv = self.dispatch_request()
  File "/home/amartinezi/sincere/venv/lib64/python3.9/site-packages/flask/app.py", line 865, in dispatch_request
    return self.ensure_sync(self.view_functions[rule.endpoint])(**view_args)  # type: ignore[no-any-return]
  File "/home/amartinezi/sincere/api_scheduler_experiments.py", line 473, in inference
    model_usage_count[model_alias] += 1
NameError: name 'model_usage_count' is not defined
2024-09-23 14:13:17,902 127.0.0.1 - - [23/Sep/2024 14:13:17] "[35m[1mPOST /inference HTTP/1.1[0m" 500 -
2024-09-23 14:13:17,912 Request with ID 7c346824 for model gemma-7b received
2024-09-23 14:13:17,912 Exception on /inference [POST]
Traceback (most recent call last):
  File "/home/amartinezi/sincere/venv/lib64/python3.9/site-packages/flask/app.py", line 1473, in wsgi_app
    response = self.full_dispatch_request()
  File "/home/amartinezi/sincere/venv/lib64/python3.9/site-packages/flask/app.py", line 882, in full_dispatch_request
    rv = self.handle_user_exception(e)
  File "/home/amartinezi/sincere/venv/lib64/python3.9/site-packages/flask/app.py", line 880, in full_dispatch_request
    rv = self.dispatch_request()
  File "/home/amartinezi/sincere/venv/lib64/python3.9/site-packages/flask/app.py", line 865, in dispatch_request
    return self.ensure_sync(self.view_functions[rule.endpoint])(**view_args)  # type: ignore[no-any-return]
  File "/home/amartinezi/sincere/api_scheduler_experiments.py", line 473, in inference
    model_usage_count[model_alias] += 1
NameError: name 'model_usage_count' is not defined
2024-09-23 14:13:17,913 127.0.0.1 - - [23/Sep/2024 14:13:17] "[35m[1mPOST /inference HTTP/1.1[0m" 500 -
2024-09-23 14:13:18,055 Request with ID c6204666 for model llama3-8b received
2024-09-23 14:13:18,055 Exception on /inference [POST]
Traceback (most recent call last):
  File "/home/amartinezi/sincere/venv/lib64/python3.9/site-packages/flask/app.py", line 1473, in wsgi_app
    response = self.full_dispatch_request()
  File "/home/amartinezi/sincere/venv/lib64/python3.9/site-packages/flask/app.py", line 882, in full_dispatch_request
    rv = self.handle_user_exception(e)
  File "/home/amartinezi/sincere/venv/lib64/python3.9/site-packages/flask/app.py", line 880, in full_dispatch_request
    rv = self.dispatch_request()
  File "/home/amartinezi/sincere/venv/lib64/python3.9/site-packages/flask/app.py", line 865, in dispatch_request
    return self.ensure_sync(self.view_functions[rule.endpoint])(**view_args)  # type: ignore[no-any-return]
  File "/home/amartinezi/sincere/api_scheduler_experiments.py", line 473, in inference
    model_usage_count[model_alias] += 1
NameError: name 'model_usage_count' is not defined
2024-09-23 14:13:18,056 127.0.0.1 - - [23/Sep/2024 14:13:18] "[35m[1mPOST /inference HTTP/1.1[0m" 500 -
2024-09-23 14:13:18,067 Request with ID c2124e2a for model llama3-8b received
2024-09-23 14:13:18,067 Exception on /inference [POST]
Traceback (most recent call last):
  File "/home/amartinezi/sincere/venv/lib64/python3.9/site-packages/flask/app.py", line 1473, in wsgi_app
    response = self.full_dispatch_request()
  File "/home/amartinezi/sincere/venv/lib64/python3.9/site-packages/flask/app.py", line 882, in full_dispatch_request
    rv = self.handle_user_exception(e)
  File "/home/amartinezi/sincere/venv/lib64/python3.9/site-packages/flask/app.py", line 880, in full_dispatch_request
    rv = self.dispatch_request()
  File "/home/amartinezi/sincere/venv/lib64/python3.9/site-packages/flask/app.py", line 865, in dispatch_request
    return self.ensure_sync(self.view_functions[rule.endpoint])(**view_args)  # type: ignore[no-any-return]
  File "/home/amartinezi/sincere/api_scheduler_experiments.py", line 473, in inference
    model_usage_count[model_alias] += 1
NameError: name 'model_usage_count' is not defined
2024-09-23 14:13:18,067 127.0.0.1 - - [23/Sep/2024 14:13:18] "[35m[1mPOST /inference HTTP/1.1[0m" 500 -
2024-09-23 14:13:18,758 Request with ID 15934d0f for model llama3-8b received
2024-09-23 14:13:18,759 Exception on /inference [POST]
Traceback (most recent call last):
  File "/home/amartinezi/sincere/venv/lib64/python3.9/site-packages/flask/app.py", line 1473, in wsgi_app
    response = self.full_dispatch_request()
  File "/home/amartinezi/sincere/venv/lib64/python3.9/site-packages/flask/app.py", line 882, in full_dispatch_request
    rv = self.handle_user_exception(e)
  File "/home/amartinezi/sincere/venv/lib64/python3.9/site-packages/flask/app.py", line 880, in full_dispatch_request
    rv = self.dispatch_request()
  File "/home/amartinezi/sincere/venv/lib64/python3.9/site-packages/flask/app.py", line 865, in dispatch_request
    return self.ensure_sync(self.view_functions[rule.endpoint])(**view_args)  # type: ignore[no-any-return]
  File "/home/amartinezi/sincere/api_scheduler_experiments.py", line 473, in inference
    model_usage_count[model_alias] += 1
NameError: name 'model_usage_count' is not defined
2024-09-23 14:13:18,759 127.0.0.1 - - [23/Sep/2024 14:13:18] "[35m[1mPOST /inference HTTP/1.1[0m" 500 -
2024-09-23 14:13:19,034 Request with ID 5d31dea8 for model llama3-8b received
2024-09-23 14:13:19,034 Exception on /inference [POST]
Traceback (most recent call last):
  File "/home/amartinezi/sincere/venv/lib64/python3.9/site-packages/flask/app.py", line 1473, in wsgi_app
    response = self.full_dispatch_request()
  File "/home/amartinezi/sincere/venv/lib64/python3.9/site-packages/flask/app.py", line 882, in full_dispatch_request
    rv = self.handle_user_exception(e)
  File "/home/amartinezi/sincere/venv/lib64/python3.9/site-packages/flask/app.py", line 880, in full_dispatch_request
    rv = self.dispatch_request()
  File "/home/amartinezi/sincere/venv/lib64/python3.9/site-packages/flask/app.py", line 865, in dispatch_request
    return self.ensure_sync(self.view_functions[rule.endpoint])(**view_args)  # type: ignore[no-any-return]
  File "/home/amartinezi/sincere/api_scheduler_experiments.py", line 473, in inference
    model_usage_count[model_alias] += 1
NameError: name 'model_usage_count' is not defined
2024-09-23 14:13:19,034 127.0.0.1 - - [23/Sep/2024 14:13:19] "[35m[1mPOST /inference HTTP/1.1[0m" 500 -
2024-09-23 14:13:19,468 Request with ID 6c05a285 for model llama3-8b received
2024-09-23 14:13:19,468 Exception on /inference [POST]
Traceback (most recent call last):
  File "/home/amartinezi/sincere/venv/lib64/python3.9/site-packages/flask/app.py", line 1473, in wsgi_app
    response = self.full_dispatch_request()
  File "/home/amartinezi/sincere/venv/lib64/python3.9/site-packages/flask/app.py", line 882, in full_dispatch_request
    rv = self.handle_user_exception(e)
  File "/home/amartinezi/sincere/venv/lib64/python3.9/site-packages/flask/app.py", line 880, in full_dispatch_request
    rv = self.dispatch_request()
  File "/home/amartinezi/sincere/venv/lib64/python3.9/site-packages/flask/app.py", line 865, in dispatch_request
    return self.ensure_sync(self.view_functions[rule.endpoint])(**view_args)  # type: ignore[no-any-return]
  File "/home/amartinezi/sincere/api_scheduler_experiments.py", line 473, in inference
    model_usage_count[model_alias] += 1
NameError: name 'model_usage_count' is not defined
2024-09-23 14:13:19,469 127.0.0.1 - - [23/Sep/2024 14:13:19] "[35m[1mPOST /inference HTTP/1.1[0m" 500 -
2024-09-23 14:13:19,482 Request with ID 71a4e336 for model llama3-8b received
2024-09-23 14:13:19,483 Exception on /inference [POST]
Traceback (most recent call last):
  File "/home/amartinezi/sincere/venv/lib64/python3.9/site-packages/flask/app.py", line 1473, in wsgi_app
    response = self.full_dispatch_request()
  File "/home/amartinezi/sincere/venv/lib64/python3.9/site-packages/flask/app.py", line 882, in full_dispatch_request
    rv = self.handle_user_exception(e)
  File "/home/amartinezi/sincere/venv/lib64/python3.9/site-packages/flask/app.py", line 880, in full_dispatch_request
    rv = self.dispatch_request()
  File "/home/amartinezi/sincere/venv/lib64/python3.9/site-packages/flask/app.py", line 865, in dispatch_request
    return self.ensure_sync(self.view_functions[rule.endpoint])(**view_args)  # type: ignore[no-any-return]
  File "/home/amartinezi/sincere/api_scheduler_experiments.py", line 473, in inference
    model_usage_count[model_alias] += 1
NameError: name 'model_usage_count' is not defined
2024-09-23 14:13:19,483 127.0.0.1 - - [23/Sep/2024 14:13:19] "[35m[1mPOST /inference HTTP/1.1[0m" 500 -
2024-09-23 14:13:19,515 Request with ID 0a1d016f for model llama3-8b received
2024-09-23 14:13:19,515 Exception on /inference [POST]
Traceback (most recent call last):
  File "/home/amartinezi/sincere/venv/lib64/python3.9/site-packages/flask/app.py", line 1473, in wsgi_app
    response = self.full_dispatch_request()
  File "/home/amartinezi/sincere/venv/lib64/python3.9/site-packages/flask/app.py", line 882, in full_dispatch_request
    rv = self.handle_user_exception(e)
  File "/home/amartinezi/sincere/venv/lib64/python3.9/site-packages/flask/app.py", line 880, in full_dispatch_request
    rv = self.dispatch_request()
  File "/home/amartinezi/sincere/venv/lib64/python3.9/site-packages/flask/app.py", line 865, in dispatch_request
    return self.ensure_sync(self.view_functions[rule.endpoint])(**view_args)  # type: ignore[no-any-return]
  File "/home/amartinezi/sincere/api_scheduler_experiments.py", line 473, in inference
    model_usage_count[model_alias] += 1
NameError: name 'model_usage_count' is not defined
2024-09-23 14:13:19,515 127.0.0.1 - - [23/Sep/2024 14:13:19] "[35m[1mPOST /inference HTTP/1.1[0m" 500 -
2024-09-23 14:13:19,670 Request with ID 403e31df for model llama3-8b received
2024-09-23 14:13:19,670 Exception on /inference [POST]
Traceback (most recent call last):
  File "/home/amartinezi/sincere/venv/lib64/python3.9/site-packages/flask/app.py", line 1473, in wsgi_app
    response = self.full_dispatch_request()
  File "/home/amartinezi/sincere/venv/lib64/python3.9/site-packages/flask/app.py", line 882, in full_dispatch_request
    rv = self.handle_user_exception(e)
  File "/home/amartinezi/sincere/venv/lib64/python3.9/site-packages/flask/app.py", line 880, in full_dispatch_request
    rv = self.dispatch_request()
  File "/home/amartinezi/sincere/venv/lib64/python3.9/site-packages/flask/app.py", line 865, in dispatch_request
    return self.ensure_sync(self.view_functions[rule.endpoint])(**view_args)  # type: ignore[no-any-return]
  File "/home/amartinezi/sincere/api_scheduler_experiments.py", line 473, in inference
    model_usage_count[model_alias] += 1
NameError: name 'model_usage_count' is not defined
2024-09-23 14:13:19,671 127.0.0.1 - - [23/Sep/2024 14:13:19] "[35m[1mPOST /inference HTTP/1.1[0m" 500 -
2024-09-23 14:13:19,703 Request with ID 3670bc93 for model llama3-8b received
2024-09-23 14:13:19,703 Exception on /inference [POST]
Traceback (most recent call last):
  File "/home/amartinezi/sincere/venv/lib64/python3.9/site-packages/flask/app.py", line 1473, in wsgi_app
    response = self.full_dispatch_request()
  File "/home/amartinezi/sincere/venv/lib64/python3.9/site-packages/flask/app.py", line 882, in full_dispatch_request
    rv = self.handle_user_exception(e)
  File "/home/amartinezi/sincere/venv/lib64/python3.9/site-packages/flask/app.py", line 880, in full_dispatch_request
    rv = self.dispatch_request()
  File "/home/amartinezi/sincere/venv/lib64/python3.9/site-packages/flask/app.py", line 865, in dispatch_request
    return self.ensure_sync(self.view_functions[rule.endpoint])(**view_args)  # type: ignore[no-any-return]
  File "/home/amartinezi/sincere/api_scheduler_experiments.py", line 473, in inference
    model_usage_count[model_alias] += 1
NameError: name 'model_usage_count' is not defined
2024-09-23 14:13:19,704 127.0.0.1 - - [23/Sep/2024 14:13:19] "[35m[1mPOST /inference HTTP/1.1[0m" 500 -
2024-09-23 14:13:19,971 Request with ID a4606984 for model llama3-8b received
2024-09-23 14:13:19,972 Exception on /inference [POST]
Traceback (most recent call last):
  File "/home/amartinezi/sincere/venv/lib64/python3.9/site-packages/flask/app.py", line 1473, in wsgi_app
    response = self.full_dispatch_request()
  File "/home/amartinezi/sincere/venv/lib64/python3.9/site-packages/flask/app.py", line 882, in full_dispatch_request
    rv = self.handle_user_exception(e)
  File "/home/amartinezi/sincere/venv/lib64/python3.9/site-packages/flask/app.py", line 880, in full_dispatch_request
    rv = self.dispatch_request()
  File "/home/amartinezi/sincere/venv/lib64/python3.9/site-packages/flask/app.py", line 865, in dispatch_request
    return self.ensure_sync(self.view_functions[rule.endpoint])(**view_args)  # type: ignore[no-any-return]
  File "/home/amartinezi/sincere/api_scheduler_experiments.py", line 473, in inference
    model_usage_count[model_alias] += 1
NameError: name 'model_usage_count' is not defined
2024-09-23 14:13:19,972 127.0.0.1 - - [23/Sep/2024 14:13:19] "[35m[1mPOST /inference HTTP/1.1[0m" 500 -
2024-09-23 14:13:20,507 Request with ID cdfa5e25 for model gemma-7b received
2024-09-23 14:13:20,507 Exception on /inference [POST]
Traceback (most recent call last):
  File "/home/amartinezi/sincere/venv/lib64/python3.9/site-packages/flask/app.py", line 1473, in wsgi_app
    response = self.full_dispatch_request()
  File "/home/amartinezi/sincere/venv/lib64/python3.9/site-packages/flask/app.py", line 882, in full_dispatch_request
    rv = self.handle_user_exception(e)
  File "/home/amartinezi/sincere/venv/lib64/python3.9/site-packages/flask/app.py", line 880, in full_dispatch_request
    rv = self.dispatch_request()
  File "/home/amartinezi/sincere/venv/lib64/python3.9/site-packages/flask/app.py", line 865, in dispatch_request
    return self.ensure_sync(self.view_functions[rule.endpoint])(**view_args)  # type: ignore[no-any-return]
  File "/home/amartinezi/sincere/api_scheduler_experiments.py", line 473, in inference
    model_usage_count[model_alias] += 1
NameError: name 'model_usage_count' is not defined
2024-09-23 14:13:20,508 127.0.0.1 - - [23/Sep/2024 14:13:20] "[35m[1mPOST /inference HTTP/1.1[0m" 500 -
2024-09-23 14:13:20,663 Request with ID 08dd0538 for model llama3-8b received
2024-09-23 14:13:20,663 Exception on /inference [POST]
Traceback (most recent call last):
  File "/home/amartinezi/sincere/venv/lib64/python3.9/site-packages/flask/app.py", line 1473, in wsgi_app
    response = self.full_dispatch_request()
  File "/home/amartinezi/sincere/venv/lib64/python3.9/site-packages/flask/app.py", line 882, in full_dispatch_request
    rv = self.handle_user_exception(e)
  File "/home/amartinezi/sincere/venv/lib64/python3.9/site-packages/flask/app.py", line 880, in full_dispatch_request
    rv = self.dispatch_request()
  File "/home/amartinezi/sincere/venv/lib64/python3.9/site-packages/flask/app.py", line 865, in dispatch_request
    return self.ensure_sync(self.view_functions[rule.endpoint])(**view_args)  # type: ignore[no-any-return]
  File "/home/amartinezi/sincere/api_scheduler_experiments.py", line 473, in inference
    model_usage_count[model_alias] += 1
NameError: name 'model_usage_count' is not defined
2024-09-23 14:13:20,664 127.0.0.1 - - [23/Sep/2024 14:13:20] "[35m[1mPOST /inference HTTP/1.1[0m" 500 -
2024-09-23 14:13:20,767 Request with ID 58fe159b for model gemma-7b received
2024-09-23 14:13:20,767 Exception on /inference [POST]
Traceback (most recent call last):
  File "/home/amartinezi/sincere/venv/lib64/python3.9/site-packages/flask/app.py", line 1473, in wsgi_app
    response = self.full_dispatch_request()
  File "/home/amartinezi/sincere/venv/lib64/python3.9/site-packages/flask/app.py", line 882, in full_dispatch_request
    rv = self.handle_user_exception(e)
  File "/home/amartinezi/sincere/venv/lib64/python3.9/site-packages/flask/app.py", line 880, in full_dispatch_request
    rv = self.dispatch_request()
  File "/home/amartinezi/sincere/venv/lib64/python3.9/site-packages/flask/app.py", line 865, in dispatch_request
    return self.ensure_sync(self.view_functions[rule.endpoint])(**view_args)  # type: ignore[no-any-return]
  File "/home/amartinezi/sincere/api_scheduler_experiments.py", line 473, in inference
    model_usage_count[model_alias] += 1
NameError: name 'model_usage_count' is not defined
2024-09-23 14:13:20,768 127.0.0.1 - - [23/Sep/2024 14:13:20] "[35m[1mPOST /inference HTTP/1.1[0m" 500 -
2024-09-23 14:13:20,819 Request with ID 5fb1f8b4 for model granite-7b received
2024-09-23 14:13:20,819 Exception on /inference [POST]
Traceback (most recent call last):
  File "/home/amartinezi/sincere/venv/lib64/python3.9/site-packages/flask/app.py", line 1473, in wsgi_app
    response = self.full_dispatch_request()
  File "/home/amartinezi/sincere/venv/lib64/python3.9/site-packages/flask/app.py", line 882, in full_dispatch_request
    rv = self.handle_user_exception(e)
  File "/home/amartinezi/sincere/venv/lib64/python3.9/site-packages/flask/app.py", line 880, in full_dispatch_request
    rv = self.dispatch_request()
  File "/home/amartinezi/sincere/venv/lib64/python3.9/site-packages/flask/app.py", line 865, in dispatch_request
    return self.ensure_sync(self.view_functions[rule.endpoint])(**view_args)  # type: ignore[no-any-return]
  File "/home/amartinezi/sincere/api_scheduler_experiments.py", line 473, in inference
    model_usage_count[model_alias] += 1
NameError: name 'model_usage_count' is not defined
2024-09-23 14:13:20,820 127.0.0.1 - - [23/Sep/2024 14:13:20] "[35m[1mPOST /inference HTTP/1.1[0m" 500 -
2024-09-23 14:13:20,901 Request with ID f1225b2d for model llama3-8b received
2024-09-23 14:13:20,901 Exception on /inference [POST]
Traceback (most recent call last):
  File "/home/amartinezi/sincere/venv/lib64/python3.9/site-packages/flask/app.py", line 1473, in wsgi_app
    response = self.full_dispatch_request()
  File "/home/amartinezi/sincere/venv/lib64/python3.9/site-packages/flask/app.py", line 882, in full_dispatch_request
    rv = self.handle_user_exception(e)
  File "/home/amartinezi/sincere/venv/lib64/python3.9/site-packages/flask/app.py", line 880, in full_dispatch_request
    rv = self.dispatch_request()
  File "/home/amartinezi/sincere/venv/lib64/python3.9/site-packages/flask/app.py", line 865, in dispatch_request
    return self.ensure_sync(self.view_functions[rule.endpoint])(**view_args)  # type: ignore[no-any-return]
  File "/home/amartinezi/sincere/api_scheduler_experiments.py", line 473, in inference
    model_usage_count[model_alias] += 1
NameError: name 'model_usage_count' is not defined
2024-09-23 14:13:20,902 127.0.0.1 - - [23/Sep/2024 14:13:20] "[35m[1mPOST /inference HTTP/1.1[0m" 500 -
2024-09-23 14:13:21,084 Request with ID 9379ee02 for model llama3-8b received
2024-09-23 14:13:21,084 Exception on /inference [POST]
Traceback (most recent call last):
  File "/home/amartinezi/sincere/venv/lib64/python3.9/site-packages/flask/app.py", line 1473, in wsgi_app
    response = self.full_dispatch_request()
  File "/home/amartinezi/sincere/venv/lib64/python3.9/site-packages/flask/app.py", line 882, in full_dispatch_request
    rv = self.handle_user_exception(e)
  File "/home/amartinezi/sincere/venv/lib64/python3.9/site-packages/flask/app.py", line 880, in full_dispatch_request
    rv = self.dispatch_request()
  File "/home/amartinezi/sincere/venv/lib64/python3.9/site-packages/flask/app.py", line 865, in dispatch_request
    return self.ensure_sync(self.view_functions[rule.endpoint])(**view_args)  # type: ignore[no-any-return]
  File "/home/amartinezi/sincere/api_scheduler_experiments.py", line 473, in inference
    model_usage_count[model_alias] += 1
NameError: name 'model_usage_count' is not defined
2024-09-23 14:13:21,085 127.0.0.1 - - [23/Sep/2024 14:13:21] "[35m[1mPOST /inference HTTP/1.1[0m" 500 -
2024-09-23 14:13:21,258 Request with ID 127002f6 for model gemma-7b received
2024-09-23 14:13:21,258 Exception on /inference [POST]
Traceback (most recent call last):
  File "/home/amartinezi/sincere/venv/lib64/python3.9/site-packages/flask/app.py", line 1473, in wsgi_app
    response = self.full_dispatch_request()
  File "/home/amartinezi/sincere/venv/lib64/python3.9/site-packages/flask/app.py", line 882, in full_dispatch_request
    rv = self.handle_user_exception(e)
  File "/home/amartinezi/sincere/venv/lib64/python3.9/site-packages/flask/app.py", line 880, in full_dispatch_request
    rv = self.dispatch_request()
  File "/home/amartinezi/sincere/venv/lib64/python3.9/site-packages/flask/app.py", line 865, in dispatch_request
    return self.ensure_sync(self.view_functions[rule.endpoint])(**view_args)  # type: ignore[no-any-return]
  File "/home/amartinezi/sincere/api_scheduler_experiments.py", line 473, in inference
    model_usage_count[model_alias] += 1
NameError: name 'model_usage_count' is not defined
2024-09-23 14:13:21,259 127.0.0.1 - - [23/Sep/2024 14:13:21] "[35m[1mPOST /inference HTTP/1.1[0m" 500 -
2024-09-23 14:13:21,323 Request with ID 0daca6ca for model gemma-7b received
2024-09-23 14:13:21,323 Exception on /inference [POST]
Traceback (most recent call last):
  File "/home/amartinezi/sincere/venv/lib64/python3.9/site-packages/flask/app.py", line 1473, in wsgi_app
    response = self.full_dispatch_request()
  File "/home/amartinezi/sincere/venv/lib64/python3.9/site-packages/flask/app.py", line 882, in full_dispatch_request
    rv = self.handle_user_exception(e)
  File "/home/amartinezi/sincere/venv/lib64/python3.9/site-packages/flask/app.py", line 880, in full_dispatch_request
    rv = self.dispatch_request()
  File "/home/amartinezi/sincere/venv/lib64/python3.9/site-packages/flask/app.py", line 865, in dispatch_request
    return self.ensure_sync(self.view_functions[rule.endpoint])(**view_args)  # type: ignore[no-any-return]
  File "/home/amartinezi/sincere/api_scheduler_experiments.py", line 473, in inference
    model_usage_count[model_alias] += 1
NameError: name 'model_usage_count' is not defined
2024-09-23 14:13:21,323 127.0.0.1 - - [23/Sep/2024 14:13:21] "[35m[1mPOST /inference HTTP/1.1[0m" 500 -
2024-09-23 14:13:21,578 Request with ID 9ddcd10a for model llama3-8b received
2024-09-23 14:13:21,578 Exception on /inference [POST]
Traceback (most recent call last):
  File "/home/amartinezi/sincere/venv/lib64/python3.9/site-packages/flask/app.py", line 1473, in wsgi_app
    response = self.full_dispatch_request()
  File "/home/amartinezi/sincere/venv/lib64/python3.9/site-packages/flask/app.py", line 882, in full_dispatch_request
    rv = self.handle_user_exception(e)
  File "/home/amartinezi/sincere/venv/lib64/python3.9/site-packages/flask/app.py", line 880, in full_dispatch_request
    rv = self.dispatch_request()
  File "/home/amartinezi/sincere/venv/lib64/python3.9/site-packages/flask/app.py", line 865, in dispatch_request
    return self.ensure_sync(self.view_functions[rule.endpoint])(**view_args)  # type: ignore[no-any-return]
  File "/home/amartinezi/sincere/api_scheduler_experiments.py", line 473, in inference
    model_usage_count[model_alias] += 1
NameError: name 'model_usage_count' is not defined
2024-09-23 14:13:21,579 127.0.0.1 - - [23/Sep/2024 14:13:21] "[35m[1mPOST /inference HTTP/1.1[0m" 500 -
2024-09-23 14:13:21,782 Request with ID ac1d8674 for model llama3-8b received
2024-09-23 14:13:21,782 Exception on /inference [POST]
Traceback (most recent call last):
  File "/home/amartinezi/sincere/venv/lib64/python3.9/site-packages/flask/app.py", line 1473, in wsgi_app
    response = self.full_dispatch_request()
  File "/home/amartinezi/sincere/venv/lib64/python3.9/site-packages/flask/app.py", line 882, in full_dispatch_request
    rv = self.handle_user_exception(e)
  File "/home/amartinezi/sincere/venv/lib64/python3.9/site-packages/flask/app.py", line 880, in full_dispatch_request
    rv = self.dispatch_request()
  File "/home/amartinezi/sincere/venv/lib64/python3.9/site-packages/flask/app.py", line 865, in dispatch_request
    return self.ensure_sync(self.view_functions[rule.endpoint])(**view_args)  # type: ignore[no-any-return]
  File "/home/amartinezi/sincere/api_scheduler_experiments.py", line 473, in inference
    model_usage_count[model_alias] += 1
NameError: name 'model_usage_count' is not defined
2024-09-23 14:13:21,783 127.0.0.1 - - [23/Sep/2024 14:13:21] "[35m[1mPOST /inference HTTP/1.1[0m" 500 -
2024-09-23 14:13:21,787 Request with ID c615f64d for model granite-7b received
2024-09-23 14:13:21,787 Exception on /inference [POST]
Traceback (most recent call last):
  File "/home/amartinezi/sincere/venv/lib64/python3.9/site-packages/flask/app.py", line 1473, in wsgi_app
    response = self.full_dispatch_request()
  File "/home/amartinezi/sincere/venv/lib64/python3.9/site-packages/flask/app.py", line 882, in full_dispatch_request
    rv = self.handle_user_exception(e)
  File "/home/amartinezi/sincere/venv/lib64/python3.9/site-packages/flask/app.py", line 880, in full_dispatch_request
    rv = self.dispatch_request()
  File "/home/amartinezi/sincere/venv/lib64/python3.9/site-packages/flask/app.py", line 865, in dispatch_request
    return self.ensure_sync(self.view_functions[rule.endpoint])(**view_args)  # type: ignore[no-any-return]
  File "/home/amartinezi/sincere/api_scheduler_experiments.py", line 473, in inference
    model_usage_count[model_alias] += 1
NameError: name 'model_usage_count' is not defined
2024-09-23 14:13:21,788 127.0.0.1 - - [23/Sep/2024 14:13:21] "[35m[1mPOST /inference HTTP/1.1[0m" 500 -
2024-09-23 14:13:22,113 Request with ID ba9e3137 for model gemma-7b received
2024-09-23 14:13:22,114 Exception on /inference [POST]
Traceback (most recent call last):
  File "/home/amartinezi/sincere/venv/lib64/python3.9/site-packages/flask/app.py", line 1473, in wsgi_app
    response = self.full_dispatch_request()
  File "/home/amartinezi/sincere/venv/lib64/python3.9/site-packages/flask/app.py", line 882, in full_dispatch_request
    rv = self.handle_user_exception(e)
  File "/home/amartinezi/sincere/venv/lib64/python3.9/site-packages/flask/app.py", line 880, in full_dispatch_request
    rv = self.dispatch_request()
  File "/home/amartinezi/sincere/venv/lib64/python3.9/site-packages/flask/app.py", line 865, in dispatch_request
    return self.ensure_sync(self.view_functions[rule.endpoint])(**view_args)  # type: ignore[no-any-return]
  File "/home/amartinezi/sincere/api_scheduler_experiments.py", line 473, in inference
    model_usage_count[model_alias] += 1
NameError: name 'model_usage_count' is not defined
2024-09-23 14:13:22,115 127.0.0.1 - - [23/Sep/2024 14:13:22] "[35m[1mPOST /inference HTTP/1.1[0m" 500 -
2024-09-23 14:13:22,264 Request with ID 27222ff4 for model llama3-8b received
2024-09-23 14:13:22,264 Exception on /inference [POST]
Traceback (most recent call last):
  File "/home/amartinezi/sincere/venv/lib64/python3.9/site-packages/flask/app.py", line 1473, in wsgi_app
    response = self.full_dispatch_request()
  File "/home/amartinezi/sincere/venv/lib64/python3.9/site-packages/flask/app.py", line 882, in full_dispatch_request
    rv = self.handle_user_exception(e)
  File "/home/amartinezi/sincere/venv/lib64/python3.9/site-packages/flask/app.py", line 880, in full_dispatch_request
    rv = self.dispatch_request()
  File "/home/amartinezi/sincere/venv/lib64/python3.9/site-packages/flask/app.py", line 865, in dispatch_request
    return self.ensure_sync(self.view_functions[rule.endpoint])(**view_args)  # type: ignore[no-any-return]
  File "/home/amartinezi/sincere/api_scheduler_experiments.py", line 473, in inference
    model_usage_count[model_alias] += 1
NameError: name 'model_usage_count' is not defined
2024-09-23 14:13:22,265 127.0.0.1 - - [23/Sep/2024 14:13:22] "[35m[1mPOST /inference HTTP/1.1[0m" 500 -
2024-09-23 14:13:22,414 Request with ID 3786633f for model llama3-8b received
2024-09-23 14:13:22,414 Exception on /inference [POST]
Traceback (most recent call last):
  File "/home/amartinezi/sincere/venv/lib64/python3.9/site-packages/flask/app.py", line 1473, in wsgi_app
    response = self.full_dispatch_request()
  File "/home/amartinezi/sincere/venv/lib64/python3.9/site-packages/flask/app.py", line 882, in full_dispatch_request
    rv = self.handle_user_exception(e)
  File "/home/amartinezi/sincere/venv/lib64/python3.9/site-packages/flask/app.py", line 880, in full_dispatch_request
    rv = self.dispatch_request()
  File "/home/amartinezi/sincere/venv/lib64/python3.9/site-packages/flask/app.py", line 865, in dispatch_request
    return self.ensure_sync(self.view_functions[rule.endpoint])(**view_args)  # type: ignore[no-any-return]
  File "/home/amartinezi/sincere/api_scheduler_experiments.py", line 473, in inference
    model_usage_count[model_alias] += 1
NameError: name 'model_usage_count' is not defined
2024-09-23 14:13:22,415 127.0.0.1 - - [23/Sep/2024 14:13:22] "[35m[1mPOST /inference HTTP/1.1[0m" 500 -
2024-09-23 14:13:22,476 Request with ID 052e76d4 for model granite-7b received
2024-09-23 14:13:22,476 Exception on /inference [POST]
Traceback (most recent call last):
  File "/home/amartinezi/sincere/venv/lib64/python3.9/site-packages/flask/app.py", line 1473, in wsgi_app
    response = self.full_dispatch_request()
  File "/home/amartinezi/sincere/venv/lib64/python3.9/site-packages/flask/app.py", line 882, in full_dispatch_request
    rv = self.handle_user_exception(e)
  File "/home/amartinezi/sincere/venv/lib64/python3.9/site-packages/flask/app.py", line 880, in full_dispatch_request
    rv = self.dispatch_request()
  File "/home/amartinezi/sincere/venv/lib64/python3.9/site-packages/flask/app.py", line 865, in dispatch_request
    return self.ensure_sync(self.view_functions[rule.endpoint])(**view_args)  # type: ignore[no-any-return]
  File "/home/amartinezi/sincere/api_scheduler_experiments.py", line 473, in inference
    model_usage_count[model_alias] += 1
NameError: name 'model_usage_count' is not defined
2024-09-23 14:13:22,477 127.0.0.1 - - [23/Sep/2024 14:13:22] "[35m[1mPOST /inference HTTP/1.1[0m" 500 -
