2024-09-09 13:47:10,003 [31m[1mWARNING: This is a development server. Do not use it in a production deployment. Use a production WSGI server instead.[0m
 * Running on all addresses (0.0.0.0)
 * Running on http://127.0.0.1:5000
 * Running on http://192.168.1.212:5000
2024-09-09 13:47:10,003 [33mPress CTRL+C to quit[0m
2024-09-09 13:47:22,806 Exception on /inference [POST]
Traceback (most recent call last):
  File "/Users/amartinezi/miniconda3/envs/confidentialinference/lib/python3.12/site-packages/flask/app.py", line 1473, in wsgi_app
    response = self.full_dispatch_request()
               ^^^^^^^^^^^^^^^^^^^^^^^^^^^^
  File "/Users/amartinezi/miniconda3/envs/confidentialinference/lib/python3.12/site-packages/flask/app.py", line 882, in full_dispatch_request
    rv = self.handle_user_exception(e)
         ^^^^^^^^^^^^^^^^^^^^^^^^^^^^^
  File "/Users/amartinezi/miniconda3/envs/confidentialinference/lib/python3.12/site-packages/flask/app.py", line 880, in full_dispatch_request
    rv = self.dispatch_request()
         ^^^^^^^^^^^^^^^^^^^^^^^
  File "/Users/amartinezi/miniconda3/envs/confidentialinference/lib/python3.12/site-packages/flask/app.py", line 865, in dispatch_request
    return self.ensure_sync(self.view_functions[rule.endpoint])(**view_args)  # type: ignore[no-any-return]
           ^^^^^^^^^^^^^^^^^^^^^^^^^^^^^^^^^^^^^^^^^^^^^^^^^^^^^^^^^^^^^^^^^
  File "/Users/amartinezi/Documents/SINCERE/update.py", line 303, in inference
    loading_time_std = model_load_times_std(model_alias,0)
                       ^^^^^^^^^^^^^^^^^^^^^^^^^^^^^^^^^^^
TypeError: 'dict' object is not callable
2024-09-09 13:47:22,807 127.0.0.1 - - [09/Sep/2024 13:47:22] "[35m[1mPOST /inference HTTP/1.1[0m" 500 -
2024-09-09 13:47:25,283 Exception on /inference [POST]
Traceback (most recent call last):
  File "/Users/amartinezi/miniconda3/envs/confidentialinference/lib/python3.12/site-packages/flask/app.py", line 1473, in wsgi_app
    response = self.full_dispatch_request()
               ^^^^^^^^^^^^^^^^^^^^^^^^^^^^
  File "/Users/amartinezi/miniconda3/envs/confidentialinference/lib/python3.12/site-packages/flask/app.py", line 882, in full_dispatch_request
    rv = self.handle_user_exception(e)
         ^^^^^^^^^^^^^^^^^^^^^^^^^^^^^
  File "/Users/amartinezi/miniconda3/envs/confidentialinference/lib/python3.12/site-packages/flask/app.py", line 880, in full_dispatch_request
    rv = self.dispatch_request()
         ^^^^^^^^^^^^^^^^^^^^^^^
  File "/Users/amartinezi/miniconda3/envs/confidentialinference/lib/python3.12/site-packages/flask/app.py", line 865, in dispatch_request
    return self.ensure_sync(self.view_functions[rule.endpoint])(**view_args)  # type: ignore[no-any-return]
           ^^^^^^^^^^^^^^^^^^^^^^^^^^^^^^^^^^^^^^^^^^^^^^^^^^^^^^^^^^^^^^^^^
  File "/Users/amartinezi/Documents/SINCERE/update.py", line 303, in inference
    loading_time_std = model_load_times_std(model_alias,0)
                       ^^^^^^^^^^^^^^^^^^^^^^^^^^^^^^^^^^^
TypeError: 'dict' object is not callable
2024-09-09 13:47:25,285 127.0.0.1 - - [09/Sep/2024 13:47:25] "[35m[1mPOST /inference HTTP/1.1[0m" 500 -
2024-09-09 13:47:26,275 Exception on /inference [POST]
Traceback (most recent call last):
  File "/Users/amartinezi/miniconda3/envs/confidentialinference/lib/python3.12/site-packages/flask/app.py", line 1473, in wsgi_app
    response = self.full_dispatch_request()
               ^^^^^^^^^^^^^^^^^^^^^^^^^^^^
  File "/Users/amartinezi/miniconda3/envs/confidentialinference/lib/python3.12/site-packages/flask/app.py", line 882, in full_dispatch_request
    rv = self.handle_user_exception(e)
         ^^^^^^^^^^^^^^^^^^^^^^^^^^^^^
  File "/Users/amartinezi/miniconda3/envs/confidentialinference/lib/python3.12/site-packages/flask/app.py", line 880, in full_dispatch_request
    rv = self.dispatch_request()
         ^^^^^^^^^^^^^^^^^^^^^^^
  File "/Users/amartinezi/miniconda3/envs/confidentialinference/lib/python3.12/site-packages/flask/app.py", line 865, in dispatch_request
    return self.ensure_sync(self.view_functions[rule.endpoint])(**view_args)  # type: ignore[no-any-return]
           ^^^^^^^^^^^^^^^^^^^^^^^^^^^^^^^^^^^^^^^^^^^^^^^^^^^^^^^^^^^^^^^^^
  File "/Users/amartinezi/Documents/SINCERE/update.py", line 303, in inference
    loading_time_std = model_load_times_std(model_alias,0)
                       ^^^^^^^^^^^^^^^^^^^^^^^^^^^^^^^^^^^
TypeError: 'dict' object is not callable
2024-09-09 13:47:26,276 127.0.0.1 - - [09/Sep/2024 13:47:26] "[35m[1mPOST /inference HTTP/1.1[0m" 500 -
2024-09-09 13:47:26,464 Exception on /inference [POST]
Traceback (most recent call last):
  File "/Users/amartinezi/miniconda3/envs/confidentialinference/lib/python3.12/site-packages/flask/app.py", line 1473, in wsgi_app
    response = self.full_dispatch_request()
               ^^^^^^^^^^^^^^^^^^^^^^^^^^^^
  File "/Users/amartinezi/miniconda3/envs/confidentialinference/lib/python3.12/site-packages/flask/app.py", line 882, in full_dispatch_request
    rv = self.handle_user_exception(e)
         ^^^^^^^^^^^^^^^^^^^^^^^^^^^^^
  File "/Users/amartinezi/miniconda3/envs/confidentialinference/lib/python3.12/site-packages/flask/app.py", line 880, in full_dispatch_request
    rv = self.dispatch_request()
         ^^^^^^^^^^^^^^^^^^^^^^^
  File "/Users/amartinezi/miniconda3/envs/confidentialinference/lib/python3.12/site-packages/flask/app.py", line 865, in dispatch_request
    return self.ensure_sync(self.view_functions[rule.endpoint])(**view_args)  # type: ignore[no-any-return]
           ^^^^^^^^^^^^^^^^^^^^^^^^^^^^^^^^^^^^^^^^^^^^^^^^^^^^^^^^^^^^^^^^^
  File "/Users/amartinezi/Documents/SINCERE/update.py", line 303, in inference
    loading_time_std = model_load_times_std(model_alias,0)
                       ^^^^^^^^^^^^^^^^^^^^^^^^^^^^^^^^^^^
TypeError: 'dict' object is not callable
2024-09-09 13:47:26,466 127.0.0.1 - - [09/Sep/2024 13:47:26] "[35m[1mPOST /inference HTTP/1.1[0m" 500 -
2024-09-09 13:47:27,574 Exception on /inference [POST]
Traceback (most recent call last):
  File "/Users/amartinezi/miniconda3/envs/confidentialinference/lib/python3.12/site-packages/flask/app.py", line 1473, in wsgi_app
    response = self.full_dispatch_request()
               ^^^^^^^^^^^^^^^^^^^^^^^^^^^^
  File "/Users/amartinezi/miniconda3/envs/confidentialinference/lib/python3.12/site-packages/flask/app.py", line 882, in full_dispatch_request
    rv = self.handle_user_exception(e)
         ^^^^^^^^^^^^^^^^^^^^^^^^^^^^^
  File "/Users/amartinezi/miniconda3/envs/confidentialinference/lib/python3.12/site-packages/flask/app.py", line 880, in full_dispatch_request
    rv = self.dispatch_request()
         ^^^^^^^^^^^^^^^^^^^^^^^
  File "/Users/amartinezi/miniconda3/envs/confidentialinference/lib/python3.12/site-packages/flask/app.py", line 865, in dispatch_request
    return self.ensure_sync(self.view_functions[rule.endpoint])(**view_args)  # type: ignore[no-any-return]
           ^^^^^^^^^^^^^^^^^^^^^^^^^^^^^^^^^^^^^^^^^^^^^^^^^^^^^^^^^^^^^^^^^
  File "/Users/amartinezi/Documents/SINCERE/update.py", line 303, in inference
    loading_time_std = model_load_times_std(model_alias,0)
                       ^^^^^^^^^^^^^^^^^^^^^^^^^^^^^^^^^^^
TypeError: 'dict' object is not callable
2024-09-09 13:47:27,577 127.0.0.1 - - [09/Sep/2024 13:47:27] "[35m[1mPOST /inference HTTP/1.1[0m" 500 -
2024-09-09 13:47:29,562 Exception on /inference [POST]
Traceback (most recent call last):
  File "/Users/amartinezi/miniconda3/envs/confidentialinference/lib/python3.12/site-packages/flask/app.py", line 1473, in wsgi_app
    response = self.full_dispatch_request()
               ^^^^^^^^^^^^^^^^^^^^^^^^^^^^
  File "/Users/amartinezi/miniconda3/envs/confidentialinference/lib/python3.12/site-packages/flask/app.py", line 882, in full_dispatch_request
    rv = self.handle_user_exception(e)
         ^^^^^^^^^^^^^^^^^^^^^^^^^^^^^
  File "/Users/amartinezi/miniconda3/envs/confidentialinference/lib/python3.12/site-packages/flask/app.py", line 880, in full_dispatch_request
    rv = self.dispatch_request()
         ^^^^^^^^^^^^^^^^^^^^^^^
  File "/Users/amartinezi/miniconda3/envs/confidentialinference/lib/python3.12/site-packages/flask/app.py", line 865, in dispatch_request
    return self.ensure_sync(self.view_functions[rule.endpoint])(**view_args)  # type: ignore[no-any-return]
           ^^^^^^^^^^^^^^^^^^^^^^^^^^^^^^^^^^^^^^^^^^^^^^^^^^^^^^^^^^^^^^^^^
  File "/Users/amartinezi/Documents/SINCERE/update.py", line 303, in inference
    loading_time_std = model_load_times_std(model_alias,0)
                       ^^^^^^^^^^^^^^^^^^^^^^^^^^^^^^^^^^^
TypeError: 'dict' object is not callable
2024-09-09 13:47:29,564 127.0.0.1 - - [09/Sep/2024 13:47:29] "[35m[1mPOST /inference HTTP/1.1[0m" 500 -
2024-09-09 13:47:31,388 Exception on /inference [POST]
Traceback (most recent call last):
  File "/Users/amartinezi/miniconda3/envs/confidentialinference/lib/python3.12/site-packages/flask/app.py", line 1473, in wsgi_app
    response = self.full_dispatch_request()
               ^^^^^^^^^^^^^^^^^^^^^^^^^^^^
  File "/Users/amartinezi/miniconda3/envs/confidentialinference/lib/python3.12/site-packages/flask/app.py", line 882, in full_dispatch_request
    rv = self.handle_user_exception(e)
         ^^^^^^^^^^^^^^^^^^^^^^^^^^^^^
  File "/Users/amartinezi/miniconda3/envs/confidentialinference/lib/python3.12/site-packages/flask/app.py", line 880, in full_dispatch_request
    rv = self.dispatch_request()
         ^^^^^^^^^^^^^^^^^^^^^^^
  File "/Users/amartinezi/miniconda3/envs/confidentialinference/lib/python3.12/site-packages/flask/app.py", line 865, in dispatch_request
    return self.ensure_sync(self.view_functions[rule.endpoint])(**view_args)  # type: ignore[no-any-return]
           ^^^^^^^^^^^^^^^^^^^^^^^^^^^^^^^^^^^^^^^^^^^^^^^^^^^^^^^^^^^^^^^^^
  File "/Users/amartinezi/Documents/SINCERE/update.py", line 303, in inference
    loading_time_std = model_load_times_std(model_alias,0)
                       ^^^^^^^^^^^^^^^^^^^^^^^^^^^^^^^^^^^
TypeError: 'dict' object is not callable
2024-09-09 13:47:31,389 127.0.0.1 - - [09/Sep/2024 13:47:31] "[35m[1mPOST /inference HTTP/1.1[0m" 500 -
2024-09-09 13:47:33,086 Exception on /inference [POST]
Traceback (most recent call last):
  File "/Users/amartinezi/miniconda3/envs/confidentialinference/lib/python3.12/site-packages/flask/app.py", line 1473, in wsgi_app
    response = self.full_dispatch_request()
               ^^^^^^^^^^^^^^^^^^^^^^^^^^^^
  File "/Users/amartinezi/miniconda3/envs/confidentialinference/lib/python3.12/site-packages/flask/app.py", line 882, in full_dispatch_request
    rv = self.handle_user_exception(e)
         ^^^^^^^^^^^^^^^^^^^^^^^^^^^^^
  File "/Users/amartinezi/miniconda3/envs/confidentialinference/lib/python3.12/site-packages/flask/app.py", line 880, in full_dispatch_request
    rv = self.dispatch_request()
         ^^^^^^^^^^^^^^^^^^^^^^^
  File "/Users/amartinezi/miniconda3/envs/confidentialinference/lib/python3.12/site-packages/flask/app.py", line 865, in dispatch_request
    return self.ensure_sync(self.view_functions[rule.endpoint])(**view_args)  # type: ignore[no-any-return]
           ^^^^^^^^^^^^^^^^^^^^^^^^^^^^^^^^^^^^^^^^^^^^^^^^^^^^^^^^^^^^^^^^^
  File "/Users/amartinezi/Documents/SINCERE/update.py", line 303, in inference
    loading_time_std = model_load_times_std(model_alias,0)
                       ^^^^^^^^^^^^^^^^^^^^^^^^^^^^^^^^^^^
TypeError: 'dict' object is not callable
2024-09-09 13:47:33,087 127.0.0.1 - - [09/Sep/2024 13:47:33] "[35m[1mPOST /inference HTTP/1.1[0m" 500 -
2024-09-09 13:47:34,262 Exception on /inference [POST]
Traceback (most recent call last):
  File "/Users/amartinezi/miniconda3/envs/confidentialinference/lib/python3.12/site-packages/flask/app.py", line 1473, in wsgi_app
    response = self.full_dispatch_request()
               ^^^^^^^^^^^^^^^^^^^^^^^^^^^^
  File "/Users/amartinezi/miniconda3/envs/confidentialinference/lib/python3.12/site-packages/flask/app.py", line 882, in full_dispatch_request
    rv = self.handle_user_exception(e)
         ^^^^^^^^^^^^^^^^^^^^^^^^^^^^^
  File "/Users/amartinezi/miniconda3/envs/confidentialinference/lib/python3.12/site-packages/flask/app.py", line 880, in full_dispatch_request
    rv = self.dispatch_request()
         ^^^^^^^^^^^^^^^^^^^^^^^
  File "/Users/amartinezi/miniconda3/envs/confidentialinference/lib/python3.12/site-packages/flask/app.py", line 865, in dispatch_request
    return self.ensure_sync(self.view_functions[rule.endpoint])(**view_args)  # type: ignore[no-any-return]
           ^^^^^^^^^^^^^^^^^^^^^^^^^^^^^^^^^^^^^^^^^^^^^^^^^^^^^^^^^^^^^^^^^
  File "/Users/amartinezi/Documents/SINCERE/update.py", line 303, in inference
    loading_time_std = model_load_times_std(model_alias,0)
                       ^^^^^^^^^^^^^^^^^^^^^^^^^^^^^^^^^^^
TypeError: 'dict' object is not callable
2024-09-09 13:47:34,264 127.0.0.1 - - [09/Sep/2024 13:47:34] "[35m[1mPOST /inference HTTP/1.1[0m" 500 -
